2023-12-07 11:32:38 DEBUG log_debug(23) Error Occurred: Traceback (most recent call last):
  File "C:\PERSONAL\Parking_Management_System_FastAPI\src\helpers\jwt_helpers.py", line 25, in validate_access_token
    payload = jwt.decode(token, SECRET_KEY, algorithms=[ALGORITHM])
              ^^^^^^^^^^^^^^^^^^^^^^^^^^^^^^^^^^^^^^^^^^^^^^^^^^^^^
  File "C:\Users\ahada\.virtualenvs\Parking_Management_System_FastAPI-yC4wlCPa\Lib\site-packages\jwt\api_jwt.py", line 210, in decode
    decoded = self.decode_complete(
              ^^^^^^^^^^^^^^^^^^^^^
  File "C:\Users\ahada\.virtualenvs\Parking_Management_System_FastAPI-yC4wlCPa\Lib\site-packages\jwt\api_jwt.py", line 162, in decode_complete
    self._validate_claims(
  File "C:\Users\ahada\.virtualenvs\Parking_Management_System_FastAPI-yC4wlCPa\Lib\site-packages\jwt\api_jwt.py", line 248, in _validate_claims
    self._validate_exp(payload, now, leeway)
  File "C:\Users\ahada\.virtualenvs\Parking_Management_System_FastAPI-yC4wlCPa\Lib\site-packages\jwt\api_jwt.py", line 306, in _validate_exp
    raise ExpiredSignatureError("Signature has expired")
jwt.exceptions.ExpiredSignatureError: Signature has expired

The above exception was the direct cause of the following exception:

Traceback (most recent call last):
  File "C:\PERSONAL\Parking_Management_System_FastAPI\src\helpers\handle_errors.py", line 19, in wrapper
    return_value = function(*args, **kwargs)
                   ^^^^^^^^^^^^^^^^^^^^^^^^^
  File "C:\PERSONAL\Parking_Management_System_FastAPI\src\helpers\validations.py", line 41, in wrapper
    return function(*args, **kwargs)
           ^^^^^^^^^^^^^^^^^^^^^^^^^
  File "C:\PERSONAL\Parking_Management_System_FastAPI\src\helpers\access_decorator.py", line 14, in wrapper
    token = validate_access_token(request=request)
            ^^^^^^^^^^^^^^^^^^^^^^^^^^^^^^^^^^^^^^
  File "C:\PERSONAL\Parking_Management_System_FastAPI\src\helpers\jwt_helpers.py", line 27, in validate_access_token
    raise UnauthorizedError(prompts.get(
src.helpers.errors.UnauthorizedError: Token Expired

2023-12-07 11:32:57 DEBUG log_debug(23) Error Occurred: Traceback (most recent call last):
  File "C:\PERSONAL\Parking_Management_System_FastAPI\src\helpers\handle_errors.py", line 19, in wrapper
    return_value = function(*args, **kwargs)
                   ^^^^^^^^^^^^^^^^^^^^^^^^^
  File "C:\PERSONAL\Parking_Management_System_FastAPI\src\helpers\validations.py", line 41, in wrapper
    return function(*args, **kwargs)
           ^^^^^^^^^^^^^^^^^^^^^^^^^
  File "C:\PERSONAL\Parking_Management_System_FastAPI\src\helpers\access_decorator.py", line 21, in wrapper
    return fun(*args, **kwargs)
           ^^^^^^^^^^^^^^^^^^^^
  File "C:\PERSONAL\Parking_Management_System_FastAPI\src\routers\slot.py", line 32, in occupy_slot
    slot.assign_slot(request_data.get("slot_number"), request_data.get(
  File "C:\PERSONAL\Parking_Management_System_FastAPI\src\controllers\slot.py", line 18, in assign_slot
    self.__is_slot_available(slot_number, vehicle_type)
  File "C:\PERSONAL\Parking_Management_System_FastAPI\src\controllers\slot.py", line 124, in __is_slot_available
    raise ConflictError(prompts.get("SLOT_OCCUPIED"))
src.helpers.errors.ConflictError: Slot Already Occupied! Choose One Which is not.

2023-12-08 10:07:23 DEBUG log_debug(23) Error Occurred: Traceback (most recent call last):
  File "C:\PERSONAL\Parking_Management_System_FastAPI\src\helpers\jwt_helpers.py", line 25, in validate_access_token
    payload = jwt.decode(token, SECRET_KEY, algorithms=[ALGORITHM])
              ^^^^^^^^^^^^^^^^^^^^^^^^^^^^^^^^^^^^^^^^^^^^^^^^^^^^^
  File "C:\Users\ahada\.virtualenvs\Parking_Management_System_FastAPI-yC4wlCPa\Lib\site-packages\jwt\api_jwt.py", line 210, in decode
    decoded = self.decode_complete(
              ^^^^^^^^^^^^^^^^^^^^^
  File "C:\Users\ahada\.virtualenvs\Parking_Management_System_FastAPI-yC4wlCPa\Lib\site-packages\jwt\api_jwt.py", line 162, in decode_complete
    self._validate_claims(
  File "C:\Users\ahada\.virtualenvs\Parking_Management_System_FastAPI-yC4wlCPa\Lib\site-packages\jwt\api_jwt.py", line 248, in _validate_claims
    self._validate_exp(payload, now, leeway)
  File "C:\Users\ahada\.virtualenvs\Parking_Management_System_FastAPI-yC4wlCPa\Lib\site-packages\jwt\api_jwt.py", line 306, in _validate_exp
    raise ExpiredSignatureError("Signature has expired")
jwt.exceptions.ExpiredSignatureError: Signature has expired

The above exception was the direct cause of the following exception:

Traceback (most recent call last):
  File "C:\PERSONAL\Parking_Management_System_FastAPI\src\helpers\handle_errors.py", line 19, in wrapper
    return_value = function(*args, **kwargs)
                   ^^^^^^^^^^^^^^^^^^^^^^^^^
  File "C:\PERSONAL\Parking_Management_System_FastAPI\src\helpers\access_decorator.py", line 14, in wrapper
    token = validate_access_token(request=request)
            ^^^^^^^^^^^^^^^^^^^^^^^^^^^^^^^^^^^^^^
  File "C:\PERSONAL\Parking_Management_System_FastAPI\src\helpers\jwt_helpers.py", line 27, in validate_access_token
    raise UnauthorizedError(prompts.get(
src.helpers.errors.UnauthorizedError: Token Expired

2023-12-08 13:49:03 DEBUG log_debug(23) Error Occurred: Traceback (most recent call last):
  File "C:\PERSONAL\Parking_Management_System_FastAPI\src\helpers\jwt_helpers.py", line 25, in validate_access_token
    payload = jwt.decode(token, SECRET_KEY, algorithms=[ALGORITHM])
              ^^^^^^^^^^^^^^^^^^^^^^^^^^^^^^^^^^^^^^^^^^^^^^^^^^^^^
  File "C:\Users\ahada\.virtualenvs\Parking_Management_System_FastAPI-yC4wlCPa\Lib\site-packages\jwt\api_jwt.py", line 210, in decode
    decoded = self.decode_complete(
              ^^^^^^^^^^^^^^^^^^^^^
  File "C:\Users\ahada\.virtualenvs\Parking_Management_System_FastAPI-yC4wlCPa\Lib\site-packages\jwt\api_jwt.py", line 162, in decode_complete
    self._validate_claims(
  File "C:\Users\ahada\.virtualenvs\Parking_Management_System_FastAPI-yC4wlCPa\Lib\site-packages\jwt\api_jwt.py", line 248, in _validate_claims
    self._validate_exp(payload, now, leeway)
  File "C:\Users\ahada\.virtualenvs\Parking_Management_System_FastAPI-yC4wlCPa\Lib\site-packages\jwt\api_jwt.py", line 306, in _validate_exp
    raise ExpiredSignatureError("Signature has expired")
jwt.exceptions.ExpiredSignatureError: Signature has expired

The above exception was the direct cause of the following exception:

Traceback (most recent call last):
  File "C:\PERSONAL\Parking_Management_System_FastAPI\src\helpers\handle_errors.py", line 19, in wrapper
    return_value = function(*args, **kwargs)
                   ^^^^^^^^^^^^^^^^^^^^^^^^^
  File "C:\PERSONAL\Parking_Management_System_FastAPI\src\helpers\access_decorator.py", line 14, in wrapper
    token = validate_access_token(request=request)
            ^^^^^^^^^^^^^^^^^^^^^^^^^^^^^^^^^^^^^^
  File "C:\PERSONAL\Parking_Management_System_FastAPI\src\helpers\jwt_helpers.py", line 27, in validate_access_token
    raise UnauthorizedError(prompts.get(
src.helpers.errors.UnauthorizedError: Token Expired

2023-12-08 13:58:58 DEBUG log_debug(23) Error Occurred: Traceback (most recent call last):
  File "C:\PERSONAL\Parking_Management_System_FastAPI\src\helpers\handle_errors.py", line 19, in wrapper
    return_value = function(*args, **kwargs)
                   ^^^^^^^^^^^^^^^^^^^^^^^^^
  File "C:\PERSONAL\Parking_Management_System_FastAPI\src\helpers\access_decorator.py", line 21, in wrapper
    return fun(*args, **kwargs)
           ^^^^^^^^^^^^^^^^^^^^
  File "C:\PERSONAL\Parking_Management_System_FastAPI\src\helpers\validations.py", line 41, in wrapper
    return function(*args, **kwargs)
           ^^^^^^^^^^^^^^^^^^^^^^^^^
  File "C:\PERSONAL\Parking_Management_System_FastAPI\src\routers\parkingspace.py", line 40, in update_parking_space
    raise ConflictError(prompts.get("SPACE_OCCUPIED"))
src.helpers.errors.ConflictError: Cannot reduce capacity. Space is occupied.

2023-12-08 13:59:00 DEBUG log_debug(23) Error Occurred: Traceback (most recent call last):
  File "C:\PERSONAL\Parking_Management_System_FastAPI\src\helpers\handle_errors.py", line 19, in wrapper
    return_value = function(*args, **kwargs)
                   ^^^^^^^^^^^^^^^^^^^^^^^^^
  File "C:\PERSONAL\Parking_Management_System_FastAPI\src\helpers\access_decorator.py", line 21, in wrapper
    return fun(*args, **kwargs)
           ^^^^^^^^^^^^^^^^^^^^
  File "C:\PERSONAL\Parking_Management_System_FastAPI\src\helpers\validations.py", line 41, in wrapper
    return function(*args, **kwargs)
           ^^^^^^^^^^^^^^^^^^^^^^^^^
  File "C:\PERSONAL\Parking_Management_System_FastAPI\src\routers\parkingspace.py", line 40, in update_parking_space
    raise ConflictError(prompts.get("SPACE_OCCUPIED"))
src.helpers.errors.ConflictError: Cannot reduce capacity. Space is occupied.

2023-12-08 13:59:03 DEBUG log_debug(23) Error Occurred: Traceback (most recent call last):
  File "C:\PERSONAL\Parking_Management_System_FastAPI\src\helpers\handle_errors.py", line 19, in wrapper
    return_value = function(*args, **kwargs)
                   ^^^^^^^^^^^^^^^^^^^^^^^^^
  File "C:\PERSONAL\Parking_Management_System_FastAPI\src\helpers\access_decorator.py", line 21, in wrapper
    return fun(*args, **kwargs)
           ^^^^^^^^^^^^^^^^^^^^
  File "C:\PERSONAL\Parking_Management_System_FastAPI\src\helpers\validations.py", line 41, in wrapper
    return function(*args, **kwargs)
           ^^^^^^^^^^^^^^^^^^^^^^^^^
  File "C:\PERSONAL\Parking_Management_System_FastAPI\src\routers\parkingspace.py", line 40, in update_parking_space
    raise ConflictError(prompts.get("SPACE_OCCUPIED"))
src.helpers.errors.ConflictError: Cannot reduce capacity. Space is occupied.

2023-12-08 15:20:59 DEBUG log_debug(23) Error Occurred: Traceback (most recent call last):
  File "C:\PERSONAL\Parking_Management_System_FastAPI\src\helpers\jwt_helpers.py", line 25, in validate_access_token
    payload = jwt.decode(token, SECRET_KEY, algorithms=[ALGORITHM])
              ^^^^^^^^^^^^^^^^^^^^^^^^^^^^^^^^^^^^^^^^^^^^^^^^^^^^^
  File "C:\Users\ahada\.virtualenvs\Parking_Management_System_FastAPI-yC4wlCPa\Lib\site-packages\jwt\api_jwt.py", line 210, in decode
    decoded = self.decode_complete(
              ^^^^^^^^^^^^^^^^^^^^^
  File "C:\Users\ahada\.virtualenvs\Parking_Management_System_FastAPI-yC4wlCPa\Lib\site-packages\jwt\api_jwt.py", line 162, in decode_complete
    self._validate_claims(
  File "C:\Users\ahada\.virtualenvs\Parking_Management_System_FastAPI-yC4wlCPa\Lib\site-packages\jwt\api_jwt.py", line 248, in _validate_claims
    self._validate_exp(payload, now, leeway)
  File "C:\Users\ahada\.virtualenvs\Parking_Management_System_FastAPI-yC4wlCPa\Lib\site-packages\jwt\api_jwt.py", line 306, in _validate_exp
    raise ExpiredSignatureError("Signature has expired")
jwt.exceptions.ExpiredSignatureError: Signature has expired

The above exception was the direct cause of the following exception:

Traceback (most recent call last):
  File "C:\PERSONAL\Parking_Management_System_FastAPI\src\helpers\handle_errors.py", line 19, in wrapper
    return_value = function(*args, **kwargs)
                   ^^^^^^^^^^^^^^^^^^^^^^^^^
  File "C:\PERSONAL\Parking_Management_System_FastAPI\src\helpers\access_decorator.py", line 14, in wrapper
    token = validate_access_token(request=request)
            ^^^^^^^^^^^^^^^^^^^^^^^^^^^^^^^^^^^^^^
  File "C:\PERSONAL\Parking_Management_System_FastAPI\src\helpers\jwt_helpers.py", line 27, in validate_access_token
    raise UnauthorizedError(prompts.get(
src.helpers.errors.UnauthorizedError: Token Expired

2023-12-08 16:04:18 DEBUG log_debug(23) Error Occurred: Traceback (most recent call last):
  File "C:\PERSONAL\Parking_Management_System_FastAPI\src\helpers\handle_errors.py", line 19, in wrapper
    return_value = function(*args, **kwargs)
                   ^^^^^^^^^^^^^^^^^^^^^^^^^
  File "C:\PERSONAL\Parking_Management_System_FastAPI\src\helpers\access_decorator.py", line 21, in wrapper
    return fun(*args, **kwargs)
           ^^^^^^^^^^^^^^^^^^^^
  File "C:\PERSONAL\Parking_Management_System_FastAPI\src\helpers\validations.py", line 41, in wrapper
    return function(*args, **kwargs)
           ^^^^^^^^^^^^^^^^^^^^^^^^^
  File "C:\PERSONAL\Parking_Management_System_FastAPI\src\routers\vehicles.py", line 51, in add_vehicle
    vehicle.add_vehicle(
  File "C:\PERSONAL\Parking_Management_System_FastAPI\src\controllers\vehicle.py", line 19, in add_vehicle
    raise ValueError(prompts.get("VEHICLE_ALREADY_EXISTS"))
ValueError: Vehicle Already Exists.

2023-12-11 10:34:11 DEBUG log_debug(23) Error Occurred: Traceback (most recent call last):
  File "C:\PERSONAL\Parking_Management_System_FastAPI\src\helpers\handle_errors.py", line 19, in wrapper
    return_value = function(*args, **kwargs)
                   ^^^^^^^^^^^^^^^^^^^^^^^^^
  File "C:\PERSONAL\Parking_Management_System_FastAPI\src\helpers\access_decorator.py", line 21, in wrapper
    return fun(*args, **kwargs)
           ^^^^^^^^^^^^^^^^^^^^
  File "C:\PERSONAL\Parking_Management_System_FastAPI\src\helpers\validations.py", line 41, in wrapper
    return function(*args, **kwargs)
           ^^^^^^^^^^^^^^^^^^^^^^^^^
  File "C:\PERSONAL\Parking_Management_System_FastAPI\src\routers\vehicles.py", line 51, in add_vehicle
    vehicle.add_vehicle(
  File "C:\PERSONAL\Parking_Management_System_FastAPI\src\controllers\vehicle.py", line 19, in add_vehicle
    raise ValueError(prompts.get("VEHICLE_ALREADY_EXISTS"))
ValueError: Vehicle Already Exists.

2023-12-11 10:34:27 DEBUG log_debug(23) Error Occurred: Traceback (most recent call last):
  File "C:\PERSONAL\Parking_Management_System_FastAPI\src\helpers\handle_errors.py", line 19, in wrapper
    return_value = function(*args, **kwargs)
                   ^^^^^^^^^^^^^^^^^^^^^^^^^
  File "C:\PERSONAL\Parking_Management_System_FastAPI\src\helpers\access_decorator.py", line 21, in wrapper
    return fun(*args, **kwargs)
           ^^^^^^^^^^^^^^^^^^^^
  File "C:\PERSONAL\Parking_Management_System_FastAPI\src\helpers\validations.py", line 41, in wrapper
    return function(*args, **kwargs)
           ^^^^^^^^^^^^^^^^^^^^^^^^^
  File "C:\PERSONAL\Parking_Management_System_FastAPI\src\routers\vehicles.py", line 51, in add_vehicle
    vehicle.add_vehicle(
  File "C:\PERSONAL\Parking_Management_System_FastAPI\src\controllers\vehicle.py", line 19, in add_vehicle
    raise ValueError(prompts.get("VEHICLE_ALREADY_EXISTS"))
ValueError: Vehicle Already Exists.

2023-12-11 10:37:00 DEBUG log_debug(23) Error Occurred: Traceback (most recent call last):
  File "C:\PERSONAL\Parking_Management_System_FastAPI\src\helpers\handle_errors.py", line 19, in wrapper
    return_value = function(*args, **kwargs)
                   ^^^^^^^^^^^^^^^^^^^^^^^^^
  File "C:\PERSONAL\Parking_Management_System_FastAPI\src\helpers\access_decorator.py", line 21, in wrapper
    return fun(*args, **kwargs)
           ^^^^^^^^^^^^^^^^^^^^
  File "C:\PERSONAL\Parking_Management_System_FastAPI\src\helpers\validations.py", line 41, in wrapper
    return function(*args, **kwargs)
           ^^^^^^^^^^^^^^^^^^^^^^^^^
  File "C:\PERSONAL\Parking_Management_System_FastAPI\src\routers\vehicles.py", line 51, in add_vehicle
    vehicle.add_vehicle(
  File "C:\PERSONAL\Parking_Management_System_FastAPI\src\controllers\vehicle.py", line 19, in add_vehicle
    raise ValueError(prompts.get("VEHICLE_ALREADY_EXISTS"))
ValueError: Vehicle Already Exists.

2023-12-11 14:18:13 DEBUG log_debug(23) Error Occurred: Traceback (most recent call last):
  File "C:\PERSONAL\Parking_Management_System_FastAPI\src\helpers\handle_errors.py", line 19, in wrapper
    return_value = function(*args, **kwargs)
                   ^^^^^^^^^^^^^^^^^^^^^^^^^
  File "C:\PERSONAL\Parking_Management_System_FastAPI\src\helpers\access_decorator.py", line 21, in wrapper
    return fun(*args, **kwargs)
           ^^^^^^^^^^^^^^^^^^^^
  File "C:\PERSONAL\Parking_Management_System_FastAPI\src\helpers\validations.py", line 41, in wrapper
    return function(*args, **kwargs)
           ^^^^^^^^^^^^^^^^^^^^^^^^^
  File "C:\PERSONAL\Parking_Management_System_FastAPI\src\routers\vehicles.py", line 51, in add_vehicle
    vehicle.add_vehicle(
  File "C:\PERSONAL\Parking_Management_System_FastAPI\src\controllers\vehicle.py", line 19, in add_vehicle
    raise ValueError(prompts.get("VEHICLE_ALREADY_EXISTS"))
ValueError: Vehicle Already Exists.

2023-12-11 14:25:36 DEBUG log_debug(23) Error Occurred: Traceback (most recent call last):
  File "C:\PERSONAL\Parking_Management_System_FastAPI\src\helpers\handle_errors.py", line 19, in wrapper
    return_value = function(*args, **kwargs)
                   ^^^^^^^^^^^^^^^^^^^^^^^^^
  File "C:\PERSONAL\Parking_Management_System_FastAPI\src\helpers\access_decorator.py", line 21, in wrapper
    return fun(*args, **kwargs)
           ^^^^^^^^^^^^^^^^^^^^
  File "C:\PERSONAL\Parking_Management_System_FastAPI\src\helpers\validations.py", line 41, in wrapper
    return function(*args, **kwargs)
           ^^^^^^^^^^^^^^^^^^^^^^^^^
  File "C:\PERSONAL\Parking_Management_System_FastAPI\src\routers\vehicles.py", line 51, in add_vehicle
    vehicle.add_vehicle(
  File "C:\PERSONAL\Parking_Management_System_FastAPI\src\controllers\vehicle.py", line 19, in add_vehicle
    raise ValueError(prompts.get("VEHICLE_ALREADY_EXISTS"))
ValueError: Vehicle Already Exists.

2023-12-11 14:33:22 DEBUG log_debug(23) Error Occurred: Traceback (most recent call last):
  File "C:\PERSONAL\Parking_Management_System_FastAPI\src\helpers\handle_errors.py", line 19, in wrapper
    return_value = function(*args, **kwargs)
                   ^^^^^^^^^^^^^^^^^^^^^^^^^
  File "C:\PERSONAL\Parking_Management_System_FastAPI\src\helpers\access_decorator.py", line 21, in wrapper
    return fun(*args, **kwargs)
           ^^^^^^^^^^^^^^^^^^^^
  File "C:\PERSONAL\Parking_Management_System_FastAPI\src\helpers\validations.py", line 41, in wrapper
    return function(*args, **kwargs)
           ^^^^^^^^^^^^^^^^^^^^^^^^^
  File "C:\PERSONAL\Parking_Management_System_FastAPI\src\routers\vehicles.py", line 51, in add_vehicle
    vehicle.add_vehicle(
  File "C:\PERSONAL\Parking_Management_System_FastAPI\src\controllers\vehicle.py", line 19, in add_vehicle
    raise ValueError(prompts.get("VEHICLE_ALREADY_EXISTS"))
ValueError: Vehicle Already Exists.

2023-12-11 14:36:25 DEBUG log_debug(23) Error Occurred: Traceback (most recent call last):
  File "C:\PERSONAL\Parking_Management_System_FastAPI\src\helpers\handle_errors.py", line 19, in wrapper
    return_value = function(*args, **kwargs)
                   ^^^^^^^^^^^^^^^^^^^^^^^^^
  File "C:\PERSONAL\Parking_Management_System_FastAPI\src\helpers\access_decorator.py", line 21, in wrapper
    return fun(*args, **kwargs)
           ^^^^^^^^^^^^^^^^^^^^
  File "C:\PERSONAL\Parking_Management_System_FastAPI\src\helpers\validations.py", line 41, in wrapper
    return function(*args, **kwargs)
           ^^^^^^^^^^^^^^^^^^^^^^^^^
  File "C:\PERSONAL\Parking_Management_System_FastAPI\src\routers\vehicles.py", line 51, in add_vehicle
    vehicle.add_vehicle(
  File "C:\PERSONAL\Parking_Management_System_FastAPI\src\controllers\vehicle.py", line 19, in add_vehicle
    raise ValueError(prompts.get("VEHICLE_ALREADY_EXISTS"))
ValueError: Vehicle Already Exists.

2023-12-11 14:37:10 DEBUG log_debug(23) Error Occurred: Traceback (most recent call last):
  File "C:\PERSONAL\Parking_Management_System_FastAPI\src\helpers\handle_errors.py", line 19, in wrapper
    return_value = function(*args, **kwargs)
                   ^^^^^^^^^^^^^^^^^^^^^^^^^
  File "C:\PERSONAL\Parking_Management_System_FastAPI\src\helpers\access_decorator.py", line 21, in wrapper
    return fun(*args, **kwargs)
           ^^^^^^^^^^^^^^^^^^^^
  File "C:\PERSONAL\Parking_Management_System_FastAPI\src\helpers\validations.py", line 41, in wrapper
    return function(*args, **kwargs)
           ^^^^^^^^^^^^^^^^^^^^^^^^^
  File "C:\PERSONAL\Parking_Management_System_FastAPI\src\routers\vehicles.py", line 51, in add_vehicle
    vehicle.add_vehicle(
  File "C:\PERSONAL\Parking_Management_System_FastAPI\src\controllers\vehicle.py", line 19, in add_vehicle
    raise ValueError(prompts.get("VEHICLE_ALREADY_EXISTS"))
ValueError: Vehicle Already Exists.

2023-12-11 14:38:59 DEBUG log_debug(23) Error Occurred: Traceback (most recent call last):
  File "C:\PERSONAL\Parking_Management_System_FastAPI\src\helpers\handle_errors.py", line 19, in wrapper
    return_value = function(*args, **kwargs)
                   ^^^^^^^^^^^^^^^^^^^^^^^^^
  File "C:\PERSONAL\Parking_Management_System_FastAPI\src\helpers\access_decorator.py", line 21, in wrapper
    return fun(*args, **kwargs)
           ^^^^^^^^^^^^^^^^^^^^
  File "C:\PERSONAL\Parking_Management_System_FastAPI\src\helpers\validations.py", line 41, in wrapper
    return function(*args, **kwargs)
           ^^^^^^^^^^^^^^^^^^^^^^^^^
  File "C:\PERSONAL\Parking_Management_System_FastAPI\src\routers\vehicles.py", line 51, in add_vehicle
    vehicle.add_vehicle(
  File "C:\PERSONAL\Parking_Management_System_FastAPI\src\controllers\vehicle.py", line 19, in add_vehicle
    raise ValueError(prompts.get("VEHICLE_ALREADY_EXISTS"))
ValueError: Vehicle Already Exists.

2023-12-11 14:39:59 DEBUG log_debug(23) Error Occurred: Traceback (most recent call last):
  File "C:\PERSONAL\Parking_Management_System_FastAPI\src\helpers\handle_errors.py", line 19, in wrapper
    return_value = function(*args, **kwargs)
                   ^^^^^^^^^^^^^^^^^^^^^^^^^
  File "C:\PERSONAL\Parking_Management_System_FastAPI\src\helpers\access_decorator.py", line 21, in wrapper
    return fun(*args, **kwargs)
           ^^^^^^^^^^^^^^^^^^^^
  File "C:\PERSONAL\Parking_Management_System_FastAPI\src\helpers\validations.py", line 41, in wrapper
    return function(*args, **kwargs)
           ^^^^^^^^^^^^^^^^^^^^^^^^^
  File "C:\PERSONAL\Parking_Management_System_FastAPI\src\routers\vehicles.py", line 51, in add_vehicle
    vehicle.add_vehicle(
  File "C:\PERSONAL\Parking_Management_System_FastAPI\src\controllers\vehicle.py", line 19, in add_vehicle
    raise ValueError(prompts.get("VEHICLE_ALREADY_EXISTS"))
ValueError: Vehicle Already Exists.

2023-12-11 14:40:50 DEBUG log_debug(23) Error Occurred: Traceback (most recent call last):
  File "C:\PERSONAL\Parking_Management_System_FastAPI\src\helpers\handle_errors.py", line 19, in wrapper
    return_value = function(*args, **kwargs)
                   ^^^^^^^^^^^^^^^^^^^^^^^^^
  File "C:\PERSONAL\Parking_Management_System_FastAPI\src\helpers\access_decorator.py", line 21, in wrapper
    return fun(*args, **kwargs)
           ^^^^^^^^^^^^^^^^^^^^
  File "C:\PERSONAL\Parking_Management_System_FastAPI\src\helpers\validations.py", line 41, in wrapper
    return function(*args, **kwargs)
           ^^^^^^^^^^^^^^^^^^^^^^^^^
  File "C:\PERSONAL\Parking_Management_System_FastAPI\src\routers\vehicles.py", line 51, in add_vehicle
    vehicle.add_vehicle(
  File "C:\PERSONAL\Parking_Management_System_FastAPI\src\controllers\vehicle.py", line 19, in add_vehicle
    raise ValueError(prompts.get("VEHICLE_ALREADY_EXISTS"))
ValueError: Vehicle Already Exists.

2023-12-11 15:06:59 DEBUG log_debug(23) Error Occurred: Traceback (most recent call last):
  File "C:\PERSONAL\Parking_Management_System_FastAPI\src\helpers\handle_errors.py", line 19, in wrapper
    return_value = function(*args, **kwargs)
                   ^^^^^^^^^^^^^^^^^^^^^^^^^
  File "C:\PERSONAL\Parking_Management_System_FastAPI\src\helpers\access_decorator.py", line 21, in wrapper
    return fun(*args, **kwargs)
           ^^^^^^^^^^^^^^^^^^^^
  File "C:\PERSONAL\Parking_Management_System_FastAPI\src\helpers\validations.py", line 41, in wrapper
    return function(*args, **kwargs)
           ^^^^^^^^^^^^^^^^^^^^^^^^^
  File "C:\PERSONAL\Parking_Management_System_FastAPI\src\routers\vehicles.py", line 51, in add_vehicle
    vehicle.add_vehicle(
  File "C:\PERSONAL\Parking_Management_System_FastAPI\src\controllers\vehicle.py", line 19, in add_vehicle
    raise ValueError(prompts.get("VEHICLE_ALREADY_EXISTS"))
ValueError: Vehicle Already Exists.

2023-12-11 15:09:25 DEBUG log_debug(23) Error Occurred: Traceback (most recent call last):
  File "C:\PERSONAL\Parking_Management_System_FastAPI\src\helpers\handle_errors.py", line 19, in wrapper
    return_value = function(*args, **kwargs)
                   ^^^^^^^^^^^^^^^^^^^^^^^^^
  File "C:\PERSONAL\Parking_Management_System_FastAPI\src\helpers\access_decorator.py", line 21, in wrapper
    return fun(*args, **kwargs)
           ^^^^^^^^^^^^^^^^^^^^
  File "C:\PERSONAL\Parking_Management_System_FastAPI\src\helpers\validations.py", line 41, in wrapper
    return function(*args, **kwargs)
           ^^^^^^^^^^^^^^^^^^^^^^^^^
  File "C:\PERSONAL\Parking_Management_System_FastAPI\src\routers\vehicles.py", line 51, in add_vehicle
    vehicle.add_vehicle(
  File "C:\PERSONAL\Parking_Management_System_FastAPI\src\controllers\vehicle.py", line 19, in add_vehicle
    raise ValueError(prompts.get("VEHICLE_ALREADY_EXISTS"))
ValueError: Vehicle Already Exists.

2023-12-11 15:11:27 DEBUG log_debug(23) Error Occurred: Traceback (most recent call last):
  File "C:\PERSONAL\Parking_Management_System_FastAPI\src\helpers\handle_errors.py", line 19, in wrapper
    return_value = function(*args, **kwargs)
                   ^^^^^^^^^^^^^^^^^^^^^^^^^
  File "C:\PERSONAL\Parking_Management_System_FastAPI\src\helpers\access_decorator.py", line 21, in wrapper
    return fun(*args, **kwargs)
           ^^^^^^^^^^^^^^^^^^^^
  File "C:\PERSONAL\Parking_Management_System_FastAPI\src\helpers\validations.py", line 41, in wrapper
    return function(*args, **kwargs)
           ^^^^^^^^^^^^^^^^^^^^^^^^^
  File "C:\PERSONAL\Parking_Management_System_FastAPI\src\routers\vehicles.py", line 51, in add_vehicle
    vehicle.add_vehicle(
  File "C:\PERSONAL\Parking_Management_System_FastAPI\src\controllers\vehicle.py", line 19, in add_vehicle
    raise ValueError(prompts.get("VEHICLE_ALREADY_EXISTS"))
ValueError: Vehicle Already Exists.

2023-12-11 15:33:06 DEBUG log_debug(23) Error Occurred: Traceback (most recent call last):
  File "C:\PERSONAL\Parking_Management_System_FastAPI\src\helpers\handle_errors.py", line 19, in wrapper
    return_value = function(*args, **kwargs)
                   ^^^^^^^^^^^^^^^^^^^^^^^^^
  File "C:\PERSONAL\Parking_Management_System_FastAPI\src\helpers\access_decorator.py", line 21, in wrapper
    return fun(*args, **kwargs)
           ^^^^^^^^^^^^^^^^^^^^
  File "C:\PERSONAL\Parking_Management_System_FastAPI\src\helpers\validations.py", line 41, in wrapper
    return function(*args, **kwargs)
           ^^^^^^^^^^^^^^^^^^^^^^^^^
  File "C:\PERSONAL\Parking_Management_System_FastAPI\src\routers\vehicles.py", line 51, in add_vehicle
    vehicle.add_vehicle(
  File "C:\PERSONAL\Parking_Management_System_FastAPI\src\controllers\vehicle.py", line 19, in add_vehicle
    raise ValueError(prompts.get("VEHICLE_ALREADY_EXISTS"))
ValueError: Vehicle Already Exists.

2023-12-11 15:34:15 DEBUG log_debug(23) Error Occurred: Traceback (most recent call last):
  File "C:\PERSONAL\Parking_Management_System_FastAPI\src\helpers\handle_errors.py", line 19, in wrapper
    return_value = function(*args, **kwargs)
                   ^^^^^^^^^^^^^^^^^^^^^^^^^
  File "C:\PERSONAL\Parking_Management_System_FastAPI\src\helpers\access_decorator.py", line 21, in wrapper
    return fun(*args, **kwargs)
           ^^^^^^^^^^^^^^^^^^^^
  File "C:\PERSONAL\Parking_Management_System_FastAPI\src\helpers\validations.py", line 41, in wrapper
    return function(*args, **kwargs)
           ^^^^^^^^^^^^^^^^^^^^^^^^^
  File "C:\PERSONAL\Parking_Management_System_FastAPI\src\routers\vehicles.py", line 51, in add_vehicle
    vehicle.add_vehicle(
  File "C:\PERSONAL\Parking_Management_System_FastAPI\src\controllers\vehicle.py", line 19, in add_vehicle
    raise ValueError(prompts.get("VEHICLE_ALREADY_EXISTS"))
ValueError: Vehicle Already Exists.

2023-12-11 15:35:02 DEBUG log_debug(23) Error Occurred: Traceback (most recent call last):
  File "C:\PERSONAL\Parking_Management_System_FastAPI\src\helpers\handle_errors.py", line 19, in wrapper
    return_value = function(*args, **kwargs)
                   ^^^^^^^^^^^^^^^^^^^^^^^^^
  File "C:\PERSONAL\Parking_Management_System_FastAPI\src\helpers\access_decorator.py", line 21, in wrapper
    return fun(*args, **kwargs)
           ^^^^^^^^^^^^^^^^^^^^
  File "C:\PERSONAL\Parking_Management_System_FastAPI\src\helpers\validations.py", line 41, in wrapper
    return function(*args, **kwargs)
           ^^^^^^^^^^^^^^^^^^^^^^^^^
  File "C:\PERSONAL\Parking_Management_System_FastAPI\src\routers\vehicles.py", line 51, in add_vehicle
    vehicle.add_vehicle(
  File "C:\PERSONAL\Parking_Management_System_FastAPI\src\controllers\vehicle.py", line 19, in add_vehicle
    raise ValueError(prompts.get("VEHICLE_ALREADY_EXISTS"))
ValueError: Vehicle Already Exists.

2023-12-11 15:35:18 DEBUG log_debug(23) Error Occurred: Traceback (most recent call last):
  File "C:\PERSONAL\Parking_Management_System_FastAPI\src\helpers\handle_errors.py", line 19, in wrapper
    return_value = function(*args, **kwargs)
                   ^^^^^^^^^^^^^^^^^^^^^^^^^
  File "C:\PERSONAL\Parking_Management_System_FastAPI\src\helpers\access_decorator.py", line 21, in wrapper
    return fun(*args, **kwargs)
           ^^^^^^^^^^^^^^^^^^^^
  File "C:\PERSONAL\Parking_Management_System_FastAPI\src\helpers\validations.py", line 41, in wrapper
    return function(*args, **kwargs)
           ^^^^^^^^^^^^^^^^^^^^^^^^^
  File "C:\PERSONAL\Parking_Management_System_FastAPI\src\routers\vehicles.py", line 51, in add_vehicle
    vehicle.add_vehicle(
  File "C:\PERSONAL\Parking_Management_System_FastAPI\src\controllers\vehicle.py", line 19, in add_vehicle
    raise ValueError(prompts.get("VEHICLE_ALREADY_EXISTS"))
ValueError: Vehicle Already Exists.

2023-12-11 15:35:43 DEBUG log_debug(23) Error Occurred: Traceback (most recent call last):
  File "C:\PERSONAL\Parking_Management_System_FastAPI\src\helpers\handle_errors.py", line 19, in wrapper
    return_value = function(*args, **kwargs)
                   ^^^^^^^^^^^^^^^^^^^^^^^^^
  File "C:\PERSONAL\Parking_Management_System_FastAPI\src\helpers\access_decorator.py", line 21, in wrapper
    return fun(*args, **kwargs)
           ^^^^^^^^^^^^^^^^^^^^
  File "C:\PERSONAL\Parking_Management_System_FastAPI\src\helpers\validations.py", line 41, in wrapper
    return function(*args, **kwargs)
           ^^^^^^^^^^^^^^^^^^^^^^^^^
  File "C:\PERSONAL\Parking_Management_System_FastAPI\src\routers\vehicles.py", line 51, in add_vehicle
    vehicle.add_vehicle(
  File "C:\PERSONAL\Parking_Management_System_FastAPI\src\controllers\vehicle.py", line 19, in add_vehicle
    raise ValueError(prompts.get("VEHICLE_ALREADY_EXISTS"))
ValueError: Vehicle Already Exists.

2023-12-11 15:36:21 DEBUG log_debug(23) Error Occurred: Traceback (most recent call last):
  File "C:\PERSONAL\Parking_Management_System_FastAPI\src\helpers\handle_errors.py", line 19, in wrapper
    return_value = function(*args, **kwargs)
                   ^^^^^^^^^^^^^^^^^^^^^^^^^
  File "C:\PERSONAL\Parking_Management_System_FastAPI\src\helpers\access_decorator.py", line 21, in wrapper
    return fun(*args, **kwargs)
           ^^^^^^^^^^^^^^^^^^^^
  File "C:\PERSONAL\Parking_Management_System_FastAPI\src\helpers\validations.py", line 41, in wrapper
    return function(*args, **kwargs)
           ^^^^^^^^^^^^^^^^^^^^^^^^^
  File "C:\PERSONAL\Parking_Management_System_FastAPI\src\routers\vehicles.py", line 51, in add_vehicle
    vehicle.add_vehicle(
  File "C:\PERSONAL\Parking_Management_System_FastAPI\src\controllers\vehicle.py", line 19, in add_vehicle
    raise ValueError(prompts.get("VEHICLE_ALREADY_EXISTS"))
ValueError: Vehicle Already Exists.

2023-12-11 15:36:49 DEBUG log_debug(23) Error Occurred: Traceback (most recent call last):
  File "C:\PERSONAL\Parking_Management_System_FastAPI\src\helpers\handle_errors.py", line 19, in wrapper
    return_value = function(*args, **kwargs)
                   ^^^^^^^^^^^^^^^^^^^^^^^^^
  File "C:\PERSONAL\Parking_Management_System_FastAPI\src\helpers\access_decorator.py", line 21, in wrapper
    return fun(*args, **kwargs)
           ^^^^^^^^^^^^^^^^^^^^
  File "C:\PERSONAL\Parking_Management_System_FastAPI\src\helpers\validations.py", line 41, in wrapper
    return function(*args, **kwargs)
           ^^^^^^^^^^^^^^^^^^^^^^^^^
  File "C:\PERSONAL\Parking_Management_System_FastAPI\src\routers\vehicles.py", line 51, in add_vehicle
    vehicle.add_vehicle(
  File "C:\PERSONAL\Parking_Management_System_FastAPI\src\controllers\vehicle.py", line 19, in add_vehicle
    raise ValueError(prompts.get("VEHICLE_ALREADY_EXISTS"))
ValueError: Vehicle Already Exists.

2023-12-11 15:48:20 DEBUG log_debug(23) Error Occurred: Traceback (most recent call last):
  File "C:\PERSONAL\Parking_Management_System_FastAPI\src\helpers\jwt_helpers.py", line 25, in validate_access_token
    payload = jwt.decode(token, SECRET_KEY, algorithms=[ALGORITHM])
              ^^^^^^^^^^^^^^^^^^^^^^^^^^^^^^^^^^^^^^^^^^^^^^^^^^^^^
  File "C:\Users\ahada\.virtualenvs\Parking_Management_System_FastAPI-yC4wlCPa\Lib\site-packages\jwt\api_jwt.py", line 210, in decode
    decoded = self.decode_complete(
              ^^^^^^^^^^^^^^^^^^^^^
  File "C:\Users\ahada\.virtualenvs\Parking_Management_System_FastAPI-yC4wlCPa\Lib\site-packages\jwt\api_jwt.py", line 162, in decode_complete
    self._validate_claims(
  File "C:\Users\ahada\.virtualenvs\Parking_Management_System_FastAPI-yC4wlCPa\Lib\site-packages\jwt\api_jwt.py", line 248, in _validate_claims
    self._validate_exp(payload, now, leeway)
  File "C:\Users\ahada\.virtualenvs\Parking_Management_System_FastAPI-yC4wlCPa\Lib\site-packages\jwt\api_jwt.py", line 306, in _validate_exp
    raise ExpiredSignatureError("Signature has expired")
jwt.exceptions.ExpiredSignatureError: Signature has expired

The above exception was the direct cause of the following exception:

Traceback (most recent call last):
  File "C:\PERSONAL\Parking_Management_System_FastAPI\src\helpers\handle_errors.py", line 19, in wrapper
    return_value = function(*args, **kwargs)
                   ^^^^^^^^^^^^^^^^^^^^^^^^^
  File "C:\PERSONAL\Parking_Management_System_FastAPI\src\helpers\access_decorator.py", line 14, in wrapper
    token = validate_access_token(request=request)
            ^^^^^^^^^^^^^^^^^^^^^^^^^^^^^^^^^^^^^^
  File "C:\PERSONAL\Parking_Management_System_FastAPI\src\helpers\jwt_helpers.py", line 27, in validate_access_token
    raise UnauthorizedError(prompts.get(
src.helpers.errors.UnauthorizedError: Token Expired

2023-12-11 16:02:00 DEBUG establish_connection(87) Connection established
2023-12-11 16:02:00 DEBUG log_debug(23) Error Occurred: Traceback (most recent call last):
  File "C:\Users\ahada\.virtualenvs\Parking_Management_System_FastAPI-yC4wlCPa\Lib\site-packages\mysql\connector\connection_cext.py", line 633, in cmd_query
    self._cmysql.query(
_mysql_connector.MySQLInterfaceError: Duplicate entry 'LMV' for key 'slot_category.slot_type_UNIQUE'

The above exception was the direct cause of the following exception:

Traceback (most recent call last):
  File "C:\PERSONAL\Parking_Management_System_FastAPI\src\helpers\handle_errors.py", line 19, in wrapper
    return_value = function(*args, **kwargs)
                   ^^^^^^^^^^^^^^^^^^^^^^^^^
  File "C:\PERSONAL\Parking_Management_System_FastAPI\src\helpers\access_decorator.py", line 21, in wrapper
    return fun(*args, **kwargs)
           ^^^^^^^^^^^^^^^^^^^^
  File "C:\PERSONAL\Parking_Management_System_FastAPI\src\helpers\validations.py", line 41, in wrapper
    return function(*args, **kwargs)
           ^^^^^^^^^^^^^^^^^^^^^^^^^
  File "C:\PERSONAL\Parking_Management_System_FastAPI\src\routers\parkingspace.py", line 58, in add_new_parking_space
    parking_space.add_parking_category(
  File "C:\PERSONAL\Parking_Management_System_FastAPI\src\controllers\parking_space.py", line 17, in add_parking_category
    db.update_item(
  File "C:\PERSONAL\Parking_Management_System_FastAPI\src\models\database.py", line 42, in update_item
    raise error
  File "C:\PERSONAL\Parking_Management_System_FastAPI\src\models\database.py", line 35, in update_item
    self.cursor.execute(query, *args)
  File "C:\Users\ahada\.virtualenvs\Parking_Management_System_FastAPI-yC4wlCPa\Lib\site-packages\mysql\connector\cursor_cext.py", line 330, in execute
    result = self._cnx.cmd_query(
             ^^^^^^^^^^^^^^^^^^^^
  File "C:\Users\ahada\.virtualenvs\Parking_Management_System_FastAPI-yC4wlCPa\Lib\site-packages\mysql\connector\opentelemetry\context_propagation.py", line 77, in wrapper
    return method(cnx, *args, **kwargs)
           ^^^^^^^^^^^^^^^^^^^^^^^^^^^^
  File "C:\Users\ahada\.virtualenvs\Parking_Management_System_FastAPI-yC4wlCPa\Lib\site-packages\mysql\connector\connection_cext.py", line 641, in cmd_query
    raise get_mysql_exception(
mysql.connector.errors.IntegrityError: 1062 (23000): Duplicate entry 'LMV' for key 'slot_category.slot_type_UNIQUE'

2023-12-11 16:02:51 DEBUG establish_connection(87) Connection established
2023-12-11 16:02:51 DEBUG log_debug(23) Error Occurred: Traceback (most recent call last):
  File "C:\Users\ahada\.virtualenvs\Parking_Management_System_FastAPI-yC4wlCPa\Lib\site-packages\mysql\connector\connection_cext.py", line 633, in cmd_query
    self._cmysql.query(
_mysql_connector.MySQLInterfaceError: Duplicate entry 'LMV' for key 'slot_category.slot_type_UNIQUE'

The above exception was the direct cause of the following exception:

Traceback (most recent call last):
  File "C:\PERSONAL\Parking_Management_System_FastAPI\src\helpers\handle_errors.py", line 19, in wrapper
    return_value = function(*args, **kwargs)
                   ^^^^^^^^^^^^^^^^^^^^^^^^^
  File "C:\PERSONAL\Parking_Management_System_FastAPI\src\helpers\access_decorator.py", line 21, in wrapper
    return fun(*args, **kwargs)
           ^^^^^^^^^^^^^^^^^^^^
  File "C:\PERSONAL\Parking_Management_System_FastAPI\src\helpers\validations.py", line 41, in wrapper
    return function(*args, **kwargs)
           ^^^^^^^^^^^^^^^^^^^^^^^^^
  File "C:\PERSONAL\Parking_Management_System_FastAPI\src\routers\parkingspace.py", line 58, in add_new_parking_space
    parking_space.add_parking_category(
  File "C:\PERSONAL\Parking_Management_System_FastAPI\src\controllers\parking_space.py", line 17, in add_parking_category
    db.update_item(
  File "C:\PERSONAL\Parking_Management_System_FastAPI\src\models\database.py", line 42, in update_item
    raise error
  File "C:\PERSONAL\Parking_Management_System_FastAPI\src\models\database.py", line 35, in update_item
    self.cursor.execute(query, *args)
  File "C:\Users\ahada\.virtualenvs\Parking_Management_System_FastAPI-yC4wlCPa\Lib\site-packages\mysql\connector\cursor_cext.py", line 330, in execute
    result = self._cnx.cmd_query(
             ^^^^^^^^^^^^^^^^^^^^
  File "C:\Users\ahada\.virtualenvs\Parking_Management_System_FastAPI-yC4wlCPa\Lib\site-packages\mysql\connector\opentelemetry\context_propagation.py", line 77, in wrapper
    return method(cnx, *args, **kwargs)
           ^^^^^^^^^^^^^^^^^^^^^^^^^^^^
  File "C:\Users\ahada\.virtualenvs\Parking_Management_System_FastAPI-yC4wlCPa\Lib\site-packages\mysql\connector\connection_cext.py", line 641, in cmd_query
    raise get_mysql_exception(
mysql.connector.errors.IntegrityError: 1062 (23000): Duplicate entry 'LMV' for key 'slot_category.slot_type_UNIQUE'

2023-12-11 16:03:53 DEBUG log_debug(23) Error Occurred: Traceback (most recent call last):
  File "C:\PERSONAL\Parking_Management_System_FastAPI\src\helpers\handle_errors.py", line 19, in wrapper
    return_value = function(*args, **kwargs)
                   ^^^^^^^^^^^^^^^^^^^^^^^^^
  File "C:\PERSONAL\Parking_Management_System_FastAPI\src\helpers\access_decorator.py", line 21, in wrapper
    return fun(*args, **kwargs)
           ^^^^^^^^^^^^^^^^^^^^
  File "C:\PERSONAL\Parking_Management_System_FastAPI\src\helpers\validations.py", line 41, in wrapper
    return function(*args, **kwargs)
           ^^^^^^^^^^^^^^^^^^^^^^^^^
  File "C:\PERSONAL\Parking_Management_System_FastAPI\src\routers\vehicles.py", line 51, in add_vehicle
    vehicle.add_vehicle(
  File "C:\PERSONAL\Parking_Management_System_FastAPI\src\controllers\vehicle.py", line 19, in add_vehicle
    raise ValueError(prompts.get("VEHICLE_ALREADY_EXISTS"))
ValueError: Vehicle Already Exists.

2023-12-11 16:04:16 DEBUG log_debug(23) Error Occurred: Traceback (most recent call last):
  File "C:\PERSONAL\Parking_Management_System_FastAPI\src\helpers\handle_errors.py", line 19, in wrapper
    return_value = function(*args, **kwargs)
                   ^^^^^^^^^^^^^^^^^^^^^^^^^
  File "C:\PERSONAL\Parking_Management_System_FastAPI\src\helpers\access_decorator.py", line 21, in wrapper
    return fun(*args, **kwargs)
           ^^^^^^^^^^^^^^^^^^^^
  File "C:\PERSONAL\Parking_Management_System_FastAPI\src\helpers\validations.py", line 41, in wrapper
    return function(*args, **kwargs)
           ^^^^^^^^^^^^^^^^^^^^^^^^^
  File "C:\PERSONAL\Parking_Management_System_FastAPI\src\routers\vehicles.py", line 51, in add_vehicle
    vehicle.add_vehicle(
  File "C:\PERSONAL\Parking_Management_System_FastAPI\src\controllers\vehicle.py", line 19, in add_vehicle
    raise ValueError(prompts.get("VEHICLE_ALREADY_EXISTS"))
ValueError: Vehicle Already Exists.

2023-12-11 16:04:28 DEBUG establish_connection(87) Connection established
2023-12-11 16:04:28 DEBUG log_debug(23) Error Occurred: Traceback (most recent call last):
  File "C:\Users\ahada\.virtualenvs\Parking_Management_System_FastAPI-yC4wlCPa\Lib\site-packages\mysql\connector\connection_cext.py", line 633, in cmd_query
    self._cmysql.query(
_mysql_connector.MySQLInterfaceError: Duplicate entry 'LMV' for key 'slot_category.slot_type_UNIQUE'

The above exception was the direct cause of the following exception:

Traceback (most recent call last):
  File "C:\PERSONAL\Parking_Management_System_FastAPI\src\helpers\handle_errors.py", line 19, in wrapper
    return_value = function(*args, **kwargs)
                   ^^^^^^^^^^^^^^^^^^^^^^^^^
  File "C:\PERSONAL\Parking_Management_System_FastAPI\src\helpers\access_decorator.py", line 21, in wrapper
    return fun(*args, **kwargs)
           ^^^^^^^^^^^^^^^^^^^^
  File "C:\PERSONAL\Parking_Management_System_FastAPI\src\helpers\validations.py", line 41, in wrapper
    return function(*args, **kwargs)
           ^^^^^^^^^^^^^^^^^^^^^^^^^
  File "C:\PERSONAL\Parking_Management_System_FastAPI\src\routers\parkingspace.py", line 58, in add_new_parking_space
    parking_space.add_parking_category(
  File "C:\PERSONAL\Parking_Management_System_FastAPI\src\controllers\parking_space.py", line 17, in add_parking_category
    db.update_item(
  File "C:\PERSONAL\Parking_Management_System_FastAPI\src\models\database.py", line 42, in update_item
    raise error
  File "C:\PERSONAL\Parking_Management_System_FastAPI\src\models\database.py", line 35, in update_item
    self.cursor.execute(query, *args)
  File "C:\Users\ahada\.virtualenvs\Parking_Management_System_FastAPI-yC4wlCPa\Lib\site-packages\mysql\connector\cursor_cext.py", line 330, in execute
    result = self._cnx.cmd_query(
             ^^^^^^^^^^^^^^^^^^^^
  File "C:\Users\ahada\.virtualenvs\Parking_Management_System_FastAPI-yC4wlCPa\Lib\site-packages\mysql\connector\opentelemetry\context_propagation.py", line 77, in wrapper
    return method(cnx, *args, **kwargs)
           ^^^^^^^^^^^^^^^^^^^^^^^^^^^^
  File "C:\Users\ahada\.virtualenvs\Parking_Management_System_FastAPI-yC4wlCPa\Lib\site-packages\mysql\connector\connection_cext.py", line 641, in cmd_query
    raise get_mysql_exception(
mysql.connector.errors.IntegrityError: 1062 (23000): Duplicate entry 'LMV' for key 'slot_category.slot_type_UNIQUE'

2023-12-11 16:05:24 DEBUG establish_connection(87) Connection established
2023-12-11 16:05:24 DEBUG log_debug(23) Error Occurred: Traceback (most recent call last):
  File "C:\Users\ahada\.virtualenvs\Parking_Management_System_FastAPI-yC4wlCPa\Lib\site-packages\mysql\connector\connection_cext.py", line 633, in cmd_query
    self._cmysql.query(
_mysql_connector.MySQLInterfaceError: Duplicate entry 'LMV' for key 'slot_category.slot_type_UNIQUE'

The above exception was the direct cause of the following exception:

Traceback (most recent call last):
  File "C:\PERSONAL\Parking_Management_System_FastAPI\src\helpers\handle_errors.py", line 19, in wrapper
    return_value = function(*args, **kwargs)
                   ^^^^^^^^^^^^^^^^^^^^^^^^^
  File "C:\PERSONAL\Parking_Management_System_FastAPI\src\helpers\access_decorator.py", line 21, in wrapper
    return fun(*args, **kwargs)
           ^^^^^^^^^^^^^^^^^^^^
  File "C:\PERSONAL\Parking_Management_System_FastAPI\src\helpers\validations.py", line 41, in wrapper
    return function(*args, **kwargs)
           ^^^^^^^^^^^^^^^^^^^^^^^^^
  File "C:\PERSONAL\Parking_Management_System_FastAPI\src\routers\parkingspace.py", line 58, in add_new_parking_space
    parking_space.add_parking_category(
  File "C:\PERSONAL\Parking_Management_System_FastAPI\src\controllers\parking_space.py", line 17, in add_parking_category
    db.update_item(
  File "C:\PERSONAL\Parking_Management_System_FastAPI\src\models\database.py", line 42, in update_item
    raise error
  File "C:\PERSONAL\Parking_Management_System_FastAPI\src\models\database.py", line 35, in update_item
    self.cursor.execute(query, *args)
  File "C:\Users\ahada\.virtualenvs\Parking_Management_System_FastAPI-yC4wlCPa\Lib\site-packages\mysql\connector\cursor_cext.py", line 330, in execute
    result = self._cnx.cmd_query(
             ^^^^^^^^^^^^^^^^^^^^
  File "C:\Users\ahada\.virtualenvs\Parking_Management_System_FastAPI-yC4wlCPa\Lib\site-packages\mysql\connector\opentelemetry\context_propagation.py", line 77, in wrapper
    return method(cnx, *args, **kwargs)
           ^^^^^^^^^^^^^^^^^^^^^^^^^^^^
  File "C:\Users\ahada\.virtualenvs\Parking_Management_System_FastAPI-yC4wlCPa\Lib\site-packages\mysql\connector\connection_cext.py", line 641, in cmd_query
    raise get_mysql_exception(
mysql.connector.errors.IntegrityError: 1062 (23000): Duplicate entry 'LMV' for key 'slot_category.slot_type_UNIQUE'

2023-12-11 16:05:52 DEBUG establish_connection(87) Connection established
2023-12-11 16:05:52 DEBUG log_debug(23) Error Occurred: Traceback (most recent call last):
  File "C:\Users\ahada\.virtualenvs\Parking_Management_System_FastAPI-yC4wlCPa\Lib\site-packages\mysql\connector\connection_cext.py", line 633, in cmd_query
    self._cmysql.query(
_mysql_connector.MySQLInterfaceError: Duplicate entry 'LMV' for key 'slot_category.slot_type_UNIQUE'

The above exception was the direct cause of the following exception:

Traceback (most recent call last):
  File "C:\PERSONAL\Parking_Management_System_FastAPI\src\helpers\handle_errors.py", line 19, in wrapper
    return_value = function(*args, **kwargs)
                   ^^^^^^^^^^^^^^^^^^^^^^^^^
  File "C:\PERSONAL\Parking_Management_System_FastAPI\src\helpers\access_decorator.py", line 21, in wrapper
    return fun(*args, **kwargs)
           ^^^^^^^^^^^^^^^^^^^^
  File "C:\PERSONAL\Parking_Management_System_FastAPI\src\helpers\validations.py", line 41, in wrapper
    return function(*args, **kwargs)
           ^^^^^^^^^^^^^^^^^^^^^^^^^
  File "C:\PERSONAL\Parking_Management_System_FastAPI\src\routers\parkingspace.py", line 58, in add_new_parking_space
    parking_space.add_parking_category(
  File "C:\PERSONAL\Parking_Management_System_FastAPI\src\controllers\parking_space.py", line 17, in add_parking_category
    db.update_item(
  File "C:\PERSONAL\Parking_Management_System_FastAPI\src\models\database.py", line 42, in update_item
    raise error
  File "C:\PERSONAL\Parking_Management_System_FastAPI\src\models\database.py", line 35, in update_item
    self.cursor.execute(query, *args)
  File "C:\Users\ahada\.virtualenvs\Parking_Management_System_FastAPI-yC4wlCPa\Lib\site-packages\mysql\connector\cursor_cext.py", line 330, in execute
    result = self._cnx.cmd_query(
             ^^^^^^^^^^^^^^^^^^^^
  File "C:\Users\ahada\.virtualenvs\Parking_Management_System_FastAPI-yC4wlCPa\Lib\site-packages\mysql\connector\opentelemetry\context_propagation.py", line 77, in wrapper
    return method(cnx, *args, **kwargs)
           ^^^^^^^^^^^^^^^^^^^^^^^^^^^^
  File "C:\Users\ahada\.virtualenvs\Parking_Management_System_FastAPI-yC4wlCPa\Lib\site-packages\mysql\connector\connection_cext.py", line 641, in cmd_query
    raise get_mysql_exception(
mysql.connector.errors.IntegrityError: 1062 (23000): Duplicate entry 'LMV' for key 'slot_category.slot_type_UNIQUE'

2023-12-11 16:06:02 DEBUG establish_connection(87) Connection established
2023-12-11 16:06:02 DEBUG log_debug(23) Error Occurred: Traceback (most recent call last):
  File "C:\Users\ahada\.virtualenvs\Parking_Management_System_FastAPI-yC4wlCPa\Lib\site-packages\mysql\connector\connection_cext.py", line 633, in cmd_query
    self._cmysql.query(
_mysql_connector.MySQLInterfaceError: Duplicate entry 'LMV' for key 'slot_category.slot_type_UNIQUE'

The above exception was the direct cause of the following exception:

Traceback (most recent call last):
  File "C:\PERSONAL\Parking_Management_System_FastAPI\src\helpers\handle_errors.py", line 19, in wrapper
    return_value = function(*args, **kwargs)
                   ^^^^^^^^^^^^^^^^^^^^^^^^^
  File "C:\PERSONAL\Parking_Management_System_FastAPI\src\helpers\access_decorator.py", line 21, in wrapper
    return fun(*args, **kwargs)
           ^^^^^^^^^^^^^^^^^^^^
  File "C:\PERSONAL\Parking_Management_System_FastAPI\src\helpers\validations.py", line 41, in wrapper
    return function(*args, **kwargs)
           ^^^^^^^^^^^^^^^^^^^^^^^^^
  File "C:\PERSONAL\Parking_Management_System_FastAPI\src\routers\parkingspace.py", line 58, in add_new_parking_space
    parking_space.add_parking_category(
  File "C:\PERSONAL\Parking_Management_System_FastAPI\src\controllers\parking_space.py", line 17, in add_parking_category
    db.update_item(
  File "C:\PERSONAL\Parking_Management_System_FastAPI\src\models\database.py", line 42, in update_item
    raise error
  File "C:\PERSONAL\Parking_Management_System_FastAPI\src\models\database.py", line 35, in update_item
    self.cursor.execute(query, *args)
  File "C:\Users\ahada\.virtualenvs\Parking_Management_System_FastAPI-yC4wlCPa\Lib\site-packages\mysql\connector\cursor_cext.py", line 330, in execute
    result = self._cnx.cmd_query(
             ^^^^^^^^^^^^^^^^^^^^
  File "C:\Users\ahada\.virtualenvs\Parking_Management_System_FastAPI-yC4wlCPa\Lib\site-packages\mysql\connector\opentelemetry\context_propagation.py", line 77, in wrapper
    return method(cnx, *args, **kwargs)
           ^^^^^^^^^^^^^^^^^^^^^^^^^^^^
  File "C:\Users\ahada\.virtualenvs\Parking_Management_System_FastAPI-yC4wlCPa\Lib\site-packages\mysql\connector\connection_cext.py", line 641, in cmd_query
    raise get_mysql_exception(
mysql.connector.errors.IntegrityError: 1062 (23000): Duplicate entry 'LMV' for key 'slot_category.slot_type_UNIQUE'

2023-12-11 16:06:06 DEBUG establish_connection(87) Connection established
2023-12-11 16:06:06 DEBUG log_debug(23) Error Occurred: Traceback (most recent call last):
  File "C:\Users\ahada\.virtualenvs\Parking_Management_System_FastAPI-yC4wlCPa\Lib\site-packages\mysql\connector\connection_cext.py", line 633, in cmd_query
    self._cmysql.query(
_mysql_connector.MySQLInterfaceError: Duplicate entry 'LMV' for key 'slot_category.slot_type_UNIQUE'

The above exception was the direct cause of the following exception:

Traceback (most recent call last):
  File "C:\PERSONAL\Parking_Management_System_FastAPI\src\helpers\handle_errors.py", line 19, in wrapper
    return_value = function(*args, **kwargs)
                   ^^^^^^^^^^^^^^^^^^^^^^^^^
  File "C:\PERSONAL\Parking_Management_System_FastAPI\src\helpers\access_decorator.py", line 21, in wrapper
    return fun(*args, **kwargs)
           ^^^^^^^^^^^^^^^^^^^^
  File "C:\PERSONAL\Parking_Management_System_FastAPI\src\helpers\validations.py", line 41, in wrapper
    return function(*args, **kwargs)
           ^^^^^^^^^^^^^^^^^^^^^^^^^
  File "C:\PERSONAL\Parking_Management_System_FastAPI\src\routers\parkingspace.py", line 58, in add_new_parking_space
    parking_space.add_parking_category(
  File "C:\PERSONAL\Parking_Management_System_FastAPI\src\controllers\parking_space.py", line 17, in add_parking_category
    db.update_item(
  File "C:\PERSONAL\Parking_Management_System_FastAPI\src\models\database.py", line 42, in update_item
    raise error
  File "C:\PERSONAL\Parking_Management_System_FastAPI\src\models\database.py", line 35, in update_item
    self.cursor.execute(query, *args)
  File "C:\Users\ahada\.virtualenvs\Parking_Management_System_FastAPI-yC4wlCPa\Lib\site-packages\mysql\connector\cursor_cext.py", line 330, in execute
    result = self._cnx.cmd_query(
             ^^^^^^^^^^^^^^^^^^^^
  File "C:\Users\ahada\.virtualenvs\Parking_Management_System_FastAPI-yC4wlCPa\Lib\site-packages\mysql\connector\opentelemetry\context_propagation.py", line 77, in wrapper
    return method(cnx, *args, **kwargs)
           ^^^^^^^^^^^^^^^^^^^^^^^^^^^^
  File "C:\Users\ahada\.virtualenvs\Parking_Management_System_FastAPI-yC4wlCPa\Lib\site-packages\mysql\connector\connection_cext.py", line 641, in cmd_query
    raise get_mysql_exception(
mysql.connector.errors.IntegrityError: 1062 (23000): Duplicate entry 'LMV' for key 'slot_category.slot_type_UNIQUE'

2023-12-11 16:17:38 DEBUG log_debug(23) Error Occurred: Traceback (most recent call last):
  File "C:\PERSONAL\Parking_Management_System_FastAPI\src\helpers\handle_errors.py", line 19, in wrapper
    return_value = function(*args, **kwargs)
                   ^^^^^^^^^^^^^^^^^^^^^^^^^
  File "C:\PERSONAL\Parking_Management_System_FastAPI\src\helpers\access_decorator.py", line 21, in wrapper
    return fun(*args, **kwargs)
           ^^^^^^^^^^^^^^^^^^^^
  File "C:\PERSONAL\Parking_Management_System_FastAPI\src\helpers\validations.py", line 41, in wrapper
    return function(*args, **kwargs)
           ^^^^^^^^^^^^^^^^^^^^^^^^^
  File "C:\PERSONAL\Parking_Management_System_FastAPI\src\routers\vehicles.py", line 51, in add_vehicle
    vehicle.add_vehicle(
  File "C:\PERSONAL\Parking_Management_System_FastAPI\src\controllers\vehicle.py", line 19, in add_vehicle
    raise ValueError(prompts.get("VEHICLE_ALREADY_EXISTS"))
ValueError: Vehicle Already Exists.

2023-12-11 16:18:34 DEBUG establish_connection(87) Connection established
2023-12-11 16:18:34 DEBUG log_debug(23) Error Occurred: Traceback (most recent call last):
  File "C:\Users\ahada\.virtualenvs\Parking_Management_System_FastAPI-yC4wlCPa\Lib\site-packages\mysql\connector\connection_cext.py", line 633, in cmd_query
    self._cmysql.query(
_mysql_connector.MySQLInterfaceError: Duplicate entry 'LMV' for key 'slot_category.slot_type_UNIQUE'

The above exception was the direct cause of the following exception:

Traceback (most recent call last):
  File "C:\PERSONAL\Parking_Management_System_FastAPI\src\helpers\handle_errors.py", line 19, in wrapper
    return_value = function(*args, **kwargs)
                   ^^^^^^^^^^^^^^^^^^^^^^^^^
  File "C:\PERSONAL\Parking_Management_System_FastAPI\src\helpers\access_decorator.py", line 21, in wrapper
    return fun(*args, **kwargs)
           ^^^^^^^^^^^^^^^^^^^^
  File "C:\PERSONAL\Parking_Management_System_FastAPI\src\helpers\validations.py", line 41, in wrapper
    return function(*args, **kwargs)
           ^^^^^^^^^^^^^^^^^^^^^^^^^
  File "C:\PERSONAL\Parking_Management_System_FastAPI\src\routers\parkingspace.py", line 58, in add_new_parking_space
    parking_space.add_parking_category(
  File "C:\PERSONAL\Parking_Management_System_FastAPI\src\controllers\parking_space.py", line 17, in add_parking_category
    db.update_item(
  File "C:\PERSONAL\Parking_Management_System_FastAPI\src\models\database.py", line 42, in update_item
    raise error
  File "C:\PERSONAL\Parking_Management_System_FastAPI\src\models\database.py", line 35, in update_item
    self.cursor.execute(query, *args)
  File "C:\Users\ahada\.virtualenvs\Parking_Management_System_FastAPI-yC4wlCPa\Lib\site-packages\mysql\connector\cursor_cext.py", line 330, in execute
    result = self._cnx.cmd_query(
             ^^^^^^^^^^^^^^^^^^^^
  File "C:\Users\ahada\.virtualenvs\Parking_Management_System_FastAPI-yC4wlCPa\Lib\site-packages\mysql\connector\opentelemetry\context_propagation.py", line 77, in wrapper
    return method(cnx, *args, **kwargs)
           ^^^^^^^^^^^^^^^^^^^^^^^^^^^^
  File "C:\Users\ahada\.virtualenvs\Parking_Management_System_FastAPI-yC4wlCPa\Lib\site-packages\mysql\connector\connection_cext.py", line 641, in cmd_query
    raise get_mysql_exception(
mysql.connector.errors.IntegrityError: 1062 (23000): Duplicate entry 'LMV' for key 'slot_category.slot_type_UNIQUE'

2023-12-11 16:35:23 DEBUG establish_connection(87) Connection established
2023-12-11 16:35:23 DEBUG log_debug(23) Error Occurred: Traceback (most recent call last):
  File "C:\Users\ahada\.virtualenvs\Parking_Management_System_FastAPI-yC4wlCPa\Lib\site-packages\mysql\connector\connection_cext.py", line 633, in cmd_query
    self._cmysql.query(
_mysql_connector.MySQLInterfaceError: Duplicate entry 'LMV' for key 'slot_category.slot_type_UNIQUE'

The above exception was the direct cause of the following exception:

Traceback (most recent call last):
  File "C:\PERSONAL\Parking_Management_System_FastAPI\src\helpers\handle_errors.py", line 19, in wrapper
    return_value = function(*args, **kwargs)
                   ^^^^^^^^^^^^^^^^^^^^^^^^^
  File "C:\PERSONAL\Parking_Management_System_FastAPI\src\helpers\access_decorator.py", line 21, in wrapper
    return fun(*args, **kwargs)
           ^^^^^^^^^^^^^^^^^^^^
  File "C:\PERSONAL\Parking_Management_System_FastAPI\src\helpers\validations.py", line 41, in wrapper
    return function(*args, **kwargs)
           ^^^^^^^^^^^^^^^^^^^^^^^^^
  File "C:\PERSONAL\Parking_Management_System_FastAPI\src\routers\parkingspace.py", line 58, in add_new_parking_space
    parking_space.add_parking_category(
  File "C:\PERSONAL\Parking_Management_System_FastAPI\src\controllers\parking_space.py", line 17, in add_parking_category
    db.update_item(
  File "C:\PERSONAL\Parking_Management_System_FastAPI\src\models\database.py", line 42, in update_item
    raise error
  File "C:\PERSONAL\Parking_Management_System_FastAPI\src\models\database.py", line 35, in update_item
    self.cursor.execute(query, *args)
  File "C:\Users\ahada\.virtualenvs\Parking_Management_System_FastAPI-yC4wlCPa\Lib\site-packages\mysql\connector\cursor_cext.py", line 330, in execute
    result = self._cnx.cmd_query(
             ^^^^^^^^^^^^^^^^^^^^
  File "C:\Users\ahada\.virtualenvs\Parking_Management_System_FastAPI-yC4wlCPa\Lib\site-packages\mysql\connector\opentelemetry\context_propagation.py", line 77, in wrapper
    return method(cnx, *args, **kwargs)
           ^^^^^^^^^^^^^^^^^^^^^^^^^^^^
  File "C:\Users\ahada\.virtualenvs\Parking_Management_System_FastAPI-yC4wlCPa\Lib\site-packages\mysql\connector\connection_cext.py", line 641, in cmd_query
    raise get_mysql_exception(
mysql.connector.errors.IntegrityError: 1062 (23000): Duplicate entry 'LMV' for key 'slot_category.slot_type_UNIQUE'

2023-12-11 16:35:29 DEBUG establish_connection(87) Connection established
2023-12-11 16:35:29 DEBUG log_debug(23) Error Occurred: Traceback (most recent call last):
  File "C:\Users\ahada\.virtualenvs\Parking_Management_System_FastAPI-yC4wlCPa\Lib\site-packages\mysql\connector\connection_cext.py", line 633, in cmd_query
    self._cmysql.query(
_mysql_connector.MySQLInterfaceError: Duplicate entry 'LMV' for key 'slot_category.slot_type_UNIQUE'

The above exception was the direct cause of the following exception:

Traceback (most recent call last):
  File "C:\PERSONAL\Parking_Management_System_FastAPI\src\helpers\handle_errors.py", line 19, in wrapper
    return_value = function(*args, **kwargs)
                   ^^^^^^^^^^^^^^^^^^^^^^^^^
  File "C:\PERSONAL\Parking_Management_System_FastAPI\src\helpers\access_decorator.py", line 21, in wrapper
    return fun(*args, **kwargs)
           ^^^^^^^^^^^^^^^^^^^^
  File "C:\PERSONAL\Parking_Management_System_FastAPI\src\helpers\validations.py", line 41, in wrapper
    return function(*args, **kwargs)
           ^^^^^^^^^^^^^^^^^^^^^^^^^
  File "C:\PERSONAL\Parking_Management_System_FastAPI\src\routers\parkingspace.py", line 58, in add_new_parking_space
    parking_space.add_parking_category(
  File "C:\PERSONAL\Parking_Management_System_FastAPI\src\controllers\parking_space.py", line 17, in add_parking_category
    db.update_item(
  File "C:\PERSONAL\Parking_Management_System_FastAPI\src\models\database.py", line 42, in update_item
    raise error
  File "C:\PERSONAL\Parking_Management_System_FastAPI\src\models\database.py", line 35, in update_item
    self.cursor.execute(query, *args)
  File "C:\Users\ahada\.virtualenvs\Parking_Management_System_FastAPI-yC4wlCPa\Lib\site-packages\mysql\connector\cursor_cext.py", line 330, in execute
    result = self._cnx.cmd_query(
             ^^^^^^^^^^^^^^^^^^^^
  File "C:\Users\ahada\.virtualenvs\Parking_Management_System_FastAPI-yC4wlCPa\Lib\site-packages\mysql\connector\opentelemetry\context_propagation.py", line 77, in wrapper
    return method(cnx, *args, **kwargs)
           ^^^^^^^^^^^^^^^^^^^^^^^^^^^^
  File "C:\Users\ahada\.virtualenvs\Parking_Management_System_FastAPI-yC4wlCPa\Lib\site-packages\mysql\connector\connection_cext.py", line 641, in cmd_query
    raise get_mysql_exception(
mysql.connector.errors.IntegrityError: 1062 (23000): Duplicate entry 'LMV' for key 'slot_category.slot_type_UNIQUE'

2023-12-11 16:35:33 DEBUG establish_connection(87) Connection established
2023-12-11 16:35:33 DEBUG log_debug(23) Error Occurred: Traceback (most recent call last):
  File "C:\Users\ahada\.virtualenvs\Parking_Management_System_FastAPI-yC4wlCPa\Lib\site-packages\mysql\connector\connection_cext.py", line 633, in cmd_query
    self._cmysql.query(
_mysql_connector.MySQLInterfaceError: Duplicate entry 'LMV' for key 'slot_category.slot_type_UNIQUE'

The above exception was the direct cause of the following exception:

Traceback (most recent call last):
  File "C:\PERSONAL\Parking_Management_System_FastAPI\src\helpers\handle_errors.py", line 19, in wrapper
    return_value = function(*args, **kwargs)
                   ^^^^^^^^^^^^^^^^^^^^^^^^^
  File "C:\PERSONAL\Parking_Management_System_FastAPI\src\helpers\access_decorator.py", line 21, in wrapper
    return fun(*args, **kwargs)
           ^^^^^^^^^^^^^^^^^^^^
  File "C:\PERSONAL\Parking_Management_System_FastAPI\src\helpers\validations.py", line 41, in wrapper
    return function(*args, **kwargs)
           ^^^^^^^^^^^^^^^^^^^^^^^^^
  File "C:\PERSONAL\Parking_Management_System_FastAPI\src\routers\parkingspace.py", line 58, in add_new_parking_space
    parking_space.add_parking_category(
  File "C:\PERSONAL\Parking_Management_System_FastAPI\src\controllers\parking_space.py", line 17, in add_parking_category
    db.update_item(
  File "C:\PERSONAL\Parking_Management_System_FastAPI\src\models\database.py", line 42, in update_item
    raise error
  File "C:\PERSONAL\Parking_Management_System_FastAPI\src\models\database.py", line 35, in update_item
    self.cursor.execute(query, *args)
  File "C:\Users\ahada\.virtualenvs\Parking_Management_System_FastAPI-yC4wlCPa\Lib\site-packages\mysql\connector\cursor_cext.py", line 330, in execute
    result = self._cnx.cmd_query(
             ^^^^^^^^^^^^^^^^^^^^
  File "C:\Users\ahada\.virtualenvs\Parking_Management_System_FastAPI-yC4wlCPa\Lib\site-packages\mysql\connector\opentelemetry\context_propagation.py", line 77, in wrapper
    return method(cnx, *args, **kwargs)
           ^^^^^^^^^^^^^^^^^^^^^^^^^^^^
  File "C:\Users\ahada\.virtualenvs\Parking_Management_System_FastAPI-yC4wlCPa\Lib\site-packages\mysql\connector\connection_cext.py", line 641, in cmd_query
    raise get_mysql_exception(
mysql.connector.errors.IntegrityError: 1062 (23000): Duplicate entry 'LMV' for key 'slot_category.slot_type_UNIQUE'

2023-12-11 17:51:32 DEBUG log_debug(23) Error Occurred: Traceback (most recent call last):
  File "C:\PERSONAL\Parking_Management_System_FastAPI\src\helpers\handle_errors.py", line 19, in wrapper
    return_value = function(*args, **kwargs)
                   ^^^^^^^^^^^^^^^^^^^^^^^^^
  File "C:\PERSONAL\Parking_Management_System_FastAPI\src\helpers\validations.py", line 41, in wrapper
    return function(*args, **kwargs)
           ^^^^^^^^^^^^^^^^^^^^^^^^^
  File "C:\PERSONAL\Parking_Management_System_FastAPI\src\routers\auth.py", line 21, in login
    instance.authenticate()
  File "C:\PERSONAL\Parking_Management_System_FastAPI\src\controllers\login.py", line 36, in authenticate
    raise AuthenticationError(prompts.get("INVALID_DETAILS"))
src.helpers.errors.AuthenticationError: Invalid Login Details

2023-12-11 18:01:48 DEBUG log_debug(23) Error Occurred: Traceback (most recent call last):
  File "C:\PERSONAL\Parking_Management_System_FastAPI\src\helpers\handle_errors.py", line 19, in wrapper
    return_value = function(*args, **kwargs)
                   ^^^^^^^^^^^^^^^^^^^^^^^^^
  File "C:\PERSONAL\Parking_Management_System_FastAPI\src\helpers\access_decorator.py", line 21, in wrapper
    return fun(*args, **kwargs)
           ^^^^^^^^^^^^^^^^^^^^
  File "C:\PERSONAL\Parking_Management_System_FastAPI\src\helpers\validations.py", line 41, in wrapper
    return function(*args, **kwargs)
           ^^^^^^^^^^^^^^^^^^^^^^^^^
  File "C:\PERSONAL\Parking_Management_System_FastAPI\src\routers\vehicles.py", line 51, in add_vehicle
    vehicle.add_vehicle(
  File "C:\PERSONAL\Parking_Management_System_FastAPI\src\controllers\vehicle.py", line 19, in add_vehicle
    raise ValueError(prompts.get("VEHICLE_ALREADY_EXISTS"))
ValueError: Vehicle Already Exists.

2023-12-11 18:03:52 DEBUG log_debug(23) Error Occurred: Traceback (most recent call last):
  File "C:\PERSONAL\Parking_Management_System_FastAPI\src\helpers\handle_errors.py", line 19, in wrapper
    return_value = function(*args, **kwargs)
                   ^^^^^^^^^^^^^^^^^^^^^^^^^
  File "C:\PERSONAL\Parking_Management_System_FastAPI\src\helpers\access_decorator.py", line 21, in wrapper
    return fun(*args, **kwargs)
           ^^^^^^^^^^^^^^^^^^^^
  File "C:\PERSONAL\Parking_Management_System_FastAPI\src\helpers\validations.py", line 41, in wrapper
    return function(*args, **kwargs)
           ^^^^^^^^^^^^^^^^^^^^^^^^^
  File "C:\PERSONAL\Parking_Management_System_FastAPI\src\routers\vehicles.py", line 51, in add_vehicle
    vehicle.add_vehicle(
  File "C:\PERSONAL\Parking_Management_System_FastAPI\src\controllers\vehicle.py", line 19, in add_vehicle
    raise ValueError(prompts.get("VEHICLE_ALREADY_EXISTS"))
ValueError: Vehicle Already Exists.

2023-12-11 18:04:07 DEBUG log_debug(23) Error Occurred: Traceback (most recent call last):
  File "C:\PERSONAL\Parking_Management_System_FastAPI\src\helpers\handle_errors.py", line 19, in wrapper
    return_value = function(*args, **kwargs)
                   ^^^^^^^^^^^^^^^^^^^^^^^^^
  File "C:\PERSONAL\Parking_Management_System_FastAPI\src\helpers\access_decorator.py", line 21, in wrapper
    return fun(*args, **kwargs)
           ^^^^^^^^^^^^^^^^^^^^
  File "C:\PERSONAL\Parking_Management_System_FastAPI\src\helpers\validations.py", line 41, in wrapper
    return function(*args, **kwargs)
           ^^^^^^^^^^^^^^^^^^^^^^^^^
  File "C:\PERSONAL\Parking_Management_System_FastAPI\src\routers\vehicles.py", line 51, in add_vehicle
    vehicle.add_vehicle(
  File "C:\PERSONAL\Parking_Management_System_FastAPI\src\controllers\vehicle.py", line 19, in add_vehicle
    raise ValueError(prompts.get("VEHICLE_ALREADY_EXISTS"))
ValueError: Vehicle Already Exists.

2023-12-11 18:17:05 DEBUG log_debug(23) Error Occurred: Traceback (most recent call last):
  File "C:\PERSONAL\Parking_Management_System_FastAPI\src\helpers\handle_errors.py", line 19, in wrapper
    return_value = function(*args, **kwargs)
                   ^^^^^^^^^^^^^^^^^^^^^^^^^
  File "C:\PERSONAL\Parking_Management_System_FastAPI\src\helpers\validations.py", line 41, in wrapper
    return function(*args, **kwargs)
           ^^^^^^^^^^^^^^^^^^^^^^^^^
  File "C:\PERSONAL\Parking_Management_System_FastAPI\src\routers\auth.py", line 21, in login
    instance.authenticate()
  File "C:\PERSONAL\Parking_Management_System_FastAPI\src\controllers\login.py", line 36, in authenticate
    raise AuthenticationError(prompts.get("INVALID_DETAILS"))
src.helpers.errors.AuthenticationError: Invalid Login Details

2023-12-11 18:17:09 DEBUG log_debug(23) Error Occurred: Traceback (most recent call last):
  File "C:\PERSONAL\Parking_Management_System_FastAPI\src\helpers\handle_errors.py", line 19, in wrapper
    return_value = function(*args, **kwargs)
                   ^^^^^^^^^^^^^^^^^^^^^^^^^
  File "C:\PERSONAL\Parking_Management_System_FastAPI\src\helpers\validations.py", line 41, in wrapper
    return function(*args, **kwargs)
           ^^^^^^^^^^^^^^^^^^^^^^^^^
  File "C:\PERSONAL\Parking_Management_System_FastAPI\src\routers\auth.py", line 21, in login
    instance.authenticate()
  File "C:\PERSONAL\Parking_Management_System_FastAPI\src\controllers\login.py", line 36, in authenticate
    raise AuthenticationError(prompts.get("INVALID_DETAILS"))
src.helpers.errors.AuthenticationError: Invalid Login Details

2023-12-11 18:17:10 DEBUG log_debug(23) Error Occurred: Traceback (most recent call last):
  File "C:\PERSONAL\Parking_Management_System_FastAPI\src\helpers\handle_errors.py", line 19, in wrapper
    return_value = function(*args, **kwargs)
                   ^^^^^^^^^^^^^^^^^^^^^^^^^
  File "C:\PERSONAL\Parking_Management_System_FastAPI\src\helpers\validations.py", line 41, in wrapper
    return function(*args, **kwargs)
           ^^^^^^^^^^^^^^^^^^^^^^^^^
  File "C:\PERSONAL\Parking_Management_System_FastAPI\src\routers\auth.py", line 21, in login
    instance.authenticate()
  File "C:\PERSONAL\Parking_Management_System_FastAPI\src\controllers\login.py", line 36, in authenticate
    raise AuthenticationError(prompts.get("INVALID_DETAILS"))
src.helpers.errors.AuthenticationError: Invalid Login Details

2023-12-12 10:01:18 DEBUG log_debug(23) Error Occurred: Traceback (most recent call last):
  File "C:\PERSONAL\Parking_Management_System_FastAPI\src\helpers\jwt_helpers.py", line 25, in validate_access_token
    payload = jwt.decode(token, SECRET_KEY, algorithms=[ALGORITHM])
              ^^^^^^^^^^^^^^^^^^^^^^^^^^^^^^^^^^^^^^^^^^^^^^^^^^^^^
  File "C:\Users\ahada\.virtualenvs\Parking_Management_System_FastAPI-yC4wlCPa\Lib\site-packages\jwt\api_jwt.py", line 210, in decode
    decoded = self.decode_complete(
              ^^^^^^^^^^^^^^^^^^^^^
  File "C:\Users\ahada\.virtualenvs\Parking_Management_System_FastAPI-yC4wlCPa\Lib\site-packages\jwt\api_jwt.py", line 162, in decode_complete
    self._validate_claims(
  File "C:\Users\ahada\.virtualenvs\Parking_Management_System_FastAPI-yC4wlCPa\Lib\site-packages\jwt\api_jwt.py", line 248, in _validate_claims
    self._validate_exp(payload, now, leeway)
  File "C:\Users\ahada\.virtualenvs\Parking_Management_System_FastAPI-yC4wlCPa\Lib\site-packages\jwt\api_jwt.py", line 306, in _validate_exp
    raise ExpiredSignatureError("Signature has expired")
jwt.exceptions.ExpiredSignatureError: Signature has expired

The above exception was the direct cause of the following exception:

Traceback (most recent call last):
  File "C:\PERSONAL\Parking_Management_System_FastAPI\src\helpers\handle_errors.py", line 19, in wrapper
    return_value = function(*args, **kwargs)
                   ^^^^^^^^^^^^^^^^^^^^^^^^^
  File "C:\PERSONAL\Parking_Management_System_FastAPI\src\helpers\access_decorator.py", line 14, in wrapper
    token = validate_access_token(request=request)
            ^^^^^^^^^^^^^^^^^^^^^^^^^^^^^^^^^^^^^^
  File "C:\PERSONAL\Parking_Management_System_FastAPI\src\helpers\jwt_helpers.py", line 27, in validate_access_token
    raise UnauthorizedError(prompts.get(
src.helpers.errors.UnauthorizedError: Token Expired

2023-12-12 12:46:22 DEBUG log_debug(23) Error Occurred: Traceback (most recent call last):
  File "C:\PERSONAL\Parking_Management_System_FastAPI\src\helpers\handle_errors.py", line 19, in wrapper
    return_value = function(*args, **kwargs)
                   ^^^^^^^^^^^^^^^^^^^^^^^^^
  File "C:\PERSONAL\Parking_Management_System_FastAPI\src\helpers\validations.py", line 41, in wrapper
    return function(*args, **kwargs)
           ^^^^^^^^^^^^^^^^^^^^^^^^^
  File "C:\PERSONAL\Parking_Management_System_FastAPI\src\helpers\access_decorator.py", line 21, in wrapper
    return fun(*args, **kwargs)
           ^^^^^^^^^^^^^^^^^^^^
  File "C:\PERSONAL\Parking_Management_System_FastAPI\src\routers\slot.py", line 32, in occupy_slot
    slot.assign_slot(request_data.get("slot_number"), request_data.get(
  File "C:\PERSONAL\Parking_Management_System_FastAPI\src\controllers\slot.py", line 19, in assign_slot
    self.__is_already_parked(vehicle_number)
  File "C:\PERSONAL\Parking_Management_System_FastAPI\src\controllers\slot.py", line 112, in __is_already_parked
    raise ConflictError(prompts.get("VEHICLE_ALREADY_PARKED"))
src.helpers.errors.ConflictError: Vehicle Already Parked.

2023-12-12 16:52:40 DEBUG log_debug(23) Error Occurred: Traceback (most recent call last):
  File "C:\PERSONAL\Parking_Management_System_FastAPI\src\helpers\handle_errors.py", line 19, in wrapper
    return_value = function(*args, **kwargs)
                   ^^^^^^^^^^^^^^^^^^^^^^^^^
  File "C:\PERSONAL\Parking_Management_System_FastAPI\src\helpers\validations.py", line 41, in wrapper
    return function(*args, **kwargs)
           ^^^^^^^^^^^^^^^^^^^^^^^^^
  File "C:\PERSONAL\Parking_Management_System_FastAPI\src\helpers\access_decorator.py", line 21, in wrapper
    return fun(*args, **kwargs)
           ^^^^^^^^^^^^^^^^^^^^
  File "C:\PERSONAL\Parking_Management_System_FastAPI\src\routers\slot.py", line 32, in occupy_slot
    slot.assign_slot(request_data.get("slot_number"), request_data.get(
  File "C:\PERSONAL\Parking_Management_System_FastAPI\src\controllers\slot.py", line 19, in assign_slot
    self.__is_already_parked(vehicle_number)
  File "C:\PERSONAL\Parking_Management_System_FastAPI\src\controllers\slot.py", line 112, in __is_already_parked
    raise ConflictError(prompts.get("VEHICLE_ALREADY_PARKED"))
src.helpers.errors.ConflictError: Vehicle Already Parked.

2023-12-12 16:56:51 DEBUG log_debug(23) Error Occurred: Traceback (most recent call last):
  File "C:\PERSONAL\Parking_Management_System_FastAPI\src\helpers\jwt_helpers.py", line 25, in validate_access_token
    payload = jwt.decode(token, SECRET_KEY, algorithms=[ALGORITHM])
              ^^^^^^^^^^^^^^^^^^^^^^^^^^^^^^^^^^^^^^^^^^^^^^^^^^^^^
  File "C:\Users\ahada\.virtualenvs\Parking_Management_System_FastAPI-yC4wlCPa\Lib\site-packages\jwt\api_jwt.py", line 210, in decode
    decoded = self.decode_complete(
              ^^^^^^^^^^^^^^^^^^^^^
  File "C:\Users\ahada\.virtualenvs\Parking_Management_System_FastAPI-yC4wlCPa\Lib\site-packages\jwt\api_jwt.py", line 162, in decode_complete
    self._validate_claims(
  File "C:\Users\ahada\.virtualenvs\Parking_Management_System_FastAPI-yC4wlCPa\Lib\site-packages\jwt\api_jwt.py", line 248, in _validate_claims
    self._validate_exp(payload, now, leeway)
  File "C:\Users\ahada\.virtualenvs\Parking_Management_System_FastAPI-yC4wlCPa\Lib\site-packages\jwt\api_jwt.py", line 306, in _validate_exp
    raise ExpiredSignatureError("Signature has expired")
jwt.exceptions.ExpiredSignatureError: Signature has expired

The above exception was the direct cause of the following exception:

Traceback (most recent call last):
  File "C:\PERSONAL\Parking_Management_System_FastAPI\src\helpers\handle_errors.py", line 19, in wrapper
    return_value = function(*args, **kwargs)
                   ^^^^^^^^^^^^^^^^^^^^^^^^^
  File "C:\PERSONAL\Parking_Management_System_FastAPI\src\helpers\access_decorator.py", line 14, in wrapper
    token = validate_access_token(request=request)
            ^^^^^^^^^^^^^^^^^^^^^^^^^^^^^^^^^^^^^^
  File "C:\PERSONAL\Parking_Management_System_FastAPI\src\helpers\jwt_helpers.py", line 27, in validate_access_token
    raise UnauthorizedError(prompts.get(
src.helpers.errors.UnauthorizedError: Token Expired

2023-12-12 16:57:12 DEBUG log_debug(23) Error Occurred: Traceback (most recent call last):
  File "C:\PERSONAL\Parking_Management_System_FastAPI\src\helpers\handle_errors.py", line 19, in wrapper
    return_value = function(*args, **kwargs)
                   ^^^^^^^^^^^^^^^^^^^^^^^^^
  File "C:\PERSONAL\Parking_Management_System_FastAPI\src\helpers\access_decorator.py", line 21, in wrapper
    return fun(*args, **kwargs)
           ^^^^^^^^^^^^^^^^^^^^
  File "C:\PERSONAL\Parking_Management_System_FastAPI\src\routers\slot.py", line 56, in unassign_slot
    slot_details = slot.unassign_slot(vehicle_number)
                   ^^^^^^^^^^^^^^^^^^^^^^^^^^^^^^^^^^
  File "C:\PERSONAL\Parking_Management_System_FastAPI\src\controllers\slot.py", line 30, in unassign_slot
    slot_details = self.__get_slot_details_by_vehicle(vehicle_number)
                   ^^^^^^^^^^^^^^^^^^^^^^^^^^^^^^^^^^^^^^^^^^^^^^^^^^
  File "C:\PERSONAL\Parking_Management_System_FastAPI\src\controllers\slot.py", line 144, in __get_slot_details_by_vehicle
    raise ValueError(prompts.get("VEHICLE_NOT_PARKED"))
ValueError: Vehicle do not have any assigned slot.

2023-12-12 16:59:44 DEBUG establish_connection(87) Connection established
2023-12-12 16:59:44 DEBUG log_debug(23) Error Occurred: Traceback (most recent call last):
  File "C:\Users\ahada\.virtualenvs\Parking_Management_System_FastAPI-yC4wlCPa\Lib\site-packages\mysql\connector\connection_cext.py", line 633, in cmd_query
    self._cmysql.query(
_mysql_connector.MySQLInterfaceError: Lost connection to MySQL server during query

The above exception was the direct cause of the following exception:

Traceback (most recent call last):
  File "C:\PERSONAL\Parking_Management_System_FastAPI\src\controllers\parking_space.py", line 107, in __get_parking_space_details
    vehicle_category_data = db.get_multiple_items(sql_queries.get("vehicle_category_data"))
                            ^^^^^^^^^^^^^^^^^^^^^^^^^^^^^^^^^^^^^^^^^^^^^^^^^^^^^^^^^^^^^^^
  File "C:\PERSONAL\Parking_Management_System_FastAPI\src\models\database.py", line 30, in get_multiple_items
    raise error
  File "C:\PERSONAL\Parking_Management_System_FastAPI\src\models\database.py", line 25, in get_multiple_items
    self.cursor.execute(query, *args)
  File "C:\Users\ahada\.virtualenvs\Parking_Management_System_FastAPI-yC4wlCPa\Lib\site-packages\mysql\connector\cursor_cext.py", line 330, in execute
    result = self._cnx.cmd_query(
             ^^^^^^^^^^^^^^^^^^^^
  File "C:\Users\ahada\.virtualenvs\Parking_Management_System_FastAPI-yC4wlCPa\Lib\site-packages\mysql\connector\opentelemetry\context_propagation.py", line 77, in wrapper
    return method(cnx, *args, **kwargs)
           ^^^^^^^^^^^^^^^^^^^^^^^^^^^^
  File "C:\Users\ahada\.virtualenvs\Parking_Management_System_FastAPI-yC4wlCPa\Lib\site-packages\mysql\connector\connection_cext.py", line 641, in cmd_query
    raise get_mysql_exception(
mysql.connector.errors.OperationalError: 2013 (HY000): Lost connection to MySQL server during query

The above exception was the direct cause of the following exception:

Traceback (most recent call last):
  File "C:\PERSONAL\Parking_Management_System_FastAPI\src\controllers\parking_space.py", line 95, in get_parking_capacity
    vehicle_category_data = self.__get_parking_space_details()
                            ^^^^^^^^^^^^^^^^^^^^^^^^^^^^^^^^^^
  File "C:\PERSONAL\Parking_Management_System_FastAPI\src\controllers\parking_space.py", line 110, in __get_parking_space_details
    raise ResourceWarning(prompts.get("FETCH_PARKING_SPACE_ERROR")) from exc
ResourceWarning: Cannot Fetch Vehicle Category Data.

The above exception was the direct cause of the following exception:

Traceback (most recent call last):
  File "C:\PERSONAL\Parking_Management_System_FastAPI\src\helpers\handle_errors.py", line 19, in wrapper
    return_value = function(*args, **kwargs)
                   ^^^^^^^^^^^^^^^^^^^^^^^^^
  File "C:\PERSONAL\Parking_Management_System_FastAPI\src\helpers\access_decorator.py", line 21, in wrapper
    return fun(*args, **kwargs)
           ^^^^^^^^^^^^^^^^^^^^
  File "C:\PERSONAL\Parking_Management_System_FastAPI\src\routers\slot.py", line 44, in get_slot_table
    slot_table = slot.get_all_slot_status(slot_type)
                 ^^^^^^^^^^^^^^^^^^^^^^^^^^^^^^^^^^^
  File "C:\PERSONAL\Parking_Management_System_FastAPI\src\controllers\slot.py", line 75, in get_all_slot_status
    slot_type_capacity = self.get_parking_capacity(vehicle_type)
                         ^^^^^^^^^^^^^^^^^^^^^^^^^^^^^^^^^^^^^^^
  File "C:\PERSONAL\Parking_Management_System_FastAPI\src\controllers\parking_space.py", line 101, in get_parking_capacity
    raise ResourceWarning(prompts.get("FETCH_PARKING_CAPACITY_ERROR")) from exc
ResourceWarning: Cannot Fetch Parking Capacity.

2023-12-18 11:21:27 DEBUG log_debug(23) Error Occurred: Traceback (most recent call last):
  File "C:\PERSONAL\Parking_Management_System_FastAPI\src\helpers\jwt_helpers.py", line 25, in validate_access_token
    payload = jwt.decode(token, SECRET_KEY, algorithms=[ALGORITHM])
              ^^^^^^^^^^^^^^^^^^^^^^^^^^^^^^^^^^^^^^^^^^^^^^^^^^^^^
  File "C:\Users\ahada\.virtualenvs\Parking_Management_System_FastAPI-yC4wlCPa\Lib\site-packages\jwt\api_jwt.py", line 210, in decode
    decoded = self.decode_complete(
              ^^^^^^^^^^^^^^^^^^^^^
  File "C:\Users\ahada\.virtualenvs\Parking_Management_System_FastAPI-yC4wlCPa\Lib\site-packages\jwt\api_jwt.py", line 162, in decode_complete
    self._validate_claims(
  File "C:\Users\ahada\.virtualenvs\Parking_Management_System_FastAPI-yC4wlCPa\Lib\site-packages\jwt\api_jwt.py", line 248, in _validate_claims
    self._validate_exp(payload, now, leeway)
  File "C:\Users\ahada\.virtualenvs\Parking_Management_System_FastAPI-yC4wlCPa\Lib\site-packages\jwt\api_jwt.py", line 306, in _validate_exp
    raise ExpiredSignatureError("Signature has expired")
jwt.exceptions.ExpiredSignatureError: Signature has expired

The above exception was the direct cause of the following exception:

Traceback (most recent call last):
  File "C:\PERSONAL\Parking_Management_System_FastAPI\src\helpers\handle_errors.py", line 19, in wrapper
    return_value = function(*args, **kwargs)
                   ^^^^^^^^^^^^^^^^^^^^^^^^^
  File "C:\PERSONAL\Parking_Management_System_FastAPI\src\helpers\access_decorator.py", line 14, in wrapper
    token = validate_access_token(request=request)
            ^^^^^^^^^^^^^^^^^^^^^^^^^^^^^^^^^^^^^^
  File "C:\PERSONAL\Parking_Management_System_FastAPI\src\helpers\jwt_helpers.py", line 27, in validate_access_token
    raise UnauthorizedError(prompts.get(
src.helpers.errors.UnauthorizedError: Token Expired

2023-12-18 11:30:20 DEBUG log_debug(23) Error Occurred: Traceback (most recent call last):
  File "C:\PERSONAL\Parking_Management_System_FastAPI\src\helpers\handle_errors.py", line 19, in wrapper
    return_value = function(*args, **kwargs)
                   ^^^^^^^^^^^^^^^^^^^^^^^^^
  File "C:\PERSONAL\Parking_Management_System_FastAPI\src\helpers\access_decorator.py", line 21, in wrapper
    return fun(*args, **kwargs)
           ^^^^^^^^^^^^^^^^^^^^
  File "C:\PERSONAL\Parking_Management_System_FastAPI\src\helpers\validations.py", line 41, in wrapper
    return function(*args, **kwargs)
           ^^^^^^^^^^^^^^^^^^^^^^^^^
  File "C:\PERSONAL\Parking_Management_System_FastAPI\src\routers\slot.py", line 73, in ban_slot
    slot.ban_slot(request_data.get("slot_number"),
  File "C:\PERSONAL\Parking_Management_System_FastAPI\src\controllers\slot.py", line 44, in ban_slot
    self.__is_slot_available(slot_number, slot_type)
  File "C:\PERSONAL\Parking_Management_System_FastAPI\src\controllers\slot.py", line 124, in __is_slot_available
    raise ConflictError(prompts.get("SLOT_OCCUPIED"))
src.helpers.errors.ConflictError: Slot Already Occupied! Choose One Which is not.

2023-12-18 11:44:25 DEBUG log_debug(23) Error Occurred: Traceback (most recent call last):
  File "C:\PERSONAL\Parking_Management_System_FastAPI\src\helpers\handle_errors.py", line 19, in wrapper
    return_value = function(*args, **kwargs)
                   ^^^^^^^^^^^^^^^^^^^^^^^^^
  File "C:\PERSONAL\Parking_Management_System_FastAPI\src\helpers\access_decorator.py", line 21, in wrapper
    return fun(*args, **kwargs)
           ^^^^^^^^^^^^^^^^^^^^
  File "C:\PERSONAL\Parking_Management_System_FastAPI\src\helpers\validations.py", line 42, in wrapper
    return function(*args, **kwargs)
           ^^^^^^^^^^^^^^^^^^^^^^^^^
  File "C:\PERSONAL\Parking_Management_System_FastAPI\src\routers\slot.py", line 73, in ban_slot
    slot.ban_slot(request_data.get("slot_number"),
  File "C:\PERSONAL\Parking_Management_System_FastAPI\src\controllers\slot.py", line 44, in ban_slot
    self.__is_slot_available(slot_number, slot_type)
  File "C:\PERSONAL\Parking_Management_System_FastAPI\src\controllers\slot.py", line 124, in __is_slot_available
    raise ConflictError(prompts.get("SLOT_OCCUPIED"))
src.helpers.errors.ConflictError: Slot Already Occupied! Choose One Which is not.

2023-12-18 11:44:30 DEBUG log_debug(23) Error Occurred: Traceback (most recent call last):
  File "C:\PERSONAL\Parking_Management_System_FastAPI\src\helpers\handle_errors.py", line 19, in wrapper
    return_value = function(*args, **kwargs)
                   ^^^^^^^^^^^^^^^^^^^^^^^^^
  File "C:\PERSONAL\Parking_Management_System_FastAPI\src\helpers\access_decorator.py", line 21, in wrapper
    return fun(*args, **kwargs)
           ^^^^^^^^^^^^^^^^^^^^
  File "C:\PERSONAL\Parking_Management_System_FastAPI\src\helpers\validations.py", line 42, in wrapper
    return function(*args, **kwargs)
           ^^^^^^^^^^^^^^^^^^^^^^^^^
  File "C:\PERSONAL\Parking_Management_System_FastAPI\src\routers\slot.py", line 73, in ban_slot
    slot.ban_slot(request_data.get("slot_number"),
  File "C:\PERSONAL\Parking_Management_System_FastAPI\src\controllers\slot.py", line 44, in ban_slot
    self.__is_slot_available(slot_number, slot_type)
  File "C:\PERSONAL\Parking_Management_System_FastAPI\src\controllers\slot.py", line 124, in __is_slot_available
    raise ConflictError(prompts.get("SLOT_OCCUPIED"))
src.helpers.errors.ConflictError: Slot Already Occupied! Choose One Which is not.

2023-12-18 12:21:26 DEBUG log_debug(23) Error Occurred: Traceback (most recent call last):
  File "C:\PERSONAL\Parking_Management_System_FastAPI\src\helpers\handle_errors.py", line 19, in wrapper
    return_value = function(*args, **kwargs)
                   ^^^^^^^^^^^^^^^^^^^^^^^^^
  File "C:\PERSONAL\Parking_Management_System_FastAPI\src\helpers\validations.py", line 42, in wrapper
    return function(*args, **kwargs)
           ^^^^^^^^^^^^^^^^^^^^^^^^^
  File "C:\PERSONAL\Parking_Management_System_FastAPI\src\helpers\access_decorator.py", line 21, in wrapper
    return fun(*args, **kwargs)
           ^^^^^^^^^^^^^^^^^^^^
  File "C:\PERSONAL\Parking_Management_System_FastAPI\src\routers\slot.py", line 32, in occupy_slot
    slot.assign_slot(request_data.get("slot_number"), request_data.get(
  File "C:\PERSONAL\Parking_Management_System_FastAPI\src\controllers\slot.py", line 19, in assign_slot
    self.__is_already_parked(vehicle_number)
  File "C:\PERSONAL\Parking_Management_System_FastAPI\src\controllers\slot.py", line 112, in __is_already_parked
    raise ConflictError(prompts.get("VEHICLE_ALREADY_PARKED"))
src.helpers.errors.ConflictError: Vehicle Already Parked.

2023-12-18 12:23:27 DEBUG log_debug(23) Error Occurred: Traceback (most recent call last):
  File "C:\PERSONAL\Parking_Management_System_FastAPI\src\helpers\handle_errors.py", line 19, in wrapper
    return_value = function(*args, **kwargs)
                   ^^^^^^^^^^^^^^^^^^^^^^^^^
  File "C:\PERSONAL\Parking_Management_System_FastAPI\src\helpers\validations.py", line 42, in wrapper
    return function(*args, **kwargs)
           ^^^^^^^^^^^^^^^^^^^^^^^^^
  File "C:\PERSONAL\Parking_Management_System_FastAPI\src\helpers\access_decorator.py", line 21, in wrapper
    return fun(*args, **kwargs)
           ^^^^^^^^^^^^^^^^^^^^
  File "C:\PERSONAL\Parking_Management_System_FastAPI\src\routers\slot.py", line 32, in occupy_slot
    slot.assign_slot(request_data.get("slot_number"), request_data.get(
  File "C:\PERSONAL\Parking_Management_System_FastAPI\src\controllers\slot.py", line 19, in assign_slot
    self.__is_already_parked(vehicle_number)
  File "C:\PERSONAL\Parking_Management_System_FastAPI\src\controllers\slot.py", line 112, in __is_already_parked
    raise ConflictError(prompts.get("VEHICLE_ALREADY_PARKED"))
src.helpers.errors.ConflictError: Vehicle Already Parked.

2023-12-18 13:39:09 DEBUG log_debug(23) Error Occurred: Traceback (most recent call last):
  File "C:\PERSONAL\Parking_Management_System_FastAPI\src\helpers\handle_errors.py", line 19, in wrapper
    return_value = function(*args, **kwargs)
                   ^^^^^^^^^^^^^^^^^^^^^^^^^
  File "C:\PERSONAL\Parking_Management_System_FastAPI\src\helpers\access_decorator.py", line 21, in wrapper
    return fun(*args, **kwargs)
           ^^^^^^^^^^^^^^^^^^^^
  File "C:\PERSONAL\Parking_Management_System_FastAPI\src\routers\slot.py", line 56, in unassign_slot
    slot_details = slot.unassign_slot(vehicle_number)
                   ^^^^^^^^^^^^^^^^^^^^^^^^^^^^^^^^^^
  File "C:\PERSONAL\Parking_Management_System_FastAPI\src\controllers\slot.py", line 30, in unassign_slot
    slot_details = self.__get_slot_details_by_vehicle(vehicle_number)
                   ^^^^^^^^^^^^^^^^^^^^^^^^^^^^^^^^^^^^^^^^^^^^^^^^^^
  File "C:\PERSONAL\Parking_Management_System_FastAPI\src\controllers\slot.py", line 144, in __get_slot_details_by_vehicle
    raise ValueError(prompts.get("VEHICLE_NOT_PARKED"))
ValueError: Vehicle do not have any assigned slot.

2023-12-18 13:39:10 DEBUG log_debug(23) Error Occurred: Traceback (most recent call last):
  File "C:\PERSONAL\Parking_Management_System_FastAPI\src\helpers\handle_errors.py", line 19, in wrapper
    return_value = function(*args, **kwargs)
                   ^^^^^^^^^^^^^^^^^^^^^^^^^
  File "C:\PERSONAL\Parking_Management_System_FastAPI\src\helpers\access_decorator.py", line 21, in wrapper
    return fun(*args, **kwargs)
           ^^^^^^^^^^^^^^^^^^^^
  File "C:\PERSONAL\Parking_Management_System_FastAPI\src\routers\slot.py", line 56, in unassign_slot
    slot_details = slot.unassign_slot(vehicle_number)
                   ^^^^^^^^^^^^^^^^^^^^^^^^^^^^^^^^^^
  File "C:\PERSONAL\Parking_Management_System_FastAPI\src\controllers\slot.py", line 30, in unassign_slot
    slot_details = self.__get_slot_details_by_vehicle(vehicle_number)
                   ^^^^^^^^^^^^^^^^^^^^^^^^^^^^^^^^^^^^^^^^^^^^^^^^^^
  File "C:\PERSONAL\Parking_Management_System_FastAPI\src\controllers\slot.py", line 144, in __get_slot_details_by_vehicle
    raise ValueError(prompts.get("VEHICLE_NOT_PARKED"))
ValueError: Vehicle do not have any assigned slot.

2023-12-18 13:48:29 DEBUG log_debug(23) Error Occurred: Traceback (most recent call last):
  File "C:\PERSONAL\Parking_Management_System_FastAPI\src\helpers\jwt_helpers.py", line 25, in validate_access_token
    payload = jwt.decode(token, SECRET_KEY, algorithms=[ALGORITHM])
              ^^^^^^^^^^^^^^^^^^^^^^^^^^^^^^^^^^^^^^^^^^^^^^^^^^^^^
  File "C:\Users\ahada\.virtualenvs\Parking_Management_System_FastAPI-yC4wlCPa\Lib\site-packages\jwt\api_jwt.py", line 210, in decode
    decoded = self.decode_complete(
              ^^^^^^^^^^^^^^^^^^^^^
  File "C:\Users\ahada\.virtualenvs\Parking_Management_System_FastAPI-yC4wlCPa\Lib\site-packages\jwt\api_jwt.py", line 162, in decode_complete
    self._validate_claims(
  File "C:\Users\ahada\.virtualenvs\Parking_Management_System_FastAPI-yC4wlCPa\Lib\site-packages\jwt\api_jwt.py", line 248, in _validate_claims
    self._validate_exp(payload, now, leeway)
  File "C:\Users\ahada\.virtualenvs\Parking_Management_System_FastAPI-yC4wlCPa\Lib\site-packages\jwt\api_jwt.py", line 306, in _validate_exp
    raise ExpiredSignatureError("Signature has expired")
jwt.exceptions.ExpiredSignatureError: Signature has expired

The above exception was the direct cause of the following exception:

Traceback (most recent call last):
  File "C:\PERSONAL\Parking_Management_System_FastAPI\src\helpers\handle_errors.py", line 19, in wrapper
    return_value = function(*args, **kwargs)
                   ^^^^^^^^^^^^^^^^^^^^^^^^^
  File "C:\PERSONAL\Parking_Management_System_FastAPI\src\helpers\access_decorator.py", line 14, in wrapper
    token = validate_access_token(request=request)
            ^^^^^^^^^^^^^^^^^^^^^^^^^^^^^^^^^^^^^^
  File "C:\PERSONAL\Parking_Management_System_FastAPI\src\helpers\jwt_helpers.py", line 27, in validate_access_token
    raise UnauthorizedError(prompts.get(
src.helpers.errors.UnauthorizedError: Token Expired

2023-12-18 16:00:54 DEBUG log_debug(23) Error Occurred: Traceback (most recent call last):
  File "C:\PERSONAL\Parking_Management_System_FastAPI\src\helpers\handle_errors.py", line 19, in wrapper
    return_value = function(*args, **kwargs)
                   ^^^^^^^^^^^^^^^^^^^^^^^^^
  File "C:\PERSONAL\Parking_Management_System_FastAPI\src\helpers\validations.py", line 42, in wrapper
    return function(*args, **kwargs)
           ^^^^^^^^^^^^^^^^^^^^^^^^^
  File "C:\PERSONAL\Parking_Management_System_FastAPI\src\routers\auth.py", line 21, in login
    instance.authenticate()
  File "C:\PERSONAL\Parking_Management_System_FastAPI\src\controllers\login.py", line 36, in authenticate
    raise AuthenticationError(prompts.get("INVALID_DETAILS"))
src.helpers.errors.AuthenticationError: Invalid Login Details

2023-12-18 16:00:56 DEBUG log_debug(23) Error Occurred: Traceback (most recent call last):
  File "C:\PERSONAL\Parking_Management_System_FastAPI\src\helpers\handle_errors.py", line 19, in wrapper
    return_value = function(*args, **kwargs)
                   ^^^^^^^^^^^^^^^^^^^^^^^^^
  File "C:\PERSONAL\Parking_Management_System_FastAPI\src\helpers\validations.py", line 42, in wrapper
    return function(*args, **kwargs)
           ^^^^^^^^^^^^^^^^^^^^^^^^^
  File "C:\PERSONAL\Parking_Management_System_FastAPI\src\routers\auth.py", line 21, in login
    instance.authenticate()
  File "C:\PERSONAL\Parking_Management_System_FastAPI\src\controllers\login.py", line 36, in authenticate
    raise AuthenticationError(prompts.get("INVALID_DETAILS"))
src.helpers.errors.AuthenticationError: Invalid Login Details

2023-12-18 16:01:28 DEBUG log_debug(23) Error Occurred: Traceback (most recent call last):
  File "C:\PERSONAL\Parking_Management_System_FastAPI\src\helpers\handle_errors.py", line 19, in wrapper
    return_value = function(*args, **kwargs)
                   ^^^^^^^^^^^^^^^^^^^^^^^^^
  File "C:\PERSONAL\Parking_Management_System_FastAPI\src\helpers\validations.py", line 42, in wrapper
    return function(*args, **kwargs)
           ^^^^^^^^^^^^^^^^^^^^^^^^^
  File "C:\PERSONAL\Parking_Management_System_FastAPI\src\routers\auth.py", line 21, in login
    instance.authenticate()
  File "C:\PERSONAL\Parking_Management_System_FastAPI\src\controllers\login.py", line 36, in authenticate
    raise AuthenticationError(prompts.get("INVALID_DETAILS"))
src.helpers.errors.AuthenticationError: Invalid Login Details

2023-12-18 16:34:01 DEBUG log_debug(23) Error Occurred: Traceback (most recent call last):
  File "C:\PERSONAL\Parking_Management_System_FastAPI\src\helpers\handle_errors.py", line 19, in wrapper
    return_value = function(*args, **kwargs)
                   ^^^^^^^^^^^^^^^^^^^^^^^^^
  File "C:\PERSONAL\Parking_Management_System_FastAPI\src\helpers\access_decorator.py", line 21, in wrapper
    return fun(*args, **kwargs)
           ^^^^^^^^^^^^^^^^^^^^
  File "C:\PERSONAL\Parking_Management_System_FastAPI\src\routers\slot.py", line 56, in unassign_slot
    slot_details = slot.unassign_slot(vehicle_number)
                   ^^^^^^^^^^^^^^^^^^^^^^^^^^^^^^^^^^
  File "C:\PERSONAL\Parking_Management_System_FastAPI\src\controllers\slot.py", line 30, in unassign_slot
    slot_details = self.__get_slot_details_by_vehicle(vehicle_number)
                   ^^^^^^^^^^^^^^^^^^^^^^^^^^^^^^^^^^^^^^^^^^^^^^^^^^
  File "C:\PERSONAL\Parking_Management_System_FastAPI\src\controllers\slot.py", line 144, in __get_slot_details_by_vehicle
    raise ValueError(prompts.get("VEHICLE_NOT_PARKED"))
ValueError: Vehicle do not have any assigned slot.

2023-12-18 16:40:11 DEBUG log_debug(23) Error Occurred: Traceback (most recent call last):
  File "C:\PERSONAL\Parking_Management_System_FastAPI\src\helpers\handle_errors.py", line 19, in wrapper
    return_value = function(*args, **kwargs)
                   ^^^^^^^^^^^^^^^^^^^^^^^^^
  File "C:\PERSONAL\Parking_Management_System_FastAPI\src\helpers\validations.py", line 42, in wrapper
    return function(*args, **kwargs)
           ^^^^^^^^^^^^^^^^^^^^^^^^^
  File "C:\PERSONAL\Parking_Management_System_FastAPI\src\helpers\access_decorator.py", line 21, in wrapper
    return fun(*args, **kwargs)
           ^^^^^^^^^^^^^^^^^^^^
  File "C:\PERSONAL\Parking_Management_System_FastAPI\src\routers\slot.py", line 32, in occupy_slot
    slot.assign_slot(request_data.get("slot_number"), request_data.get(
  File "C:\PERSONAL\Parking_Management_System_FastAPI\src\controllers\slot.py", line 18, in assign_slot
    self.__is_slot_available(slot_number, vehicle_type)
  File "C:\PERSONAL\Parking_Management_System_FastAPI\src\controllers\slot.py", line 124, in __is_slot_available
    raise ConflictError(prompts.get("SLOT_OCCUPIED"))
src.helpers.errors.ConflictError: Slot Already Occupied! Choose One Which is not.

2023-12-18 16:42:22 DEBUG log_debug(23) Error Occurred: Traceback (most recent call last):
  File "C:\PERSONAL\Parking_Management_System_FastAPI\src\helpers\handle_errors.py", line 19, in wrapper
    return_value = function(*args, **kwargs)
                   ^^^^^^^^^^^^^^^^^^^^^^^^^
  File "C:\PERSONAL\Parking_Management_System_FastAPI\src\helpers\access_decorator.py", line 21, in wrapper
    return fun(*args, **kwargs)
           ^^^^^^^^^^^^^^^^^^^^
  File "C:\PERSONAL\Parking_Management_System_FastAPI\src\routers\slot.py", line 56, in unassign_slot
    slot_details = slot.unassign_slot(vehicle_number)
                   ^^^^^^^^^^^^^^^^^^^^^^^^^^^^^^^^^^
  File "C:\PERSONAL\Parking_Management_System_FastAPI\src\controllers\slot.py", line 30, in unassign_slot
    slot_details = self.__get_slot_details_by_vehicle(vehicle_number)
                   ^^^^^^^^^^^^^^^^^^^^^^^^^^^^^^^^^^^^^^^^^^^^^^^^^^
  File "C:\PERSONAL\Parking_Management_System_FastAPI\src\controllers\slot.py", line 144, in __get_slot_details_by_vehicle
    raise ValueError(prompts.get("VEHICLE_NOT_PARKED"))
ValueError: Vehicle do not have any assigned slot.

2023-12-18 16:42:24 DEBUG log_debug(23) Error Occurred: Traceback (most recent call last):
  File "C:\PERSONAL\Parking_Management_System_FastAPI\src\helpers\handle_errors.py", line 19, in wrapper
    return_value = function(*args, **kwargs)
                   ^^^^^^^^^^^^^^^^^^^^^^^^^
  File "C:\PERSONAL\Parking_Management_System_FastAPI\src\helpers\access_decorator.py", line 21, in wrapper
    return fun(*args, **kwargs)
           ^^^^^^^^^^^^^^^^^^^^
  File "C:\PERSONAL\Parking_Management_System_FastAPI\src\routers\slot.py", line 56, in unassign_slot
    slot_details = slot.unassign_slot(vehicle_number)
                   ^^^^^^^^^^^^^^^^^^^^^^^^^^^^^^^^^^
  File "C:\PERSONAL\Parking_Management_System_FastAPI\src\controllers\slot.py", line 30, in unassign_slot
    slot_details = self.__get_slot_details_by_vehicle(vehicle_number)
                   ^^^^^^^^^^^^^^^^^^^^^^^^^^^^^^^^^^^^^^^^^^^^^^^^^^
  File "C:\PERSONAL\Parking_Management_System_FastAPI\src\controllers\slot.py", line 144, in __get_slot_details_by_vehicle
    raise ValueError(prompts.get("VEHICLE_NOT_PARKED"))
ValueError: Vehicle do not have any assigned slot.

2023-12-18 16:53:58 DEBUG log_debug(23) Error Occurred: Traceback (most recent call last):
  File "C:\PERSONAL\Parking_Management_System_FastAPI\src\helpers\handle_errors.py", line 19, in wrapper
    return_value = function(*args, **kwargs)
                   ^^^^^^^^^^^^^^^^^^^^^^^^^
  File "C:\PERSONAL\Parking_Management_System_FastAPI\src\helpers\access_decorator.py", line 21, in wrapper
    return fun(*args, **kwargs)
           ^^^^^^^^^^^^^^^^^^^^
  File "C:\PERSONAL\Parking_Management_System_FastAPI\src\routers\slot.py", line 56, in unassign_slot
    slot_details = slot.unassign_slot(vehicle_number)
                   ^^^^^^^^^^^^^^^^^^^^^^^^^^^^^^^^^^
  File "C:\PERSONAL\Parking_Management_System_FastAPI\src\controllers\slot.py", line 30, in unassign_slot
    slot_details = self.__get_slot_details_by_vehicle(vehicle_number)
                   ^^^^^^^^^^^^^^^^^^^^^^^^^^^^^^^^^^^^^^^^^^^^^^^^^^
  File "C:\PERSONAL\Parking_Management_System_FastAPI\src\controllers\slot.py", line 144, in __get_slot_details_by_vehicle
    raise ValueError(prompts.get("VEHICLE_NOT_PARKED"))
ValueError: Vehicle do not have any assigned slot.

2023-12-18 16:54:00 DEBUG log_debug(23) Error Occurred: Traceback (most recent call last):
  File "C:\PERSONAL\Parking_Management_System_FastAPI\src\helpers\handle_errors.py", line 19, in wrapper
    return_value = function(*args, **kwargs)
                   ^^^^^^^^^^^^^^^^^^^^^^^^^
  File "C:\PERSONAL\Parking_Management_System_FastAPI\src\helpers\access_decorator.py", line 21, in wrapper
    return fun(*args, **kwargs)
           ^^^^^^^^^^^^^^^^^^^^
  File "C:\PERSONAL\Parking_Management_System_FastAPI\src\routers\slot.py", line 56, in unassign_slot
    slot_details = slot.unassign_slot(vehicle_number)
                   ^^^^^^^^^^^^^^^^^^^^^^^^^^^^^^^^^^
  File "C:\PERSONAL\Parking_Management_System_FastAPI\src\controllers\slot.py", line 30, in unassign_slot
    slot_details = self.__get_slot_details_by_vehicle(vehicle_number)
                   ^^^^^^^^^^^^^^^^^^^^^^^^^^^^^^^^^^^^^^^^^^^^^^^^^^
  File "C:\PERSONAL\Parking_Management_System_FastAPI\src\controllers\slot.py", line 144, in __get_slot_details_by_vehicle
    raise ValueError(prompts.get("VEHICLE_NOT_PARKED"))
ValueError: Vehicle do not have any assigned slot.

2023-12-18 16:54:57 DEBUG log_debug(23) Error Occurred: Traceback (most recent call last):
  File "C:\PERSONAL\Parking_Management_System_FastAPI\src\helpers\handle_errors.py", line 19, in wrapper
    return_value = function(*args, **kwargs)
                   ^^^^^^^^^^^^^^^^^^^^^^^^^
  File "C:\PERSONAL\Parking_Management_System_FastAPI\src\helpers\access_decorator.py", line 21, in wrapper
    return fun(*args, **kwargs)
           ^^^^^^^^^^^^^^^^^^^^
  File "C:\PERSONAL\Parking_Management_System_FastAPI\src\routers\slot.py", line 56, in unassign_slot
    slot_details = slot.unassign_slot(vehicle_number)
                   ^^^^^^^^^^^^^^^^^^^^^^^^^^^^^^^^^^
  File "C:\PERSONAL\Parking_Management_System_FastAPI\src\controllers\slot.py", line 30, in unassign_slot
    slot_details = self.__get_slot_details_by_vehicle(vehicle_number)
                   ^^^^^^^^^^^^^^^^^^^^^^^^^^^^^^^^^^^^^^^^^^^^^^^^^^
  File "C:\PERSONAL\Parking_Management_System_FastAPI\src\controllers\slot.py", line 144, in __get_slot_details_by_vehicle
    raise ValueError(prompts.get("VEHICLE_NOT_PARKED"))
ValueError: Vehicle do not have any assigned slot.

2023-12-18 16:55:01 DEBUG log_debug(23) Error Occurred: Traceback (most recent call last):
  File "C:\PERSONAL\Parking_Management_System_FastAPI\src\helpers\handle_errors.py", line 19, in wrapper
    return_value = function(*args, **kwargs)
                   ^^^^^^^^^^^^^^^^^^^^^^^^^
  File "C:\PERSONAL\Parking_Management_System_FastAPI\src\helpers\access_decorator.py", line 21, in wrapper
    return fun(*args, **kwargs)
           ^^^^^^^^^^^^^^^^^^^^
  File "C:\PERSONAL\Parking_Management_System_FastAPI\src\routers\slot.py", line 56, in unassign_slot
    slot_details = slot.unassign_slot(vehicle_number)
                   ^^^^^^^^^^^^^^^^^^^^^^^^^^^^^^^^^^
  File "C:\PERSONAL\Parking_Management_System_FastAPI\src\controllers\slot.py", line 30, in unassign_slot
    slot_details = self.__get_slot_details_by_vehicle(vehicle_number)
                   ^^^^^^^^^^^^^^^^^^^^^^^^^^^^^^^^^^^^^^^^^^^^^^^^^^
  File "C:\PERSONAL\Parking_Management_System_FastAPI\src\controllers\slot.py", line 144, in __get_slot_details_by_vehicle
    raise ValueError(prompts.get("VEHICLE_NOT_PARKED"))
ValueError: Vehicle do not have any assigned slot.

2023-12-18 16:55:04 DEBUG log_debug(23) Error Occurred: Traceback (most recent call last):
  File "C:\PERSONAL\Parking_Management_System_FastAPI\src\helpers\handle_errors.py", line 19, in wrapper
    return_value = function(*args, **kwargs)
                   ^^^^^^^^^^^^^^^^^^^^^^^^^
  File "C:\PERSONAL\Parking_Management_System_FastAPI\src\helpers\access_decorator.py", line 21, in wrapper
    return fun(*args, **kwargs)
           ^^^^^^^^^^^^^^^^^^^^
  File "C:\PERSONAL\Parking_Management_System_FastAPI\src\routers\slot.py", line 56, in unassign_slot
    slot_details = slot.unassign_slot(vehicle_number)
                   ^^^^^^^^^^^^^^^^^^^^^^^^^^^^^^^^^^
  File "C:\PERSONAL\Parking_Management_System_FastAPI\src\controllers\slot.py", line 30, in unassign_slot
    slot_details = self.__get_slot_details_by_vehicle(vehicle_number)
                   ^^^^^^^^^^^^^^^^^^^^^^^^^^^^^^^^^^^^^^^^^^^^^^^^^^
  File "C:\PERSONAL\Parking_Management_System_FastAPI\src\controllers\slot.py", line 144, in __get_slot_details_by_vehicle
    raise ValueError(prompts.get("VEHICLE_NOT_PARKED"))
ValueError: Vehicle do not have any assigned slot.

2023-12-18 16:55:08 DEBUG log_debug(23) Error Occurred: Traceback (most recent call last):
  File "C:\PERSONAL\Parking_Management_System_FastAPI\src\helpers\handle_errors.py", line 19, in wrapper
    return_value = function(*args, **kwargs)
                   ^^^^^^^^^^^^^^^^^^^^^^^^^
  File "C:\PERSONAL\Parking_Management_System_FastAPI\src\helpers\access_decorator.py", line 21, in wrapper
    return fun(*args, **kwargs)
           ^^^^^^^^^^^^^^^^^^^^
  File "C:\PERSONAL\Parking_Management_System_FastAPI\src\routers\slot.py", line 56, in unassign_slot
    slot_details = slot.unassign_slot(vehicle_number)
                   ^^^^^^^^^^^^^^^^^^^^^^^^^^^^^^^^^^
  File "C:\PERSONAL\Parking_Management_System_FastAPI\src\controllers\slot.py", line 30, in unassign_slot
    slot_details = self.__get_slot_details_by_vehicle(vehicle_number)
                   ^^^^^^^^^^^^^^^^^^^^^^^^^^^^^^^^^^^^^^^^^^^^^^^^^^
  File "C:\PERSONAL\Parking_Management_System_FastAPI\src\controllers\slot.py", line 144, in __get_slot_details_by_vehicle
    raise ValueError(prompts.get("VEHICLE_NOT_PARKED"))
ValueError: Vehicle do not have any assigned slot.

2023-12-18 17:26:58 DEBUG log_debug(23) Error Occurred: Traceback (most recent call last):
  File "C:\PERSONAL\Parking_Management_System_FastAPI\src\helpers\handle_errors.py", line 19, in wrapper
    return_value = function(*args, **kwargs)
                   ^^^^^^^^^^^^^^^^^^^^^^^^^
  File "C:\PERSONAL\Parking_Management_System_FastAPI\src\helpers\validations.py", line 42, in wrapper
    return function(*args, **kwargs)
           ^^^^^^^^^^^^^^^^^^^^^^^^^
  File "C:\PERSONAL\Parking_Management_System_FastAPI\src\helpers\access_decorator.py", line 21, in wrapper
    return fun(*args, **kwargs)
           ^^^^^^^^^^^^^^^^^^^^
  File "C:\PERSONAL\Parking_Management_System_FastAPI\src\routers\slot.py", line 32, in occupy_slot
    slot.assign_slot(request_data.get("slot_number"), request_data.get(
  File "C:\PERSONAL\Parking_Management_System_FastAPI\src\controllers\slot.py", line 19, in assign_slot
    self.__is_already_parked(vehicle_number)
  File "C:\PERSONAL\Parking_Management_System_FastAPI\src\controllers\slot.py", line 112, in __is_already_parked
    raise ConflictError(prompts.get("VEHICLE_ALREADY_PARKED"))
src.helpers.errors.ConflictError: Vehicle Already Parked.

2023-12-18 17:35:44 DEBUG log_debug(23) Error Occurred: Traceback (most recent call last):
  File "C:\PERSONAL\Parking_Management_System_FastAPI\src\helpers\handle_errors.py", line 19, in wrapper
    return_value = function(*args, **kwargs)
                   ^^^^^^^^^^^^^^^^^^^^^^^^^
  File "C:\PERSONAL\Parking_Management_System_FastAPI\src\helpers\validations.py", line 42, in wrapper
    return function(*args, **kwargs)
           ^^^^^^^^^^^^^^^^^^^^^^^^^
  File "C:\PERSONAL\Parking_Management_System_FastAPI\src\routers\auth.py", line 21, in login
    instance.authenticate()
  File "C:\PERSONAL\Parking_Management_System_FastAPI\src\controllers\login.py", line 36, in authenticate
    raise AuthenticationError(prompts.get("INVALID_DETAILS"))
src.helpers.errors.AuthenticationError: Invalid Login Details

2023-12-18 17:36:08 DEBUG log_debug(23) Error Occurred: Traceback (most recent call last):
  File "C:\PERSONAL\Parking_Management_System_FastAPI\src\helpers\handle_errors.py", line 19, in wrapper
    return_value = function(*args, **kwargs)
                   ^^^^^^^^^^^^^^^^^^^^^^^^^
  File "C:\PERSONAL\Parking_Management_System_FastAPI\src\helpers\validations.py", line 42, in wrapper
    return function(*args, **kwargs)
           ^^^^^^^^^^^^^^^^^^^^^^^^^
  File "C:\PERSONAL\Parking_Management_System_FastAPI\src\helpers\access_decorator.py", line 21, in wrapper
    return fun(*args, **kwargs)
           ^^^^^^^^^^^^^^^^^^^^
  File "C:\PERSONAL\Parking_Management_System_FastAPI\src\routers\slot.py", line 27, in occupy_slot
    raise ValueError(prompts.get("VEHICLE_NOT_EXISTS"))
ValueError: Vehicle do not Exists. Please Add Vehicle First.

2023-12-18 17:37:52 DEBUG log_debug(23) Error Occurred: Traceback (most recent call last):
  File "C:\PERSONAL\Parking_Management_System_FastAPI\src\helpers\handle_errors.py", line 19, in wrapper
    return_value = function(*args, **kwargs)
                   ^^^^^^^^^^^^^^^^^^^^^^^^^
  File "C:\PERSONAL\Parking_Management_System_FastAPI\src\helpers\validations.py", line 42, in wrapper
    return function(*args, **kwargs)
           ^^^^^^^^^^^^^^^^^^^^^^^^^
  File "C:\PERSONAL\Parking_Management_System_FastAPI\src\helpers\access_decorator.py", line 21, in wrapper
    return fun(*args, **kwargs)
           ^^^^^^^^^^^^^^^^^^^^
  File "C:\PERSONAL\Parking_Management_System_FastAPI\src\routers\slot.py", line 27, in occupy_slot
    raise ValueError(prompts.get("VEHICLE_NOT_EXISTS"))
ValueError: Vehicle do not Exists. Please Add Vehicle First.

2023-12-18 17:43:56 DEBUG log_debug(23) Error Occurred: Traceback (most recent call last):
  File "C:\PERSONAL\Parking_Management_System_FastAPI\src\helpers\handle_errors.py", line 19, in wrapper
    return_value = function(*args, **kwargs)
                   ^^^^^^^^^^^^^^^^^^^^^^^^^
  File "C:\PERSONAL\Parking_Management_System_FastAPI\src\helpers\validations.py", line 42, in wrapper
    return function(*args, **kwargs)
           ^^^^^^^^^^^^^^^^^^^^^^^^^
  File "C:\PERSONAL\Parking_Management_System_FastAPI\src\helpers\access_decorator.py", line 21, in wrapper
    return fun(*args, **kwargs)
           ^^^^^^^^^^^^^^^^^^^^
  File "C:\PERSONAL\Parking_Management_System_FastAPI\src\routers\slot.py", line 27, in occupy_slot
    raise ValueError(prompts.get("VEHICLE_NOT_EXISTS"))
ValueError: Vehicle do not Exists. Please Add Vehicle First.

2023-12-18 17:45:44 DEBUG log_debug(23) Error Occurred: Traceback (most recent call last):
  File "C:\PERSONAL\Parking_Management_System_FastAPI\src\helpers\handle_errors.py", line 19, in wrapper
    return_value = function(*args, **kwargs)
                   ^^^^^^^^^^^^^^^^^^^^^^^^^
  File "C:\PERSONAL\Parking_Management_System_FastAPI\src\helpers\validations.py", line 42, in wrapper
    return function(*args, **kwargs)
           ^^^^^^^^^^^^^^^^^^^^^^^^^
  File "C:\PERSONAL\Parking_Management_System_FastAPI\src\helpers\access_decorator.py", line 21, in wrapper
    return fun(*args, **kwargs)
           ^^^^^^^^^^^^^^^^^^^^
  File "C:\PERSONAL\Parking_Management_System_FastAPI\src\routers\slot.py", line 27, in occupy_slot
    raise ValueError(prompts.get("VEHICLE_NOT_EXISTS"))
ValueError: Vehicle do not Exists. Please Add Vehicle First.

2023-12-18 17:46:18 DEBUG log_debug(23) Error Occurred: Traceback (most recent call last):
  File "C:\PERSONAL\Parking_Management_System_FastAPI\src\helpers\handle_errors.py", line 19, in wrapper
    return_value = function(*args, **kwargs)
                   ^^^^^^^^^^^^^^^^^^^^^^^^^
  File "C:\PERSONAL\Parking_Management_System_FastAPI\src\helpers\validations.py", line 42, in wrapper
    return function(*args, **kwargs)
           ^^^^^^^^^^^^^^^^^^^^^^^^^
  File "C:\PERSONAL\Parking_Management_System_FastAPI\src\helpers\access_decorator.py", line 21, in wrapper
    return fun(*args, **kwargs)
           ^^^^^^^^^^^^^^^^^^^^
  File "C:\PERSONAL\Parking_Management_System_FastAPI\src\routers\slot.py", line 27, in occupy_slot
    raise ValueError(prompts.get("VEHICLE_NOT_EXISTS"))
ValueError: Vehicle do not Exists. Please Add Vehicle First.

2023-12-18 17:48:26 DEBUG log_debug(23) Error Occurred: Traceback (most recent call last):
  File "C:\PERSONAL\Parking_Management_System_FastAPI\src\helpers\handle_errors.py", line 19, in wrapper
    return_value = function(*args, **kwargs)
                   ^^^^^^^^^^^^^^^^^^^^^^^^^
  File "C:\PERSONAL\Parking_Management_System_FastAPI\src\helpers\validations.py", line 42, in wrapper
    return function(*args, **kwargs)
           ^^^^^^^^^^^^^^^^^^^^^^^^^
  File "C:\PERSONAL\Parking_Management_System_FastAPI\src\helpers\access_decorator.py", line 21, in wrapper
    return fun(*args, **kwargs)
           ^^^^^^^^^^^^^^^^^^^^
  File "C:\PERSONAL\Parking_Management_System_FastAPI\src\routers\slot.py", line 27, in occupy_slot
    raise ValueError(prompts.get("VEHICLE_NOT_EXISTS"))
ValueError: Vehicle do not Exists. Please Add Vehicle First.

2023-12-18 17:48:30 DEBUG log_debug(23) Error Occurred: Traceback (most recent call last):
  File "C:\PERSONAL\Parking_Management_System_FastAPI\src\helpers\handle_errors.py", line 19, in wrapper
    return_value = function(*args, **kwargs)
                   ^^^^^^^^^^^^^^^^^^^^^^^^^
  File "C:\PERSONAL\Parking_Management_System_FastAPI\src\helpers\validations.py", line 42, in wrapper
    return function(*args, **kwargs)
           ^^^^^^^^^^^^^^^^^^^^^^^^^
  File "C:\PERSONAL\Parking_Management_System_FastAPI\src\helpers\access_decorator.py", line 21, in wrapper
    return fun(*args, **kwargs)
           ^^^^^^^^^^^^^^^^^^^^
  File "C:\PERSONAL\Parking_Management_System_FastAPI\src\routers\slot.py", line 27, in occupy_slot
    raise ValueError(prompts.get("VEHICLE_NOT_EXISTS"))
ValueError: Vehicle do not Exists. Please Add Vehicle First.

2023-12-18 17:48:37 DEBUG log_debug(23) Error Occurred: Traceback (most recent call last):
  File "C:\PERSONAL\Parking_Management_System_FastAPI\src\helpers\handle_errors.py", line 19, in wrapper
    return_value = function(*args, **kwargs)
                   ^^^^^^^^^^^^^^^^^^^^^^^^^
  File "C:\PERSONAL\Parking_Management_System_FastAPI\src\helpers\validations.py", line 42, in wrapper
    return function(*args, **kwargs)
           ^^^^^^^^^^^^^^^^^^^^^^^^^
  File "C:\PERSONAL\Parking_Management_System_FastAPI\src\helpers\access_decorator.py", line 21, in wrapper
    return fun(*args, **kwargs)
           ^^^^^^^^^^^^^^^^^^^^
  File "C:\PERSONAL\Parking_Management_System_FastAPI\src\routers\slot.py", line 27, in occupy_slot
    raise ValueError(prompts.get("VEHICLE_NOT_EXISTS"))
ValueError: Vehicle do not Exists. Please Add Vehicle First.

2023-12-18 17:49:05 DEBUG log_debug(23) Error Occurred: Traceback (most recent call last):
  File "C:\PERSONAL\Parking_Management_System_FastAPI\src\helpers\handle_errors.py", line 19, in wrapper
    return_value = function(*args, **kwargs)
                   ^^^^^^^^^^^^^^^^^^^^^^^^^
  File "C:\PERSONAL\Parking_Management_System_FastAPI\src\helpers\validations.py", line 42, in wrapper
    return function(*args, **kwargs)
           ^^^^^^^^^^^^^^^^^^^^^^^^^
  File "C:\PERSONAL\Parking_Management_System_FastAPI\src\helpers\access_decorator.py", line 21, in wrapper
    return fun(*args, **kwargs)
           ^^^^^^^^^^^^^^^^^^^^
  File "C:\PERSONAL\Parking_Management_System_FastAPI\src\routers\slot.py", line 27, in occupy_slot
    raise ValueError(prompts.get("VEHICLE_NOT_EXISTS"))
ValueError: Vehicle do not Exists. Please Add Vehicle First.

2023-12-18 17:50:04 DEBUG log_debug(23) Error Occurred: Traceback (most recent call last):
  File "C:\PERSONAL\Parking_Management_System_FastAPI\src\helpers\handle_errors.py", line 19, in wrapper
    return_value = function(*args, **kwargs)
                   ^^^^^^^^^^^^^^^^^^^^^^^^^
  File "C:\PERSONAL\Parking_Management_System_FastAPI\src\helpers\validations.py", line 42, in wrapper
    return function(*args, **kwargs)
           ^^^^^^^^^^^^^^^^^^^^^^^^^
  File "C:\PERSONAL\Parking_Management_System_FastAPI\src\helpers\access_decorator.py", line 21, in wrapper
    return fun(*args, **kwargs)
           ^^^^^^^^^^^^^^^^^^^^
  File "C:\PERSONAL\Parking_Management_System_FastAPI\src\routers\slot.py", line 27, in occupy_slot
    raise ValueError(prompts.get("VEHICLE_NOT_EXISTS"))
ValueError: Vehicle do not Exists. Please Add Vehicle First.

2023-12-18 17:51:12 DEBUG log_debug(23) Error Occurred: Traceback (most recent call last):
  File "C:\PERSONAL\Parking_Management_System_FastAPI\src\helpers\handle_errors.py", line 19, in wrapper
    return_value = function(*args, **kwargs)
                   ^^^^^^^^^^^^^^^^^^^^^^^^^
  File "C:\PERSONAL\Parking_Management_System_FastAPI\src\helpers\validations.py", line 42, in wrapper
    return function(*args, **kwargs)
           ^^^^^^^^^^^^^^^^^^^^^^^^^
  File "C:\PERSONAL\Parking_Management_System_FastAPI\src\helpers\access_decorator.py", line 21, in wrapper
    return fun(*args, **kwargs)
           ^^^^^^^^^^^^^^^^^^^^
  File "C:\PERSONAL\Parking_Management_System_FastAPI\src\routers\slot.py", line 27, in occupy_slot
    raise ValueError(prompts.get("VEHICLE_NOT_EXISTS"))
ValueError: Vehicle do not Exists. Please Add Vehicle First.

2023-12-18 17:51:23 DEBUG log_debug(23) Error Occurred: Traceback (most recent call last):
  File "C:\PERSONAL\Parking_Management_System_FastAPI\src\helpers\handle_errors.py", line 19, in wrapper
    return_value = function(*args, **kwargs)
                   ^^^^^^^^^^^^^^^^^^^^^^^^^
  File "C:\PERSONAL\Parking_Management_System_FastAPI\src\helpers\validations.py", line 42, in wrapper
    return function(*args, **kwargs)
           ^^^^^^^^^^^^^^^^^^^^^^^^^
  File "C:\PERSONAL\Parking_Management_System_FastAPI\src\routers\auth.py", line 21, in login
    instance.authenticate()
  File "C:\PERSONAL\Parking_Management_System_FastAPI\src\controllers\login.py", line 36, in authenticate
    raise AuthenticationError(prompts.get("INVALID_DETAILS"))
src.helpers.errors.AuthenticationError: Invalid Login Details

2023-12-18 17:53:15 DEBUG log_debug(23) Error Occurred: Traceback (most recent call last):
  File "C:\PERSONAL\Parking_Management_System_FastAPI\src\helpers\handle_errors.py", line 19, in wrapper
    return_value = function(*args, **kwargs)
                   ^^^^^^^^^^^^^^^^^^^^^^^^^
  File "C:\PERSONAL\Parking_Management_System_FastAPI\src\helpers\validations.py", line 42, in wrapper
    return function(*args, **kwargs)
           ^^^^^^^^^^^^^^^^^^^^^^^^^
  File "C:\PERSONAL\Parking_Management_System_FastAPI\src\routers\auth.py", line 21, in login
    instance.authenticate()
  File "C:\PERSONAL\Parking_Management_System_FastAPI\src\controllers\login.py", line 36, in authenticate
    raise AuthenticationError(prompts.get("INVALID_DETAILS"))
src.helpers.errors.AuthenticationError: Invalid Login Details

2023-12-18 18:06:43 DEBUG log_debug(23) Error Occurred: Traceback (most recent call last):
  File "C:\PERSONAL\Parking_Management_System_FastAPI\src\helpers\handle_errors.py", line 19, in wrapper
    return_value = function(*args, **kwargs)
                   ^^^^^^^^^^^^^^^^^^^^^^^^^
  File "C:\PERSONAL\Parking_Management_System_FastAPI\src\helpers\access_decorator.py", line 21, in wrapper
    return fun(*args, **kwargs)
           ^^^^^^^^^^^^^^^^^^^^
  File "C:\PERSONAL\Parking_Management_System_FastAPI\src\routers\slot.py", line 56, in unassign_slot
    slot_details = slot.unassign_slot(vehicle_number)
                   ^^^^^^^^^^^^^^^^^^^^^^^^^^^^^^^^^^
  File "C:\PERSONAL\Parking_Management_System_FastAPI\src\controllers\slot.py", line 30, in unassign_slot
    slot_details = self.__get_slot_details_by_vehicle(vehicle_number)
                   ^^^^^^^^^^^^^^^^^^^^^^^^^^^^^^^^^^^^^^^^^^^^^^^^^^
  File "C:\PERSONAL\Parking_Management_System_FastAPI\src\controllers\slot.py", line 144, in __get_slot_details_by_vehicle
    raise ValueError(prompts.get("VEHICLE_NOT_PARKED"))
ValueError: Vehicle do not have any assigned slot.

2023-12-18 18:06:54 DEBUG log_debug(23) Error Occurred: Traceback (most recent call last):
  File "C:\PERSONAL\Parking_Management_System_FastAPI\src\helpers\handle_errors.py", line 19, in wrapper
    return_value = function(*args, **kwargs)
                   ^^^^^^^^^^^^^^^^^^^^^^^^^
  File "C:\PERSONAL\Parking_Management_System_FastAPI\src\helpers\access_decorator.py", line 21, in wrapper
    return fun(*args, **kwargs)
           ^^^^^^^^^^^^^^^^^^^^
  File "C:\PERSONAL\Parking_Management_System_FastAPI\src\routers\slot.py", line 56, in unassign_slot
    slot_details = slot.unassign_slot(vehicle_number)
                   ^^^^^^^^^^^^^^^^^^^^^^^^^^^^^^^^^^
  File "C:\PERSONAL\Parking_Management_System_FastAPI\src\controllers\slot.py", line 30, in unassign_slot
    slot_details = self.__get_slot_details_by_vehicle(vehicle_number)
                   ^^^^^^^^^^^^^^^^^^^^^^^^^^^^^^^^^^^^^^^^^^^^^^^^^^
  File "C:\PERSONAL\Parking_Management_System_FastAPI\src\controllers\slot.py", line 144, in __get_slot_details_by_vehicle
    raise ValueError(prompts.get("VEHICLE_NOT_PARKED"))
ValueError: Vehicle do not have any assigned slot.

2023-12-18 18:20:08 DEBUG log_debug(23) Error Occurred: Traceback (most recent call last):
  File "C:\PERSONAL\Parking_Management_System_FastAPI\src\helpers\handle_errors.py", line 19, in wrapper
    return_value = function(*args, **kwargs)
                   ^^^^^^^^^^^^^^^^^^^^^^^^^
  File "C:\PERSONAL\Parking_Management_System_FastAPI\src\helpers\access_decorator.py", line 21, in wrapper
    return fun(*args, **kwargs)
           ^^^^^^^^^^^^^^^^^^^^
  File "C:\PERSONAL\Parking_Management_System_FastAPI\src\routers\slot.py", line 56, in unassign_slot
    slot_details = slot.unassign_slot(vehicle_number)
                   ^^^^^^^^^^^^^^^^^^^^^^^^^^^^^^^^^^
  File "C:\PERSONAL\Parking_Management_System_FastAPI\src\controllers\slot.py", line 30, in unassign_slot
    slot_details = self.__get_slot_details_by_vehicle(vehicle_number)
                   ^^^^^^^^^^^^^^^^^^^^^^^^^^^^^^^^^^^^^^^^^^^^^^^^^^
  File "C:\PERSONAL\Parking_Management_System_FastAPI\src\controllers\slot.py", line 144, in __get_slot_details_by_vehicle
    raise ValueError(prompts.get("VEHICLE_NOT_PARKED"))
ValueError: Vehicle do not have any assigned slot.

2023-12-19 10:18:20 DEBUG log_debug(23) Error Occurred: Traceback (most recent call last):
  File "C:\PERSONAL\Parking_Management_System_FastAPI\src\helpers\handle_errors.py", line 19, in wrapper
    return_value = function(*args, **kwargs)
                   ^^^^^^^^^^^^^^^^^^^^^^^^^
  File "C:\PERSONAL\Parking_Management_System_FastAPI\src\helpers\access_decorator.py", line 21, in wrapper
    return fun(*args, **kwargs)
           ^^^^^^^^^^^^^^^^^^^^
  File "C:\PERSONAL\Parking_Management_System_FastAPI\src\routers\slot.py", line 56, in unassign_slot
    slot_details = slot.unassign_slot(vehicle_number)
                   ^^^^^^^^^^^^^^^^^^^^^^^^^^^^^^^^^^
  File "C:\PERSONAL\Parking_Management_System_FastAPI\src\controllers\slot.py", line 30, in unassign_slot
    slot_details = self.__get_slot_details_by_vehicle(vehicle_number)
                   ^^^^^^^^^^^^^^^^^^^^^^^^^^^^^^^^^^^^^^^^^^^^^^^^^^
  File "C:\PERSONAL\Parking_Management_System_FastAPI\src\controllers\slot.py", line 144, in __get_slot_details_by_vehicle
    raise ValueError(prompts.get("VEHICLE_NOT_PARKED"))
ValueError: Vehicle do not have any assigned slot.

2023-12-19 11:03:34 DEBUG establish_connection(87) Connection established
2023-12-19 11:03:34 DEBUG log_debug(23) Error Occurred: Traceback (most recent call last):
  File "C:\Users\ahada\.virtualenvs\Parking_Management_System_FastAPI-yC4wlCPa\Lib\site-packages\mysql\connector\connection_cext.py", line 633, in cmd_query
    self._cmysql.query(
_mysql_connector.MySQLInterfaceError: Duplicate entry 'LMV' for key 'slot_category.slot_type_UNIQUE'

The above exception was the direct cause of the following exception:

Traceback (most recent call last):
  File "C:\PERSONAL\Parking_Management_System_FastAPI\src\helpers\handle_errors.py", line 19, in wrapper
    return_value = function(*args, **kwargs)
                   ^^^^^^^^^^^^^^^^^^^^^^^^^
  File "C:\PERSONAL\Parking_Management_System_FastAPI\src\helpers\access_decorator.py", line 21, in wrapper
    return fun(*args, **kwargs)
           ^^^^^^^^^^^^^^^^^^^^
  File "C:\PERSONAL\Parking_Management_System_FastAPI\src\helpers\validations.py", line 42, in wrapper
    return function(*args, **kwargs)
           ^^^^^^^^^^^^^^^^^^^^^^^^^
  File "C:\PERSONAL\Parking_Management_System_FastAPI\src\routers\parkingspace.py", line 58, in add_new_parking_space
    parking_space.add_parking_category(
  File "C:\PERSONAL\Parking_Management_System_FastAPI\src\controllers\parking_space.py", line 17, in add_parking_category
    db.update_item(
  File "C:\PERSONAL\Parking_Management_System_FastAPI\src\models\database.py", line 42, in update_item
    raise error
  File "C:\PERSONAL\Parking_Management_System_FastAPI\src\models\database.py", line 35, in update_item
    self.cursor.execute(query, *args)
  File "C:\Users\ahada\.virtualenvs\Parking_Management_System_FastAPI-yC4wlCPa\Lib\site-packages\mysql\connector\cursor_cext.py", line 330, in execute
    result = self._cnx.cmd_query(
             ^^^^^^^^^^^^^^^^^^^^
  File "C:\Users\ahada\.virtualenvs\Parking_Management_System_FastAPI-yC4wlCPa\Lib\site-packages\mysql\connector\opentelemetry\context_propagation.py", line 77, in wrapper
    return method(cnx, *args, **kwargs)
           ^^^^^^^^^^^^^^^^^^^^^^^^^^^^
  File "C:\Users\ahada\.virtualenvs\Parking_Management_System_FastAPI-yC4wlCPa\Lib\site-packages\mysql\connector\connection_cext.py", line 641, in cmd_query
    raise get_mysql_exception(
mysql.connector.errors.IntegrityError: 1062 (23000): Duplicate entry 'LMV' for key 'slot_category.slot_type_UNIQUE'

2023-12-19 16:25:53 DEBUG log_debug(23) Error Occurred: Traceback (most recent call last):
  File "C:\PERSONAL\Parking_Management_System_FastAPI\src\helpers\handle_errors.py", line 19, in wrapper
    return_value = function(*args, **kwargs)
                   ^^^^^^^^^^^^^^^^^^^^^^^^^
  File "C:\PERSONAL\Parking_Management_System_FastAPI\src\helpers\access_decorator.py", line 21, in wrapper
    return fun(*args, **kwargs)
           ^^^^^^^^^^^^^^^^^^^^
  File "C:\PERSONAL\Parking_Management_System_FastAPI\src\routers\slot.py", line 56, in unassign_slot
    slot_details = slot.unassign_slot(vehicle_number)
                   ^^^^^^^^^^^^^^^^^^^^^^^^^^^^^^^^^^
  File "C:\PERSONAL\Parking_Management_System_FastAPI\src\controllers\slot.py", line 30, in unassign_slot
    slot_details = self.__get_slot_details_by_vehicle(vehicle_number)
                   ^^^^^^^^^^^^^^^^^^^^^^^^^^^^^^^^^^^^^^^^^^^^^^^^^^
  File "C:\PERSONAL\Parking_Management_System_FastAPI\src\controllers\slot.py", line 144, in __get_slot_details_by_vehicle
    raise ValueError(prompts.get("VEHICLE_NOT_PARKED"))
ValueError: Vehicle do not have any assigned slot.

2023-12-19 16:25:57 DEBUG log_debug(23) Error Occurred: Traceback (most recent call last):
  File "C:\PERSONAL\Parking_Management_System_FastAPI\src\helpers\handle_errors.py", line 19, in wrapper
    return_value = function(*args, **kwargs)
                   ^^^^^^^^^^^^^^^^^^^^^^^^^
  File "C:\PERSONAL\Parking_Management_System_FastAPI\src\helpers\access_decorator.py", line 21, in wrapper
    return fun(*args, **kwargs)
           ^^^^^^^^^^^^^^^^^^^^
  File "C:\PERSONAL\Parking_Management_System_FastAPI\src\routers\slot.py", line 56, in unassign_slot
    slot_details = slot.unassign_slot(vehicle_number)
                   ^^^^^^^^^^^^^^^^^^^^^^^^^^^^^^^^^^
  File "C:\PERSONAL\Parking_Management_System_FastAPI\src\controllers\slot.py", line 30, in unassign_slot
    slot_details = self.__get_slot_details_by_vehicle(vehicle_number)
                   ^^^^^^^^^^^^^^^^^^^^^^^^^^^^^^^^^^^^^^^^^^^^^^^^^^
  File "C:\PERSONAL\Parking_Management_System_FastAPI\src\controllers\slot.py", line 144, in __get_slot_details_by_vehicle
    raise ValueError(prompts.get("VEHICLE_NOT_PARKED"))
ValueError: Vehicle do not have any assigned slot.

2023-12-19 16:25:58 DEBUG log_debug(23) Error Occurred: Traceback (most recent call last):
  File "C:\PERSONAL\Parking_Management_System_FastAPI\src\helpers\handle_errors.py", line 19, in wrapper
    return_value = function(*args, **kwargs)
                   ^^^^^^^^^^^^^^^^^^^^^^^^^
  File "C:\PERSONAL\Parking_Management_System_FastAPI\src\helpers\access_decorator.py", line 21, in wrapper
    return fun(*args, **kwargs)
           ^^^^^^^^^^^^^^^^^^^^
  File "C:\PERSONAL\Parking_Management_System_FastAPI\src\routers\slot.py", line 56, in unassign_slot
    slot_details = slot.unassign_slot(vehicle_number)
                   ^^^^^^^^^^^^^^^^^^^^^^^^^^^^^^^^^^
  File "C:\PERSONAL\Parking_Management_System_FastAPI\src\controllers\slot.py", line 30, in unassign_slot
    slot_details = self.__get_slot_details_by_vehicle(vehicle_number)
                   ^^^^^^^^^^^^^^^^^^^^^^^^^^^^^^^^^^^^^^^^^^^^^^^^^^
  File "C:\PERSONAL\Parking_Management_System_FastAPI\src\controllers\slot.py", line 144, in __get_slot_details_by_vehicle
    raise ValueError(prompts.get("VEHICLE_NOT_PARKED"))
ValueError: Vehicle do not have any assigned slot.

2023-12-19 16:26:04 DEBUG log_debug(23) Error Occurred: Traceback (most recent call last):
  File "C:\PERSONAL\Parking_Management_System_FastAPI\src\helpers\handle_errors.py", line 19, in wrapper
    return_value = function(*args, **kwargs)
                   ^^^^^^^^^^^^^^^^^^^^^^^^^
  File "C:\PERSONAL\Parking_Management_System_FastAPI\src\helpers\access_decorator.py", line 21, in wrapper
    return fun(*args, **kwargs)
           ^^^^^^^^^^^^^^^^^^^^
  File "C:\PERSONAL\Parking_Management_System_FastAPI\src\routers\slot.py", line 56, in unassign_slot
    slot_details = slot.unassign_slot(vehicle_number)
                   ^^^^^^^^^^^^^^^^^^^^^^^^^^^^^^^^^^
  File "C:\PERSONAL\Parking_Management_System_FastAPI\src\controllers\slot.py", line 30, in unassign_slot
    slot_details = self.__get_slot_details_by_vehicle(vehicle_number)
                   ^^^^^^^^^^^^^^^^^^^^^^^^^^^^^^^^^^^^^^^^^^^^^^^^^^
  File "C:\PERSONAL\Parking_Management_System_FastAPI\src\controllers\slot.py", line 144, in __get_slot_details_by_vehicle
    raise ValueError(prompts.get("VEHICLE_NOT_PARKED"))
ValueError: Vehicle do not have any assigned slot.

2023-12-19 16:26:19 DEBUG log_debug(23) Error Occurred: Traceback (most recent call last):
  File "C:\PERSONAL\Parking_Management_System_FastAPI\src\helpers\handle_errors.py", line 19, in wrapper
    return_value = function(*args, **kwargs)
                   ^^^^^^^^^^^^^^^^^^^^^^^^^
  File "C:\PERSONAL\Parking_Management_System_FastAPI\src\helpers\validations.py", line 42, in wrapper
    return function(*args, **kwargs)
           ^^^^^^^^^^^^^^^^^^^^^^^^^
  File "C:\PERSONAL\Parking_Management_System_FastAPI\src\helpers\access_decorator.py", line 21, in wrapper
    return fun(*args, **kwargs)
           ^^^^^^^^^^^^^^^^^^^^
  File "C:\PERSONAL\Parking_Management_System_FastAPI\src\routers\slot.py", line 32, in occupy_slot
    slot.assign_slot(request_data.get("slot_number"), request_data.get(
  File "C:\PERSONAL\Parking_Management_System_FastAPI\src\controllers\slot.py", line 19, in assign_slot
    self.__is_already_parked(vehicle_number)
  File "C:\PERSONAL\Parking_Management_System_FastAPI\src\controllers\slot.py", line 112, in __is_already_parked
    raise ConflictError(prompts.get("VEHICLE_ALREADY_PARKED"))
src.helpers.errors.ConflictError: Vehicle Already Parked.

2023-12-19 16:27:56 DEBUG log_debug(23) Error Occurred: Traceback (most recent call last):
  File "C:\PERSONAL\Parking_Management_System_FastAPI\src\helpers\handle_errors.py", line 19, in wrapper
    return_value = function(*args, **kwargs)
                   ^^^^^^^^^^^^^^^^^^^^^^^^^
  File "C:\PERSONAL\Parking_Management_System_FastAPI\src\helpers\access_decorator.py", line 21, in wrapper
    return fun(*args, **kwargs)
           ^^^^^^^^^^^^^^^^^^^^
  File "C:\PERSONAL\Parking_Management_System_FastAPI\src\routers\slot.py", line 56, in unassign_slot
    slot_details = slot.unassign_slot(vehicle_number)
                   ^^^^^^^^^^^^^^^^^^^^^^^^^^^^^^^^^^
  File "C:\PERSONAL\Parking_Management_System_FastAPI\src\controllers\slot.py", line 30, in unassign_slot
    slot_details = self.__get_slot_details_by_vehicle(vehicle_number)
                   ^^^^^^^^^^^^^^^^^^^^^^^^^^^^^^^^^^^^^^^^^^^^^^^^^^
  File "C:\PERSONAL\Parking_Management_System_FastAPI\src\controllers\slot.py", line 144, in __get_slot_details_by_vehicle
    raise ValueError(prompts.get("VEHICLE_NOT_PARKED"))
ValueError: Vehicle do not have any assigned slot.

2023-12-19 16:28:00 DEBUG log_debug(23) Error Occurred: Traceback (most recent call last):
  File "C:\PERSONAL\Parking_Management_System_FastAPI\src\helpers\handle_errors.py", line 19, in wrapper
    return_value = function(*args, **kwargs)
                   ^^^^^^^^^^^^^^^^^^^^^^^^^
  File "C:\PERSONAL\Parking_Management_System_FastAPI\src\helpers\access_decorator.py", line 21, in wrapper
    return fun(*args, **kwargs)
           ^^^^^^^^^^^^^^^^^^^^
  File "C:\PERSONAL\Parking_Management_System_FastAPI\src\routers\slot.py", line 56, in unassign_slot
    slot_details = slot.unassign_slot(vehicle_number)
                   ^^^^^^^^^^^^^^^^^^^^^^^^^^^^^^^^^^
  File "C:\PERSONAL\Parking_Management_System_FastAPI\src\controllers\slot.py", line 30, in unassign_slot
    slot_details = self.__get_slot_details_by_vehicle(vehicle_number)
                   ^^^^^^^^^^^^^^^^^^^^^^^^^^^^^^^^^^^^^^^^^^^^^^^^^^
  File "C:\PERSONAL\Parking_Management_System_FastAPI\src\controllers\slot.py", line 144, in __get_slot_details_by_vehicle
    raise ValueError(prompts.get("VEHICLE_NOT_PARKED"))
ValueError: Vehicle do not have any assigned slot.

2023-12-19 16:28:23 DEBUG log_debug(23) Error Occurred: Traceback (most recent call last):
  File "C:\PERSONAL\Parking_Management_System_FastAPI\src\helpers\jwt_helpers.py", line 25, in validate_access_token
    payload = jwt.decode(token, SECRET_KEY, algorithms=[ALGORITHM])
              ^^^^^^^^^^^^^^^^^^^^^^^^^^^^^^^^^^^^^^^^^^^^^^^^^^^^^
  File "C:\Users\ahada\.virtualenvs\Parking_Management_System_FastAPI-yC4wlCPa\Lib\site-packages\jwt\api_jwt.py", line 210, in decode
    decoded = self.decode_complete(
              ^^^^^^^^^^^^^^^^^^^^^
  File "C:\Users\ahada\.virtualenvs\Parking_Management_System_FastAPI-yC4wlCPa\Lib\site-packages\jwt\api_jwt.py", line 162, in decode_complete
    self._validate_claims(
  File "C:\Users\ahada\.virtualenvs\Parking_Management_System_FastAPI-yC4wlCPa\Lib\site-packages\jwt\api_jwt.py", line 248, in _validate_claims
    self._validate_exp(payload, now, leeway)
  File "C:\Users\ahada\.virtualenvs\Parking_Management_System_FastAPI-yC4wlCPa\Lib\site-packages\jwt\api_jwt.py", line 306, in _validate_exp
    raise ExpiredSignatureError("Signature has expired")
jwt.exceptions.ExpiredSignatureError: Signature has expired

The above exception was the direct cause of the following exception:

Traceback (most recent call last):
  File "C:\PERSONAL\Parking_Management_System_FastAPI\src\helpers\handle_errors.py", line 19, in wrapper
    return_value = function(*args, **kwargs)
                   ^^^^^^^^^^^^^^^^^^^^^^^^^
  File "C:\PERSONAL\Parking_Management_System_FastAPI\src\helpers\validations.py", line 42, in wrapper
    return function(*args, **kwargs)
           ^^^^^^^^^^^^^^^^^^^^^^^^^
  File "C:\PERSONAL\Parking_Management_System_FastAPI\src\helpers\access_decorator.py", line 14, in wrapper
    token = validate_access_token(request=request)
            ^^^^^^^^^^^^^^^^^^^^^^^^^^^^^^^^^^^^^^
  File "C:\PERSONAL\Parking_Management_System_FastAPI\src\helpers\jwt_helpers.py", line 27, in validate_access_token
    raise UnauthorizedError(prompts.get(
src.helpers.errors.UnauthorizedError: Token Expired

2023-12-19 16:28:32 DEBUG log_debug(23) Error Occurred: Traceback (most recent call last):
  File "C:\PERSONAL\Parking_Management_System_FastAPI\src\helpers\handle_errors.py", line 19, in wrapper
    return_value = function(*args, **kwargs)
                   ^^^^^^^^^^^^^^^^^^^^^^^^^
  File "C:\PERSONAL\Parking_Management_System_FastAPI\src\helpers\validations.py", line 42, in wrapper
    return function(*args, **kwargs)
           ^^^^^^^^^^^^^^^^^^^^^^^^^
  File "C:\PERSONAL\Parking_Management_System_FastAPI\src\helpers\access_decorator.py", line 21, in wrapper
    return fun(*args, **kwargs)
           ^^^^^^^^^^^^^^^^^^^^
  File "C:\PERSONAL\Parking_Management_System_FastAPI\src\routers\slot.py", line 32, in occupy_slot
    slot.assign_slot(request_data.get("slot_number"), request_data.get(
  File "C:\PERSONAL\Parking_Management_System_FastAPI\src\controllers\slot.py", line 16, in assign_slot
    self.is_vehicle_type_existing(vehicle_type)
  File "C:\PERSONAL\Parking_Management_System_FastAPI\src\controllers\parking_space.py", line 87, in is_vehicle_type_existing
    raise ValueError(prompts.get("VEHICLE_TYPE_NOT_FOUND"))
ValueError: Vehicle Type Not Found.

2023-12-19 16:44:44 DEBUG log_debug(23) Error Occurred: Traceback (most recent call last):
  File "C:\PERSONAL\Parking_Management_System_FastAPI\src\helpers\handle_errors.py", line 19, in wrapper
    return_value = function(*args, **kwargs)
                   ^^^^^^^^^^^^^^^^^^^^^^^^^
  File "C:\PERSONAL\Parking_Management_System_FastAPI\src\helpers\access_decorator.py", line 21, in wrapper
    return fun(*args, **kwargs)
           ^^^^^^^^^^^^^^^^^^^^
  File "C:\PERSONAL\Parking_Management_System_FastAPI\src\routers\slot.py", line 56, in unassign_slot
    slot_details = slot.unassign_slot(vehicle_number)
                   ^^^^^^^^^^^^^^^^^^^^^^^^^^^^^^^^^^
  File "C:\PERSONAL\Parking_Management_System_FastAPI\src\controllers\slot.py", line 31, in unassign_slot
    slot_details = self.__get_slot_details_by_vehicle(vehicle_number)
                   ^^^^^^^^^^^^^^^^^^^^^^^^^^^^^^^^^^^^^^^^^^^^^^^^^^
  File "C:\PERSONAL\Parking_Management_System_FastAPI\src\controllers\slot.py", line 145, in __get_slot_details_by_vehicle
    raise ValueError(prompts.get("VEHICLE_NOT_PARKED"))
ValueError: Vehicle do not have any assigned slot.

2023-12-19 16:44:53 DEBUG log_debug(23) Error Occurred: Traceback (most recent call last):
  File "C:\PERSONAL\Parking_Management_System_FastAPI\src\helpers\handle_errors.py", line 19, in wrapper
    return_value = function(*args, **kwargs)
                   ^^^^^^^^^^^^^^^^^^^^^^^^^
  File "C:\PERSONAL\Parking_Management_System_FastAPI\src\helpers\validations.py", line 42, in wrapper
    return function(*args, **kwargs)
           ^^^^^^^^^^^^^^^^^^^^^^^^^
  File "C:\PERSONAL\Parking_Management_System_FastAPI\src\helpers\access_decorator.py", line 21, in wrapper
    return fun(*args, **kwargs)
           ^^^^^^^^^^^^^^^^^^^^
  File "C:\PERSONAL\Parking_Management_System_FastAPI\src\routers\slot.py", line 32, in occupy_slot
    slot.assign_slot(request_data.get("slot_number"), request_data.get(
  File "C:\PERSONAL\Parking_Management_System_FastAPI\src\controllers\slot.py", line 16, in assign_slot
    self.is_slot_type_for_vehicle_correct(vehicle_number, vehicle_type)
TypeError: Slot.is_slot_type_for_vehicle_correct() takes 2 positional arguments but 3 were given

2023-12-19 16:45:14 DEBUG log_debug(23) Error Occurred: Traceback (most recent call last):
  File "C:\PERSONAL\Parking_Management_System_FastAPI\src\helpers\handle_errors.py", line 19, in wrapper
    return_value = function(*args, **kwargs)
                   ^^^^^^^^^^^^^^^^^^^^^^^^^
  File "C:\PERSONAL\Parking_Management_System_FastAPI\src\helpers\validations.py", line 42, in wrapper
    return function(*args, **kwargs)
           ^^^^^^^^^^^^^^^^^^^^^^^^^
  File "C:\PERSONAL\Parking_Management_System_FastAPI\src\helpers\access_decorator.py", line 21, in wrapper
    return fun(*args, **kwargs)
           ^^^^^^^^^^^^^^^^^^^^
  File "C:\PERSONAL\Parking_Management_System_FastAPI\src\routers\slot.py", line 32, in occupy_slot
    slot.assign_slot(request_data.get("slot_number"), request_data.get(
  File "C:\PERSONAL\Parking_Management_System_FastAPI\src\controllers\slot.py", line 16, in assign_slot
    self.is_slot_type_for_vehicle_correct(vehicle_number, vehicle_type)
  File "C:\PERSONAL\Parking_Management_System_FastAPI\src\controllers\slot.py", line 169, in is_slot_type_for_vehicle_correct
    raise ValueError(prompts.get("INVALID_VEHICLE_NUMBER"))
ValueError: Vehicle Number not found in this Parking Category.

2023-12-19 16:46:02 DEBUG log_debug(23) Error Occurred: Traceback (most recent call last):
  File "C:\PERSONAL\Parking_Management_System_FastAPI\src\helpers\handle_errors.py", line 19, in wrapper
    return_value = function(*args, **kwargs)
                   ^^^^^^^^^^^^^^^^^^^^^^^^^
  File "C:\PERSONAL\Parking_Management_System_FastAPI\src\helpers\validations.py", line 42, in wrapper
    return function(*args, **kwargs)
           ^^^^^^^^^^^^^^^^^^^^^^^^^
  File "C:\PERSONAL\Parking_Management_System_FastAPI\src\helpers\access_decorator.py", line 21, in wrapper
    return fun(*args, **kwargs)
           ^^^^^^^^^^^^^^^^^^^^
  File "C:\PERSONAL\Parking_Management_System_FastAPI\src\routers\slot.py", line 32, in occupy_slot
    slot.assign_slot(request_data.get("slot_number"), request_data.get(
  File "C:\PERSONAL\Parking_Management_System_FastAPI\src\controllers\slot.py", line 16, in assign_slot
    self.is_slot_type_for_vehicle_correct(vehicle_number, vehicle_type)
  File "C:\PERSONAL\Parking_Management_System_FastAPI\src\controllers\slot.py", line 169, in is_slot_type_for_vehicle_correct
    raise ValueError(prompts.get("INVALID_VEHICLE_NUMBER"))
ValueError: Vehicle Number not found in this Parking Category.

2023-12-19 16:46:45 DEBUG log_debug(23) Error Occurred: Traceback (most recent call last):
  File "C:\PERSONAL\Parking_Management_System_FastAPI\src\helpers\handle_errors.py", line 19, in wrapper
    return_value = function(*args, **kwargs)
                   ^^^^^^^^^^^^^^^^^^^^^^^^^
  File "C:\PERSONAL\Parking_Management_System_FastAPI\src\helpers\access_decorator.py", line 21, in wrapper
    return fun(*args, **kwargs)
           ^^^^^^^^^^^^^^^^^^^^
  File "C:\PERSONAL\Parking_Management_System_FastAPI\src\routers\slot.py", line 56, in unassign_slot
    slot_details = slot.unassign_slot(vehicle_number)
                   ^^^^^^^^^^^^^^^^^^^^^^^^^^^^^^^^^^
  File "C:\PERSONAL\Parking_Management_System_FastAPI\src\controllers\slot.py", line 31, in unassign_slot
    slot_details = self.__get_slot_details_by_vehicle(vehicle_number)
                   ^^^^^^^^^^^^^^^^^^^^^^^^^^^^^^^^^^^^^^^^^^^^^^^^^^
  File "C:\PERSONAL\Parking_Management_System_FastAPI\src\controllers\slot.py", line 145, in __get_slot_details_by_vehicle
    raise ValueError(prompts.get("VEHICLE_NOT_PARKED"))
ValueError: Vehicle do not have any assigned slot.

2023-12-19 16:47:31 DEBUG log_debug(23) Error Occurred: Traceback (most recent call last):
  File "C:\PERSONAL\Parking_Management_System_FastAPI\src\helpers\handle_errors.py", line 19, in wrapper
    return_value = function(*args, **kwargs)
                   ^^^^^^^^^^^^^^^^^^^^^^^^^
  File "C:\PERSONAL\Parking_Management_System_FastAPI\src\helpers\access_decorator.py", line 21, in wrapper
    return fun(*args, **kwargs)
           ^^^^^^^^^^^^^^^^^^^^
  File "C:\PERSONAL\Parking_Management_System_FastAPI\src\routers\slot.py", line 56, in unassign_slot
    slot_details = slot.unassign_slot(vehicle_number)
                   ^^^^^^^^^^^^^^^^^^^^^^^^^^^^^^^^^^
  File "C:\PERSONAL\Parking_Management_System_FastAPI\src\controllers\slot.py", line 31, in unassign_slot
    slot_details = self.__get_slot_details_by_vehicle(vehicle_number)
                   ^^^^^^^^^^^^^^^^^^^^^^^^^^^^^^^^^^^^^^^^^^^^^^^^^^
  File "C:\PERSONAL\Parking_Management_System_FastAPI\src\controllers\slot.py", line 145, in __get_slot_details_by_vehicle
    raise ValueError(prompts.get("VEHICLE_NOT_PARKED"))
ValueError: Vehicle do not have any assigned slot.

2023-12-19 16:49:37 DEBUG log_debug(23) Error Occurred: Traceback (most recent call last):
  File "C:\PERSONAL\Parking_Management_System_FastAPI\src\helpers\handle_errors.py", line 19, in wrapper
    return_value = function(*args, **kwargs)
                   ^^^^^^^^^^^^^^^^^^^^^^^^^
  File "C:\PERSONAL\Parking_Management_System_FastAPI\src\helpers\access_decorator.py", line 21, in wrapper
    return fun(*args, **kwargs)
           ^^^^^^^^^^^^^^^^^^^^
  File "C:\PERSONAL\Parking_Management_System_FastAPI\src\routers\slot.py", line 56, in unassign_slot
    slot_details = slot.unassign_slot(vehicle_number)
                   ^^^^^^^^^^^^^^^^^^^^^^^^^^^^^^^^^^
  File "C:\PERSONAL\Parking_Management_System_FastAPI\src\controllers\slot.py", line 31, in unassign_slot
    slot_details = self.__get_slot_details_by_vehicle(vehicle_number)
                   ^^^^^^^^^^^^^^^^^^^^^^^^^^^^^^^^^^^^^^^^^^^^^^^^^^
  File "C:\PERSONAL\Parking_Management_System_FastAPI\src\controllers\slot.py", line 145, in __get_slot_details_by_vehicle
    raise ValueError(prompts.get("VEHICLE_NOT_PARKED"))
ValueError: Vehicle do not have any assigned slot.

2023-12-19 16:50:29 DEBUG log_debug(23) Error Occurred: Traceback (most recent call last):
  File "C:\PERSONAL\Parking_Management_System_FastAPI\src\helpers\handle_errors.py", line 19, in wrapper
    return_value = function(*args, **kwargs)
                   ^^^^^^^^^^^^^^^^^^^^^^^^^
  File "C:\PERSONAL\Parking_Management_System_FastAPI\src\helpers\access_decorator.py", line 21, in wrapper
    return fun(*args, **kwargs)
           ^^^^^^^^^^^^^^^^^^^^
  File "C:\PERSONAL\Parking_Management_System_FastAPI\src\routers\slot.py", line 56, in unassign_slot
    slot_details = slot.unassign_slot(vehicle_number)
                   ^^^^^^^^^^^^^^^^^^^^^^^^^^^^^^^^^^
  File "C:\PERSONAL\Parking_Management_System_FastAPI\src\controllers\slot.py", line 31, in unassign_slot
    slot_details = self.__get_slot_details_by_vehicle(vehicle_number)
                   ^^^^^^^^^^^^^^^^^^^^^^^^^^^^^^^^^^^^^^^^^^^^^^^^^^
  File "C:\PERSONAL\Parking_Management_System_FastAPI\src\controllers\slot.py", line 145, in __get_slot_details_by_vehicle
    raise ValueError(prompts.get("VEHICLE_NOT_PARKED"))
ValueError: Vehicle do not have any assigned slot.

2023-12-19 16:50:33 DEBUG log_debug(23) Error Occurred: Traceback (most recent call last):
  File "C:\PERSONAL\Parking_Management_System_FastAPI\src\helpers\handle_errors.py", line 19, in wrapper
    return_value = function(*args, **kwargs)
                   ^^^^^^^^^^^^^^^^^^^^^^^^^
  File "C:\PERSONAL\Parking_Management_System_FastAPI\src\helpers\access_decorator.py", line 21, in wrapper
    return fun(*args, **kwargs)
           ^^^^^^^^^^^^^^^^^^^^
  File "C:\PERSONAL\Parking_Management_System_FastAPI\src\routers\slot.py", line 56, in unassign_slot
    slot_details = slot.unassign_slot(vehicle_number)
                   ^^^^^^^^^^^^^^^^^^^^^^^^^^^^^^^^^^
  File "C:\PERSONAL\Parking_Management_System_FastAPI\src\controllers\slot.py", line 31, in unassign_slot
    slot_details = self.__get_slot_details_by_vehicle(vehicle_number)
                   ^^^^^^^^^^^^^^^^^^^^^^^^^^^^^^^^^^^^^^^^^^^^^^^^^^
  File "C:\PERSONAL\Parking_Management_System_FastAPI\src\controllers\slot.py", line 145, in __get_slot_details_by_vehicle
    raise ValueError(prompts.get("VEHICLE_NOT_PARKED"))
ValueError: Vehicle do not have any assigned slot.

2023-12-19 16:50:38 DEBUG log_debug(23) Error Occurred: Traceback (most recent call last):
  File "C:\PERSONAL\Parking_Management_System_FastAPI\src\helpers\handle_errors.py", line 19, in wrapper
    return_value = function(*args, **kwargs)
                   ^^^^^^^^^^^^^^^^^^^^^^^^^
  File "C:\PERSONAL\Parking_Management_System_FastAPI\src\helpers\access_decorator.py", line 21, in wrapper
    return fun(*args, **kwargs)
           ^^^^^^^^^^^^^^^^^^^^
  File "C:\PERSONAL\Parking_Management_System_FastAPI\src\routers\slot.py", line 56, in unassign_slot
    slot_details = slot.unassign_slot(vehicle_number)
                   ^^^^^^^^^^^^^^^^^^^^^^^^^^^^^^^^^^
  File "C:\PERSONAL\Parking_Management_System_FastAPI\src\controllers\slot.py", line 31, in unassign_slot
    slot_details = self.__get_slot_details_by_vehicle(vehicle_number)
                   ^^^^^^^^^^^^^^^^^^^^^^^^^^^^^^^^^^^^^^^^^^^^^^^^^^
  File "C:\PERSONAL\Parking_Management_System_FastAPI\src\controllers\slot.py", line 145, in __get_slot_details_by_vehicle
    raise ValueError(prompts.get("VEHICLE_NOT_PARKED"))
ValueError: Vehicle do not have any assigned slot.

2023-12-19 16:50:42 DEBUG log_debug(23) Error Occurred: Traceback (most recent call last):
  File "C:\PERSONAL\Parking_Management_System_FastAPI\src\helpers\handle_errors.py", line 19, in wrapper
    return_value = function(*args, **kwargs)
                   ^^^^^^^^^^^^^^^^^^^^^^^^^
  File "C:\PERSONAL\Parking_Management_System_FastAPI\src\helpers\access_decorator.py", line 21, in wrapper
    return fun(*args, **kwargs)
           ^^^^^^^^^^^^^^^^^^^^
  File "C:\PERSONAL\Parking_Management_System_FastAPI\src\routers\slot.py", line 56, in unassign_slot
    slot_details = slot.unassign_slot(vehicle_number)
                   ^^^^^^^^^^^^^^^^^^^^^^^^^^^^^^^^^^
  File "C:\PERSONAL\Parking_Management_System_FastAPI\src\controllers\slot.py", line 31, in unassign_slot
    slot_details = self.__get_slot_details_by_vehicle(vehicle_number)
                   ^^^^^^^^^^^^^^^^^^^^^^^^^^^^^^^^^^^^^^^^^^^^^^^^^^
  File "C:\PERSONAL\Parking_Management_System_FastAPI\src\controllers\slot.py", line 145, in __get_slot_details_by_vehicle
    raise ValueError(prompts.get("VEHICLE_NOT_PARKED"))
ValueError: Vehicle do not have any assigned slot.

2023-12-19 16:57:31 DEBUG log_debug(23) Error Occurred: Traceback (most recent call last):
  File "C:\PERSONAL\Parking_Management_System_FastAPI\src\helpers\handle_errors.py", line 19, in wrapper
    return_value = function(*args, **kwargs)
                   ^^^^^^^^^^^^^^^^^^^^^^^^^
  File "C:\PERSONAL\Parking_Management_System_FastAPI\src\helpers\access_decorator.py", line 21, in wrapper
    return fun(*args, **kwargs)
           ^^^^^^^^^^^^^^^^^^^^
  File "C:\PERSONAL\Parking_Management_System_FastAPI\src\routers\slot.py", line 56, in unassign_slot
    slot_details = slot.unassign_slot(vehicle_number)
                   ^^^^^^^^^^^^^^^^^^^^^^^^^^^^^^^^^^
  File "C:\PERSONAL\Parking_Management_System_FastAPI\src\controllers\slot.py", line 31, in unassign_slot
    slot_details = self.__get_slot_details_by_vehicle(vehicle_number)
                   ^^^^^^^^^^^^^^^^^^^^^^^^^^^^^^^^^^^^^^^^^^^^^^^^^^
  File "C:\PERSONAL\Parking_Management_System_FastAPI\src\controllers\slot.py", line 145, in __get_slot_details_by_vehicle
    raise ValueError(prompts.get("VEHICLE_NOT_PARKED"))
ValueError: Vehicle do not have any assigned slot.

2023-12-19 17:29:36 DEBUG log_debug(23) Error Occurred: Traceback (most recent call last):
  File "C:\PERSONAL\Parking_Management_System_FastAPI\src\helpers\handle_errors.py", line 19, in wrapper
    return_value = function(*args, **kwargs)
                   ^^^^^^^^^^^^^^^^^^^^^^^^^
  File "C:\PERSONAL\Parking_Management_System_FastAPI\src\helpers\access_decorator.py", line 21, in wrapper
    return fun(*args, **kwargs)
           ^^^^^^^^^^^^^^^^^^^^
  File "C:\PERSONAL\Parking_Management_System_FastAPI\src\routers\slot.py", line 56, in unassign_slot
    slot_details = slot.unassign_slot(vehicle_number)
                   ^^^^^^^^^^^^^^^^^^^^^^^^^^^^^^^^^^
  File "C:\PERSONAL\Parking_Management_System_FastAPI\src\controllers\slot.py", line 31, in unassign_slot
    slot_details = self.__get_slot_details_by_vehicle(vehicle_number)
                   ^^^^^^^^^^^^^^^^^^^^^^^^^^^^^^^^^^^^^^^^^^^^^^^^^^
  File "C:\PERSONAL\Parking_Management_System_FastAPI\src\controllers\slot.py", line 145, in __get_slot_details_by_vehicle
    raise ValueError(prompts.get("VEHICLE_NOT_PARKED"))
ValueError: Vehicle do not have any assigned slot.

2023-12-19 17:31:02 DEBUG log_debug(23) Error Occurred: Traceback (most recent call last):
  File "C:\PERSONAL\Parking_Management_System_FastAPI\src\helpers\handle_errors.py", line 19, in wrapper
    return_value = function(*args, **kwargs)
                   ^^^^^^^^^^^^^^^^^^^^^^^^^
  File "C:\PERSONAL\Parking_Management_System_FastAPI\src\helpers\access_decorator.py", line 21, in wrapper
    return fun(*args, **kwargs)
           ^^^^^^^^^^^^^^^^^^^^
  File "C:\PERSONAL\Parking_Management_System_FastAPI\src\routers\slot.py", line 56, in unassign_slot
    slot_details = slot.unassign_slot(vehicle_number)
                   ^^^^^^^^^^^^^^^^^^^^^^^^^^^^^^^^^^
  File "C:\PERSONAL\Parking_Management_System_FastAPI\src\controllers\slot.py", line 31, in unassign_slot
    slot_details = self.__get_slot_details_by_vehicle(vehicle_number)
                   ^^^^^^^^^^^^^^^^^^^^^^^^^^^^^^^^^^^^^^^^^^^^^^^^^^
  File "C:\PERSONAL\Parking_Management_System_FastAPI\src\controllers\slot.py", line 145, in __get_slot_details_by_vehicle
    raise ValueError(prompts.get("VEHICLE_NOT_PARKED"))
ValueError: Vehicle do not have any assigned slot.

2023-12-19 21:35:13 DEBUG log_debug(23) Error Occurred: Traceback (most recent call last):
  File "C:\PERSONAL\Parking_Management_System_FastAPI\src\helpers\handle_errors.py", line 19, in wrapper
    return_value = function(*args, **kwargs)
                   ^^^^^^^^^^^^^^^^^^^^^^^^^
  File "C:\PERSONAL\Parking_Management_System_FastAPI\src\helpers\access_decorator.py", line 21, in wrapper
    return fun(*args, **kwargs)
           ^^^^^^^^^^^^^^^^^^^^
  File "C:\PERSONAL\Parking_Management_System_FastAPI\src\routers\slot.py", line 56, in unassign_slot
    slot_details = slot.unassign_slot(vehicle_number)
                   ^^^^^^^^^^^^^^^^^^^^^^^^^^^^^^^^^^
  File "C:\PERSONAL\Parking_Management_System_FastAPI\src\controllers\slot.py", line 31, in unassign_slot
    slot_details = self.__get_slot_details_by_vehicle(vehicle_number)
                   ^^^^^^^^^^^^^^^^^^^^^^^^^^^^^^^^^^^^^^^^^^^^^^^^^^
  File "C:\PERSONAL\Parking_Management_System_FastAPI\src\controllers\slot.py", line 145, in __get_slot_details_by_vehicle
    raise ValueError(prompts.get("VEHICLE_NOT_PARKED"))
ValueError: Vehicle do not have any assigned slot.

2023-12-19 21:35:19 DEBUG log_debug(23) Error Occurred: Traceback (most recent call last):
  File "C:\PERSONAL\Parking_Management_System_FastAPI\src\helpers\handle_errors.py", line 19, in wrapper
    return_value = function(*args, **kwargs)
                   ^^^^^^^^^^^^^^^^^^^^^^^^^
  File "C:\PERSONAL\Parking_Management_System_FastAPI\src\helpers\access_decorator.py", line 21, in wrapper
    return fun(*args, **kwargs)
           ^^^^^^^^^^^^^^^^^^^^
  File "C:\PERSONAL\Parking_Management_System_FastAPI\src\routers\slot.py", line 56, in unassign_slot
    slot_details = slot.unassign_slot(vehicle_number)
                   ^^^^^^^^^^^^^^^^^^^^^^^^^^^^^^^^^^
  File "C:\PERSONAL\Parking_Management_System_FastAPI\src\controllers\slot.py", line 31, in unassign_slot
    slot_details = self.__get_slot_details_by_vehicle(vehicle_number)
                   ^^^^^^^^^^^^^^^^^^^^^^^^^^^^^^^^^^^^^^^^^^^^^^^^^^
  File "C:\PERSONAL\Parking_Management_System_FastAPI\src\controllers\slot.py", line 145, in __get_slot_details_by_vehicle
    raise ValueError(prompts.get("VEHICLE_NOT_PARKED"))
ValueError: Vehicle do not have any assigned slot.

2023-12-19 21:39:33 DEBUG log_debug(23) Error Occurred: Traceback (most recent call last):
  File "C:\PERSONAL\Parking_Management_System_FastAPI\src\helpers\handle_errors.py", line 19, in wrapper
    return_value = function(*args, **kwargs)
                   ^^^^^^^^^^^^^^^^^^^^^^^^^
  File "C:\PERSONAL\Parking_Management_System_FastAPI\src\helpers\access_decorator.py", line 21, in wrapper
    return fun(*args, **kwargs)
           ^^^^^^^^^^^^^^^^^^^^
  File "C:\PERSONAL\Parking_Management_System_FastAPI\src\routers\slot.py", line 56, in unassign_slot
    slot_details = slot.unassign_slot(vehicle_number)
                   ^^^^^^^^^^^^^^^^^^^^^^^^^^^^^^^^^^
  File "C:\PERSONAL\Parking_Management_System_FastAPI\src\controllers\slot.py", line 31, in unassign_slot
    slot_details = self.__get_slot_details_by_vehicle(vehicle_number)
                   ^^^^^^^^^^^^^^^^^^^^^^^^^^^^^^^^^^^^^^^^^^^^^^^^^^
  File "C:\PERSONAL\Parking_Management_System_FastAPI\src\controllers\slot.py", line 145, in __get_slot_details_by_vehicle
    raise ValueError(prompts.get("VEHICLE_NOT_PARKED"))
ValueError: Vehicle do not have any assigned slot.

2023-12-19 21:52:35 DEBUG log_debug(23) Error Occurred: Traceback (most recent call last):
  File "C:\PERSONAL\Parking_Management_System_FastAPI\src\helpers\handle_errors.py", line 19, in wrapper
    return_value = function(*args, **kwargs)
                   ^^^^^^^^^^^^^^^^^^^^^^^^^
  File "C:\PERSONAL\Parking_Management_System_FastAPI\src\helpers\access_decorator.py", line 21, in wrapper
    return fun(*args, **kwargs)
           ^^^^^^^^^^^^^^^^^^^^
  File "C:\PERSONAL\Parking_Management_System_FastAPI\src\routers\slot.py", line 56, in unassign_slot
    slot_details = slot.unassign_slot(vehicle_number)
                   ^^^^^^^^^^^^^^^^^^^^^^^^^^^^^^^^^^
  File "C:\PERSONAL\Parking_Management_System_FastAPI\src\controllers\slot.py", line 31, in unassign_slot
    slot_details = self.__get_slot_details_by_vehicle(vehicle_number)
                   ^^^^^^^^^^^^^^^^^^^^^^^^^^^^^^^^^^^^^^^^^^^^^^^^^^
  File "C:\PERSONAL\Parking_Management_System_FastAPI\src\controllers\slot.py", line 145, in __get_slot_details_by_vehicle
    raise ValueError(prompts.get("VEHICLE_NOT_PARKED"))
ValueError: Vehicle do not have any assigned slot.

2023-12-19 21:52:37 DEBUG log_debug(23) Error Occurred: Traceback (most recent call last):
  File "C:\PERSONAL\Parking_Management_System_FastAPI\src\helpers\handle_errors.py", line 19, in wrapper
    return_value = function(*args, **kwargs)
                   ^^^^^^^^^^^^^^^^^^^^^^^^^
  File "C:\PERSONAL\Parking_Management_System_FastAPI\src\helpers\access_decorator.py", line 21, in wrapper
    return fun(*args, **kwargs)
           ^^^^^^^^^^^^^^^^^^^^
  File "C:\PERSONAL\Parking_Management_System_FastAPI\src\routers\slot.py", line 56, in unassign_slot
    slot_details = slot.unassign_slot(vehicle_number)
                   ^^^^^^^^^^^^^^^^^^^^^^^^^^^^^^^^^^
  File "C:\PERSONAL\Parking_Management_System_FastAPI\src\controllers\slot.py", line 31, in unassign_slot
    slot_details = self.__get_slot_details_by_vehicle(vehicle_number)
                   ^^^^^^^^^^^^^^^^^^^^^^^^^^^^^^^^^^^^^^^^^^^^^^^^^^
  File "C:\PERSONAL\Parking_Management_System_FastAPI\src\controllers\slot.py", line 145, in __get_slot_details_by_vehicle
    raise ValueError(prompts.get("VEHICLE_NOT_PARKED"))
ValueError: Vehicle do not have any assigned slot.

2023-12-20 09:50:24 DEBUG log_debug(23) Error Occurred: Traceback (most recent call last):
  File "C:\PERSONAL\Parking_Management_System_FastAPI\src\helpers\handle_errors.py", line 19, in wrapper
    return_value = function(*args, **kwargs)
                   ^^^^^^^^^^^^^^^^^^^^^^^^^
  File "C:\PERSONAL\Parking_Management_System_FastAPI\src\helpers\validations.py", line 42, in wrapper
    return function(*args, **kwargs)
           ^^^^^^^^^^^^^^^^^^^^^^^^^
  File "C:\PERSONAL\Parking_Management_System_FastAPI\src\helpers\access_decorator.py", line 21, in wrapper
    return fun(*args, **kwargs)
           ^^^^^^^^^^^^^^^^^^^^
  File "C:\PERSONAL\Parking_Management_System_FastAPI\src\routers\slot.py", line 27, in occupy_slot
    raise ValueError(prompts.get("VEHICLE_NOT_EXISTS"))
ValueError: Vehicle do not Exists. Please Add Vehicle First.

2023-12-20 09:50:33 DEBUG log_debug(23) Error Occurred: Traceback (most recent call last):
  File "C:\PERSONAL\Parking_Management_System_FastAPI\src\helpers\handle_errors.py", line 19, in wrapper
    return_value = function(*args, **kwargs)
                   ^^^^^^^^^^^^^^^^^^^^^^^^^
  File "C:\PERSONAL\Parking_Management_System_FastAPI\src\helpers\validations.py", line 42, in wrapper
    return function(*args, **kwargs)
           ^^^^^^^^^^^^^^^^^^^^^^^^^
  File "C:\PERSONAL\Parking_Management_System_FastAPI\src\helpers\access_decorator.py", line 21, in wrapper
    return fun(*args, **kwargs)
           ^^^^^^^^^^^^^^^^^^^^
  File "C:\PERSONAL\Parking_Management_System_FastAPI\src\routers\slot.py", line 27, in occupy_slot
    raise ValueError(prompts.get("VEHICLE_NOT_EXISTS"))
ValueError: Vehicle do not Exists. Please Add Vehicle First.

2023-12-20 09:50:38 DEBUG log_debug(23) Error Occurred: Traceback (most recent call last):
  File "C:\PERSONAL\Parking_Management_System_FastAPI\src\helpers\handle_errors.py", line 19, in wrapper
    return_value = function(*args, **kwargs)
                   ^^^^^^^^^^^^^^^^^^^^^^^^^
  File "C:\PERSONAL\Parking_Management_System_FastAPI\src\helpers\validations.py", line 42, in wrapper
    return function(*args, **kwargs)
           ^^^^^^^^^^^^^^^^^^^^^^^^^
  File "C:\PERSONAL\Parking_Management_System_FastAPI\src\helpers\access_decorator.py", line 21, in wrapper
    return fun(*args, **kwargs)
           ^^^^^^^^^^^^^^^^^^^^
  File "C:\PERSONAL\Parking_Management_System_FastAPI\src\routers\slot.py", line 27, in occupy_slot
    raise ValueError(prompts.get("VEHICLE_NOT_EXISTS"))
ValueError: Vehicle do not Exists. Please Add Vehicle First.

2023-12-20 09:50:45 DEBUG log_debug(23) Error Occurred: Traceback (most recent call last):
  File "C:\PERSONAL\Parking_Management_System_FastAPI\src\helpers\handle_errors.py", line 19, in wrapper
    return_value = function(*args, **kwargs)
                   ^^^^^^^^^^^^^^^^^^^^^^^^^
  File "C:\PERSONAL\Parking_Management_System_FastAPI\src\helpers\validations.py", line 42, in wrapper
    return function(*args, **kwargs)
           ^^^^^^^^^^^^^^^^^^^^^^^^^
  File "C:\PERSONAL\Parking_Management_System_FastAPI\src\helpers\access_decorator.py", line 21, in wrapper
    return fun(*args, **kwargs)
           ^^^^^^^^^^^^^^^^^^^^
  File "C:\PERSONAL\Parking_Management_System_FastAPI\src\routers\slot.py", line 27, in occupy_slot
    raise ValueError(prompts.get("VEHICLE_NOT_EXISTS"))
ValueError: Vehicle do not Exists. Please Add Vehicle First.

2023-12-20 09:51:38 DEBUG log_debug(23) Error Occurred: Traceback (most recent call last):
  File "C:\PERSONAL\Parking_Management_System_FastAPI\src\helpers\handle_errors.py", line 19, in wrapper
    return_value = function(*args, **kwargs)
                   ^^^^^^^^^^^^^^^^^^^^^^^^^
  File "C:\PERSONAL\Parking_Management_System_FastAPI\src\helpers\access_decorator.py", line 21, in wrapper
    return fun(*args, **kwargs)
           ^^^^^^^^^^^^^^^^^^^^
  File "C:\PERSONAL\Parking_Management_System_FastAPI\src\helpers\validations.py", line 42, in wrapper
    return function(*args, **kwargs)
           ^^^^^^^^^^^^^^^^^^^^^^^^^
  File "C:\PERSONAL\Parking_Management_System_FastAPI\src\routers\vehicles.py", line 51, in add_vehicle
    vehicle.add_vehicle(
  File "C:\PERSONAL\Parking_Management_System_FastAPI\src\controllers\vehicle.py", line 19, in add_vehicle
    raise ValueError(prompts.get("VEHICLE_ALREADY_EXISTS"))
ValueError: Vehicle Already Exists.

2023-12-20 09:51:55 DEBUG log_debug(23) Error Occurred: Traceback (most recent call last):
  File "C:\PERSONAL\Parking_Management_System_FastAPI\src\helpers\handle_errors.py", line 19, in wrapper
    return_value = function(*args, **kwargs)
                   ^^^^^^^^^^^^^^^^^^^^^^^^^
  File "C:\PERSONAL\Parking_Management_System_FastAPI\src\helpers\validations.py", line 42, in wrapper
    return function(*args, **kwargs)
           ^^^^^^^^^^^^^^^^^^^^^^^^^
  File "C:\PERSONAL\Parking_Management_System_FastAPI\src\helpers\access_decorator.py", line 21, in wrapper
    return fun(*args, **kwargs)
           ^^^^^^^^^^^^^^^^^^^^
  File "C:\PERSONAL\Parking_Management_System_FastAPI\src\routers\slot.py", line 32, in occupy_slot
    slot.assign_slot(request_data.get("slot_number"), request_data.get(
  File "C:\PERSONAL\Parking_Management_System_FastAPI\src\controllers\slot.py", line 16, in assign_slot
    self.is_slot_type_for_vehicle_correct(vehicle_number, vehicle_type)
  File "C:\PERSONAL\Parking_Management_System_FastAPI\src\controllers\slot.py", line 169, in is_slot_type_for_vehicle_correct
    raise ValueError(prompts.get("INVALID_VEHICLE_NUMBER"))
ValueError: Vehicle Number not found in this Parking Category.

2023-12-20 14:05:51 DEBUG log_debug(23) Error Occurred: Traceback (most recent call last):
  File "C:\PERSONAL\Parking_Management_System_FastAPI\src\helpers\handle_errors.py", line 19, in wrapper
    return_value = function(*args, **kwargs)
                   ^^^^^^^^^^^^^^^^^^^^^^^^^
  File "C:\PERSONAL\Parking_Management_System_FastAPI\src\helpers\access_decorator.py", line 21, in wrapper
    return fun(*args, **kwargs)
           ^^^^^^^^^^^^^^^^^^^^
  File "C:\PERSONAL\Parking_Management_System_FastAPI\src\helpers\validations.py", line 42, in wrapper
    return function(*args, **kwargs)
           ^^^^^^^^^^^^^^^^^^^^^^^^^
  File "C:\PERSONAL\Parking_Management_System_FastAPI\src\routers\vehicles.py", line 51, in add_vehicle
    vehicle.add_vehicle(
  File "C:\PERSONAL\Parking_Management_System_FastAPI\src\controllers\vehicle.py", line 19, in add_vehicle
    raise ValueError(prompts.get("VEHICLE_ALREADY_EXISTS"))
ValueError: Vehicle Already Exists.

2023-12-20 15:58:35 DEBUG log_debug(23) Error Occurred: Traceback (most recent call last):
  File "C:\PERSONAL\Parking_Management_System_FastAPI\src\helpers\handle_errors.py", line 19, in wrapper
    return_value = function(*args, **kwargs)
                   ^^^^^^^^^^^^^^^^^^^^^^^^^
  File "C:\PERSONAL\Parking_Management_System_FastAPI\src\helpers\access_decorator.py", line 21, in wrapper
    return fun(*args, **kwargs)
           ^^^^^^^^^^^^^^^^^^^^
  File "C:\PERSONAL\Parking_Management_System_FastAPI\src\helpers\validations.py", line 42, in wrapper
    return function(*args, **kwargs)
           ^^^^^^^^^^^^^^^^^^^^^^^^^
  File "C:\PERSONAL\Parking_Management_System_FastAPI\src\routers\parkingspace.py", line 40, in update_parking_space
    raise ConflictError(prompts.get("SPACE_OCCUPIED"))
src.helpers.errors.ConflictError: Cannot reduce capacity. Space is occupied.

2023-12-20 16:23:43 DEBUG log_debug(23) Error Occurred: Traceback (most recent call last):
  File "C:\PERSONAL\Parking_Management_System_FastAPI\src\helpers\handle_errors.py", line 19, in wrapper
    return_value = function(*args, **kwargs)
                   ^^^^^^^^^^^^^^^^^^^^^^^^^
  File "C:\PERSONAL\Parking_Management_System_FastAPI\src\helpers\access_decorator.py", line 21, in wrapper
    return fun(*args, **kwargs)
           ^^^^^^^^^^^^^^^^^^^^
  File "C:\PERSONAL\Parking_Management_System_FastAPI\src\routers\slot.py", line 56, in unassign_slot
    slot_details = slot.unassign_slot(vehicle_number)
                   ^^^^^^^^^^^^^^^^^^^^^^^^^^^^^^^^^^
  File "C:\PERSONAL\Parking_Management_System_FastAPI\src\controllers\slot.py", line 31, in unassign_slot
    slot_details = self.__get_slot_details_by_vehicle(vehicle_number)
                   ^^^^^^^^^^^^^^^^^^^^^^^^^^^^^^^^^^^^^^^^^^^^^^^^^^
  File "C:\PERSONAL\Parking_Management_System_FastAPI\src\controllers\slot.py", line 145, in __get_slot_details_by_vehicle
    raise ValueError(prompts.get("VEHICLE_NOT_PARKED"))
ValueError: Vehicle do not have any assigned slot.

